[2016-12-01 15:06:35] DEBUG [django.db.backends:90] (0.000) 
            SELECT name, type FROM sqlite_master
            WHERE type in ('table', 'view') AND NOT name='sqlite_sequence'
            ORDER BY name; args=None
[2016-12-01 15:06:35] DEBUG [django.db.backends:90] (0.000) SELECT "django_migrations"."app", "django_migrations"."name" FROM "django_migrations"; args=()
[2016-12-01 15:06:46] DEBUG [django.db.backends:90] (0.000) SELECT "auths_user"."password", "auths_user"."last_login", "auths_user"."is_superuser", "auths_user"."username", "auths_user"."first_name", "auths_user"."last_name", "auths_user"."email", "auths_user"."is_staff", "auths_user"."is_active", "auths_user"."date_joined", "auths_user"."id", "auths_user"."last_hierarchy_id", "auths_user"."last_module_id", "auths_user"."person_id", "auths_user"."updated_at", "auths_user"."registered_by" FROM "auths_user" WHERE "auths_user"."username" = 'sal'; args=('sal',)
[2016-12-01 15:06:51] DEBUG [django.db.backends:90] (0.000) BEGIN; args=None
[2016-12-01 15:06:51] DEBUG [django.db.backends:90] (0.000) UPDATE "auths_user" SET "password" = 'pbkdf2_sha256$30000$e6pCrD7iSvoY$CLSzknM2BTPNeMbkdVboyzomKC57611zGshduOXYGEA=', "last_login" = NULL, "is_superuser" = 1, "username" = 'sal', "first_name" = '', "last_name" = '', "email" = '', "is_staff" = 1, "is_active" = 1, "date_joined" = '2016-12-01 21:06:51.417311', "last_hierarchy_id" = NULL, "last_module_id" = NULL, "person_id" = NULL, "updated_at" = '2016-12-01 21:06:51.464177', "registered_by" = NULL WHERE "auths_user"."id" = 'c6b3d7e2d92447bb837367847ca01ec7'; args=('pbkdf2_sha256$30000$e6pCrD7iSvoY$CLSzknM2BTPNeMbkdVboyzomKC57611zGshduOXYGEA=', True, 'sal', '', '', '', True, True, '2016-12-01 21:06:51.417311', '2016-12-01 21:06:51.464177', 'c6b3d7e2d92447bb837367847ca01ec7')
[2016-12-01 15:06:51] DEBUG [django.db.backends:90] (0.000) INSERT INTO "auths_user" ("password", "last_login", "is_superuser", "username", "first_name", "last_name", "email", "is_staff", "is_active", "date_joined", "id", "last_hierarchy_id", "last_module_id", "person_id", "updated_at", "registered_by") SELECT 'pbkdf2_sha256$30000$e6pCrD7iSvoY$CLSzknM2BTPNeMbkdVboyzomKC57611zGshduOXYGEA=', NULL, 1, 'sal', '', '', '', 1, 1, '2016-12-01 21:06:51.417311', 'c6b3d7e2d92447bb837367847ca01ec7', NULL, NULL, NULL, '2016-12-01 21:06:51.464177', NULL; args=('pbkdf2_sha256$30000$e6pCrD7iSvoY$CLSzknM2BTPNeMbkdVboyzomKC57611zGshduOXYGEA=', None, True, 'sal', '', '', '', True, True, '2016-12-01 21:06:51.417311', 'c6b3d7e2d92447bb837367847ca01ec7', None, None, None, '2016-12-01 21:06:51.464177', None)
[2016-12-01 15:07:50] DEBUG [django.db.backends:90] (0.000) 
            SELECT name, type FROM sqlite_master
            WHERE type in ('table', 'view') AND NOT name='sqlite_sequence'
            ORDER BY name; args=None
[2016-12-01 15:07:50] DEBUG [django.db.backends:90] (0.000) SELECT "django_migrations"."app", "django_migrations"."name" FROM "django_migrations"; args=()
[2016-12-01 15:13:44] DEBUG [django.db.backends:90] (0.000) 
            SELECT name, type FROM sqlite_master
            WHERE type in ('table', 'view') AND NOT name='sqlite_sequence'
            ORDER BY name; args=None
[2016-12-01 15:13:44] DEBUG [django.db.backends:90] (0.000) SELECT "django_migrations"."app", "django_migrations"."name" FROM "django_migrations"; args=()
[2016-12-01 15:43:21] DEBUG [django.template:929] Exception while resolving variable 'name' in template 'unknown'.
Traceback (most recent call last):
  File "D:\Project\redcashier\ve_redcashier\lib\site-packages\django\core\handlers\exception.py", line 39, in inner
    response = get_response(request)
  File "D:\Project\redcashier\ve_redcashier\lib\site-packages\django\core\handlers\base.py", line 249, in _legacy_get_response
    response = self._get_response(request)
  File "D:\Project\redcashier\ve_redcashier\lib\site-packages\django\core\handlers\base.py", line 172, in _get_response
    resolver_match = resolver.resolve(request.path_info)
  File "D:\Project\redcashier\ve_redcashier\lib\site-packages\django\urls\resolvers.py", line 300, in resolve
    raise Resolver404({'tried': tried, 'path': new_path})
django.urls.exceptions.Resolver404: {'tried': [[<RegexURLResolver <RegexURLPattern list> (admin:admin) ^admin/>], [<RegexURLResolver <module 'django.contrib.admindocs.urls' from 'D:\\Project\\redcashier\\ve_redcashier\\lib\\site-packages\\django\\contrib\\admindocs\\urls.py'> (None:None) ^admin/doc/>], [<RegexURLResolver <module 'rest_framework.urls' from 'D:\\Project\\redcashier\\ve_redcashier\\lib\\site-packages\\rest_framework\\urls.py'> (rest_framework:rest_framework) ^api-auth/>], [<RegexURLResolver <module 'oauth2_provider.urls' from 'D:\\Project\\redcashier\\ve_redcashier\\lib\\site-packages\\oauth2_provider\\urls.py'> (None:oauth2_provider) ^o/>], [<RegexURLResolver <module 'redcashier_service_apps.auths_api.urls' from 'D:\\Project\\redcashier\\redcashier_service\\redcashier_service_apps\\auths_api\\urls.py'> (None:None) ^api/auths/>], [<RegexURLResolver <module 'redcashier_service_apps.catalogo_api.urls' from 'D:\\Project\\redcashier\\redcashier_service\\redcashier_service_apps\\catalogo_api\\urls.py'> (None:None) ^api/catalogo/>], [<RegexURLResolver <module 'redcashier_service_apps.caja_api.urls' from 'D:\\Project\\redcashier\\redcashier_service\\redcashier_service_apps\\caja_api\\urls.py'> (None:None) ^api/caja/>]], 'path': ''}

During handling of the above exception, another exception occurred:

Traceback (most recent call last):
  File "D:\Project\redcashier\ve_redcashier\lib\site-packages\django\template\base.py", line 885, in _resolve_lookup
    current = current[bit]
TypeError: 'RegexURLResolver' object is not subscriptable

During handling of the above exception, another exception occurred:

Traceback (most recent call last):
  File "D:\Project\redcashier\ve_redcashier\lib\site-packages\django\template\base.py", line 893, in _resolve_lookup
    current = getattr(current, bit)
AttributeError: 'RegexURLResolver' object has no attribute 'name'

During handling of the above exception, another exception occurred:

Traceback (most recent call last):
  File "D:\Project\redcashier\ve_redcashier\lib\site-packages\django\template\base.py", line 900, in _resolve_lookup
    current = current[int(bit)]
ValueError: invalid literal for int() with base 10: 'name'

During handling of the above exception, another exception occurred:

Traceback (most recent call last):
  File "D:\Project\redcashier\ve_redcashier\lib\site-packages\django\template\base.py", line 907, in _resolve_lookup
    (bit, current))  # missing attribute
django.template.base.VariableDoesNotExist: Failed lookup for key [name] in '<RegexURLResolver <RegexURLPattern list> (admin:admin) ^admin/>'
[2016-12-01 15:43:21] DEBUG [django.template:929] Exception while resolving variable 'name' in template 'unknown'.
Traceback (most recent call last):
  File "D:\Project\redcashier\ve_redcashier\lib\site-packages\django\core\handlers\exception.py", line 39, in inner
    response = get_response(request)
  File "D:\Project\redcashier\ve_redcashier\lib\site-packages\django\core\handlers\base.py", line 249, in _legacy_get_response
    response = self._get_response(request)
  File "D:\Project\redcashier\ve_redcashier\lib\site-packages\django\core\handlers\base.py", line 172, in _get_response
    resolver_match = resolver.resolve(request.path_info)
  File "D:\Project\redcashier\ve_redcashier\lib\site-packages\django\urls\resolvers.py", line 300, in resolve
    raise Resolver404({'tried': tried, 'path': new_path})
django.urls.exceptions.Resolver404: {'tried': [[<RegexURLResolver <RegexURLPattern list> (admin:admin) ^admin/>], [<RegexURLResolver <module 'django.contrib.admindocs.urls' from 'D:\\Project\\redcashier\\ve_redcashier\\lib\\site-packages\\django\\contrib\\admindocs\\urls.py'> (None:None) ^admin/doc/>], [<RegexURLResolver <module 'rest_framework.urls' from 'D:\\Project\\redcashier\\ve_redcashier\\lib\\site-packages\\rest_framework\\urls.py'> (rest_framework:rest_framework) ^api-auth/>], [<RegexURLResolver <module 'oauth2_provider.urls' from 'D:\\Project\\redcashier\\ve_redcashier\\lib\\site-packages\\oauth2_provider\\urls.py'> (None:oauth2_provider) ^o/>], [<RegexURLResolver <module 'redcashier_service_apps.auths_api.urls' from 'D:\\Project\\redcashier\\redcashier_service\\redcashier_service_apps\\auths_api\\urls.py'> (None:None) ^api/auths/>], [<RegexURLResolver <module 'redcashier_service_apps.catalogo_api.urls' from 'D:\\Project\\redcashier\\redcashier_service\\redcashier_service_apps\\catalogo_api\\urls.py'> (None:None) ^api/catalogo/>], [<RegexURLResolver <module 'redcashier_service_apps.caja_api.urls' from 'D:\\Project\\redcashier\\redcashier_service\\redcashier_service_apps\\caja_api\\urls.py'> (None:None) ^api/caja/>]], 'path': ''}

During handling of the above exception, another exception occurred:

Traceback (most recent call last):
  File "D:\Project\redcashier\ve_redcashier\lib\site-packages\django\template\base.py", line 885, in _resolve_lookup
    current = current[bit]
TypeError: 'RegexURLResolver' object is not subscriptable

During handling of the above exception, another exception occurred:

Traceback (most recent call last):
  File "D:\Project\redcashier\ve_redcashier\lib\site-packages\django\template\base.py", line 893, in _resolve_lookup
    current = getattr(current, bit)
AttributeError: 'RegexURLResolver' object has no attribute 'name'

During handling of the above exception, another exception occurred:

Traceback (most recent call last):
  File "D:\Project\redcashier\ve_redcashier\lib\site-packages\django\template\base.py", line 900, in _resolve_lookup
    current = current[int(bit)]
ValueError: invalid literal for int() with base 10: 'name'

During handling of the above exception, another exception occurred:

Traceback (most recent call last):
  File "D:\Project\redcashier\ve_redcashier\lib\site-packages\django\template\base.py", line 907, in _resolve_lookup
    (bit, current))  # missing attribute
django.template.base.VariableDoesNotExist: Failed lookup for key [name] in "<RegexURLResolver <module 'django.contrib.admindocs.urls' from 'D:\\\\Project\\\\redcashier\\\\ve_redcashier\\\\lib\\\\site-packages\\\\django\\\\contrib\\\\admindocs\\\\urls.py'> (None:None) ^admin/doc/>"
[2016-12-01 15:43:21] DEBUG [django.template:929] Exception while resolving variable 'name' in template 'unknown'.
Traceback (most recent call last):
  File "D:\Project\redcashier\ve_redcashier\lib\site-packages\django\core\handlers\exception.py", line 39, in inner
    response = get_response(request)
  File "D:\Project\redcashier\ve_redcashier\lib\site-packages\django\core\handlers\base.py", line 249, in _legacy_get_response
    response = self._get_response(request)
  File "D:\Project\redcashier\ve_redcashier\lib\site-packages\django\core\handlers\base.py", line 172, in _get_response
    resolver_match = resolver.resolve(request.path_info)
  File "D:\Project\redcashier\ve_redcashier\lib\site-packages\django\urls\resolvers.py", line 300, in resolve
    raise Resolver404({'tried': tried, 'path': new_path})
django.urls.exceptions.Resolver404: {'tried': [[<RegexURLResolver <RegexURLPattern list> (admin:admin) ^admin/>], [<RegexURLResolver <module 'django.contrib.admindocs.urls' from 'D:\\Project\\redcashier\\ve_redcashier\\lib\\site-packages\\django\\contrib\\admindocs\\urls.py'> (None:None) ^admin/doc/>], [<RegexURLResolver <module 'rest_framework.urls' from 'D:\\Project\\redcashier\\ve_redcashier\\lib\\site-packages\\rest_framework\\urls.py'> (rest_framework:rest_framework) ^api-auth/>], [<RegexURLResolver <module 'oauth2_provider.urls' from 'D:\\Project\\redcashier\\ve_redcashier\\lib\\site-packages\\oauth2_provider\\urls.py'> (None:oauth2_provider) ^o/>], [<RegexURLResolver <module 'redcashier_service_apps.auths_api.urls' from 'D:\\Project\\redcashier\\redcashier_service\\redcashier_service_apps\\auths_api\\urls.py'> (None:None) ^api/auths/>], [<RegexURLResolver <module 'redcashier_service_apps.catalogo_api.urls' from 'D:\\Project\\redcashier\\redcashier_service\\redcashier_service_apps\\catalogo_api\\urls.py'> (None:None) ^api/catalogo/>], [<RegexURLResolver <module 'redcashier_service_apps.caja_api.urls' from 'D:\\Project\\redcashier\\redcashier_service\\redcashier_service_apps\\caja_api\\urls.py'> (None:None) ^api/caja/>]], 'path': ''}

During handling of the above exception, another exception occurred:

Traceback (most recent call last):
  File "D:\Project\redcashier\ve_redcashier\lib\site-packages\django\template\base.py", line 885, in _resolve_lookup
    current = current[bit]
TypeError: 'RegexURLResolver' object is not subscriptable

During handling of the above exception, another exception occurred:

Traceback (most recent call last):
  File "D:\Project\redcashier\ve_redcashier\lib\site-packages\django\template\base.py", line 893, in _resolve_lookup
    current = getattr(current, bit)
AttributeError: 'RegexURLResolver' object has no attribute 'name'

During handling of the above exception, another exception occurred:

Traceback (most recent call last):
  File "D:\Project\redcashier\ve_redcashier\lib\site-packages\django\template\base.py", line 900, in _resolve_lookup
    current = current[int(bit)]
ValueError: invalid literal for int() with base 10: 'name'

During handling of the above exception, another exception occurred:

Traceback (most recent call last):
  File "D:\Project\redcashier\ve_redcashier\lib\site-packages\django\template\base.py", line 907, in _resolve_lookup
    (bit, current))  # missing attribute
django.template.base.VariableDoesNotExist: Failed lookup for key [name] in "<RegexURLResolver <module 'rest_framework.urls' from 'D:\\\\Project\\\\redcashier\\\\ve_redcashier\\\\lib\\\\site-packages\\\\rest_framework\\\\urls.py'> (rest_framework:rest_framework) ^api-auth/>"
[2016-12-01 15:43:21] DEBUG [django.template:929] Exception while resolving variable 'name' in template 'unknown'.
Traceback (most recent call last):
  File "D:\Project\redcashier\ve_redcashier\lib\site-packages\django\core\handlers\exception.py", line 39, in inner
    response = get_response(request)
  File "D:\Project\redcashier\ve_redcashier\lib\site-packages\django\core\handlers\base.py", line 249, in _legacy_get_response
    response = self._get_response(request)
  File "D:\Project\redcashier\ve_redcashier\lib\site-packages\django\core\handlers\base.py", line 172, in _get_response
    resolver_match = resolver.resolve(request.path_info)
  File "D:\Project\redcashier\ve_redcashier\lib\site-packages\django\urls\resolvers.py", line 300, in resolve
    raise Resolver404({'tried': tried, 'path': new_path})
django.urls.exceptions.Resolver404: {'tried': [[<RegexURLResolver <RegexURLPattern list> (admin:admin) ^admin/>], [<RegexURLResolver <module 'django.contrib.admindocs.urls' from 'D:\\Project\\redcashier\\ve_redcashier\\lib\\site-packages\\django\\contrib\\admindocs\\urls.py'> (None:None) ^admin/doc/>], [<RegexURLResolver <module 'rest_framework.urls' from 'D:\\Project\\redcashier\\ve_redcashier\\lib\\site-packages\\rest_framework\\urls.py'> (rest_framework:rest_framework) ^api-auth/>], [<RegexURLResolver <module 'oauth2_provider.urls' from 'D:\\Project\\redcashier\\ve_redcashier\\lib\\site-packages\\oauth2_provider\\urls.py'> (None:oauth2_provider) ^o/>], [<RegexURLResolver <module 'redcashier_service_apps.auths_api.urls' from 'D:\\Project\\redcashier\\redcashier_service\\redcashier_service_apps\\auths_api\\urls.py'> (None:None) ^api/auths/>], [<RegexURLResolver <module 'redcashier_service_apps.catalogo_api.urls' from 'D:\\Project\\redcashier\\redcashier_service\\redcashier_service_apps\\catalogo_api\\urls.py'> (None:None) ^api/catalogo/>], [<RegexURLResolver <module 'redcashier_service_apps.caja_api.urls' from 'D:\\Project\\redcashier\\redcashier_service\\redcashier_service_apps\\caja_api\\urls.py'> (None:None) ^api/caja/>]], 'path': ''}

During handling of the above exception, another exception occurred:

Traceback (most recent call last):
  File "D:\Project\redcashier\ve_redcashier\lib\site-packages\django\template\base.py", line 885, in _resolve_lookup
    current = current[bit]
TypeError: 'RegexURLResolver' object is not subscriptable

During handling of the above exception, another exception occurred:

Traceback (most recent call last):
  File "D:\Project\redcashier\ve_redcashier\lib\site-packages\django\template\base.py", line 893, in _resolve_lookup
    current = getattr(current, bit)
AttributeError: 'RegexURLResolver' object has no attribute 'name'

During handling of the above exception, another exception occurred:

Traceback (most recent call last):
  File "D:\Project\redcashier\ve_redcashier\lib\site-packages\django\template\base.py", line 900, in _resolve_lookup
    current = current[int(bit)]
ValueError: invalid literal for int() with base 10: 'name'

During handling of the above exception, another exception occurred:

Traceback (most recent call last):
  File "D:\Project\redcashier\ve_redcashier\lib\site-packages\django\template\base.py", line 907, in _resolve_lookup
    (bit, current))  # missing attribute
django.template.base.VariableDoesNotExist: Failed lookup for key [name] in "<RegexURLResolver <module 'oauth2_provider.urls' from 'D:\\\\Project\\\\redcashier\\\\ve_redcashier\\\\lib\\\\site-packages\\\\oauth2_provider\\\\urls.py'> (None:oauth2_provider) ^o/>"
[2016-12-01 15:43:21] DEBUG [django.template:929] Exception while resolving variable 'name' in template 'unknown'.
Traceback (most recent call last):
  File "D:\Project\redcashier\ve_redcashier\lib\site-packages\django\core\handlers\exception.py", line 39, in inner
    response = get_response(request)
  File "D:\Project\redcashier\ve_redcashier\lib\site-packages\django\core\handlers\base.py", line 249, in _legacy_get_response
    response = self._get_response(request)
  File "D:\Project\redcashier\ve_redcashier\lib\site-packages\django\core\handlers\base.py", line 172, in _get_response
    resolver_match = resolver.resolve(request.path_info)
  File "D:\Project\redcashier\ve_redcashier\lib\site-packages\django\urls\resolvers.py", line 300, in resolve
    raise Resolver404({'tried': tried, 'path': new_path})
django.urls.exceptions.Resolver404: {'tried': [[<RegexURLResolver <RegexURLPattern list> (admin:admin) ^admin/>], [<RegexURLResolver <module 'django.contrib.admindocs.urls' from 'D:\\Project\\redcashier\\ve_redcashier\\lib\\site-packages\\django\\contrib\\admindocs\\urls.py'> (None:None) ^admin/doc/>], [<RegexURLResolver <module 'rest_framework.urls' from 'D:\\Project\\redcashier\\ve_redcashier\\lib\\site-packages\\rest_framework\\urls.py'> (rest_framework:rest_framework) ^api-auth/>], [<RegexURLResolver <module 'oauth2_provider.urls' from 'D:\\Project\\redcashier\\ve_redcashier\\lib\\site-packages\\oauth2_provider\\urls.py'> (None:oauth2_provider) ^o/>], [<RegexURLResolver <module 'redcashier_service_apps.auths_api.urls' from 'D:\\Project\\redcashier\\redcashier_service\\redcashier_service_apps\\auths_api\\urls.py'> (None:None) ^api/auths/>], [<RegexURLResolver <module 'redcashier_service_apps.catalogo_api.urls' from 'D:\\Project\\redcashier\\redcashier_service\\redcashier_service_apps\\catalogo_api\\urls.py'> (None:None) ^api/catalogo/>], [<RegexURLResolver <module 'redcashier_service_apps.caja_api.urls' from 'D:\\Project\\redcashier\\redcashier_service\\redcashier_service_apps\\caja_api\\urls.py'> (None:None) ^api/caja/>]], 'path': ''}

During handling of the above exception, another exception occurred:

Traceback (most recent call last):
  File "D:\Project\redcashier\ve_redcashier\lib\site-packages\django\template\base.py", line 885, in _resolve_lookup
    current = current[bit]
TypeError: 'RegexURLResolver' object is not subscriptable

During handling of the above exception, another exception occurred:

Traceback (most recent call last):
  File "D:\Project\redcashier\ve_redcashier\lib\site-packages\django\template\base.py", line 893, in _resolve_lookup
    current = getattr(current, bit)
AttributeError: 'RegexURLResolver' object has no attribute 'name'

During handling of the above exception, another exception occurred:

Traceback (most recent call last):
  File "D:\Project\redcashier\ve_redcashier\lib\site-packages\django\template\base.py", line 900, in _resolve_lookup
    current = current[int(bit)]
ValueError: invalid literal for int() with base 10: 'name'

During handling of the above exception, another exception occurred:

Traceback (most recent call last):
  File "D:\Project\redcashier\ve_redcashier\lib\site-packages\django\template\base.py", line 907, in _resolve_lookup
    (bit, current))  # missing attribute
django.template.base.VariableDoesNotExist: Failed lookup for key [name] in "<RegexURLResolver <module 'redcashier_service_apps.auths_api.urls' from 'D:\\\\Project\\\\redcashier\\\\redcashier_service\\\\redcashier_service_apps\\\\auths_api\\\\urls.py'> (None:None) ^api/auths/>"
[2016-12-01 15:43:21] DEBUG [django.template:929] Exception while resolving variable 'name' in template 'unknown'.
Traceback (most recent call last):
  File "D:\Project\redcashier\ve_redcashier\lib\site-packages\django\core\handlers\exception.py", line 39, in inner
    response = get_response(request)
  File "D:\Project\redcashier\ve_redcashier\lib\site-packages\django\core\handlers\base.py", line 249, in _legacy_get_response
    response = self._get_response(request)
  File "D:\Project\redcashier\ve_redcashier\lib\site-packages\django\core\handlers\base.py", line 172, in _get_response
    resolver_match = resolver.resolve(request.path_info)
  File "D:\Project\redcashier\ve_redcashier\lib\site-packages\django\urls\resolvers.py", line 300, in resolve
    raise Resolver404({'tried': tried, 'path': new_path})
django.urls.exceptions.Resolver404: {'tried': [[<RegexURLResolver <RegexURLPattern list> (admin:admin) ^admin/>], [<RegexURLResolver <module 'django.contrib.admindocs.urls' from 'D:\\Project\\redcashier\\ve_redcashier\\lib\\site-packages\\django\\contrib\\admindocs\\urls.py'> (None:None) ^admin/doc/>], [<RegexURLResolver <module 'rest_framework.urls' from 'D:\\Project\\redcashier\\ve_redcashier\\lib\\site-packages\\rest_framework\\urls.py'> (rest_framework:rest_framework) ^api-auth/>], [<RegexURLResolver <module 'oauth2_provider.urls' from 'D:\\Project\\redcashier\\ve_redcashier\\lib\\site-packages\\oauth2_provider\\urls.py'> (None:oauth2_provider) ^o/>], [<RegexURLResolver <module 'redcashier_service_apps.auths_api.urls' from 'D:\\Project\\redcashier\\redcashier_service\\redcashier_service_apps\\auths_api\\urls.py'> (None:None) ^api/auths/>], [<RegexURLResolver <module 'redcashier_service_apps.catalogo_api.urls' from 'D:\\Project\\redcashier\\redcashier_service\\redcashier_service_apps\\catalogo_api\\urls.py'> (None:None) ^api/catalogo/>], [<RegexURLResolver <module 'redcashier_service_apps.caja_api.urls' from 'D:\\Project\\redcashier\\redcashier_service\\redcashier_service_apps\\caja_api\\urls.py'> (None:None) ^api/caja/>]], 'path': ''}

During handling of the above exception, another exception occurred:

Traceback (most recent call last):
  File "D:\Project\redcashier\ve_redcashier\lib\site-packages\django\template\base.py", line 885, in _resolve_lookup
    current = current[bit]
TypeError: 'RegexURLResolver' object is not subscriptable

During handling of the above exception, another exception occurred:

Traceback (most recent call last):
  File "D:\Project\redcashier\ve_redcashier\lib\site-packages\django\template\base.py", line 893, in _resolve_lookup
    current = getattr(current, bit)
AttributeError: 'RegexURLResolver' object has no attribute 'name'

During handling of the above exception, another exception occurred:

Traceback (most recent call last):
  File "D:\Project\redcashier\ve_redcashier\lib\site-packages\django\template\base.py", line 900, in _resolve_lookup
    current = current[int(bit)]
ValueError: invalid literal for int() with base 10: 'name'

During handling of the above exception, another exception occurred:

Traceback (most recent call last):
  File "D:\Project\redcashier\ve_redcashier\lib\site-packages\django\template\base.py", line 907, in _resolve_lookup
    (bit, current))  # missing attribute
django.template.base.VariableDoesNotExist: Failed lookup for key [name] in "<RegexURLResolver <module 'redcashier_service_apps.catalogo_api.urls' from 'D:\\\\Project\\\\redcashier\\\\redcashier_service\\\\redcashier_service_apps\\\\catalogo_api\\\\urls.py'> (None:None) ^api/catalogo/>"
[2016-12-01 15:43:21] DEBUG [django.template:929] Exception while resolving variable 'name' in template 'unknown'.
Traceback (most recent call last):
  File "D:\Project\redcashier\ve_redcashier\lib\site-packages\django\core\handlers\exception.py", line 39, in inner
    response = get_response(request)
  File "D:\Project\redcashier\ve_redcashier\lib\site-packages\django\core\handlers\base.py", line 249, in _legacy_get_response
    response = self._get_response(request)
  File "D:\Project\redcashier\ve_redcashier\lib\site-packages\django\core\handlers\base.py", line 172, in _get_response
    resolver_match = resolver.resolve(request.path_info)
  File "D:\Project\redcashier\ve_redcashier\lib\site-packages\django\urls\resolvers.py", line 300, in resolve
    raise Resolver404({'tried': tried, 'path': new_path})
django.urls.exceptions.Resolver404: {'tried': [[<RegexURLResolver <RegexURLPattern list> (admin:admin) ^admin/>], [<RegexURLResolver <module 'django.contrib.admindocs.urls' from 'D:\\Project\\redcashier\\ve_redcashier\\lib\\site-packages\\django\\contrib\\admindocs\\urls.py'> (None:None) ^admin/doc/>], [<RegexURLResolver <module 'rest_framework.urls' from 'D:\\Project\\redcashier\\ve_redcashier\\lib\\site-packages\\rest_framework\\urls.py'> (rest_framework:rest_framework) ^api-auth/>], [<RegexURLResolver <module 'oauth2_provider.urls' from 'D:\\Project\\redcashier\\ve_redcashier\\lib\\site-packages\\oauth2_provider\\urls.py'> (None:oauth2_provider) ^o/>], [<RegexURLResolver <module 'redcashier_service_apps.auths_api.urls' from 'D:\\Project\\redcashier\\redcashier_service\\redcashier_service_apps\\auths_api\\urls.py'> (None:None) ^api/auths/>], [<RegexURLResolver <module 'redcashier_service_apps.catalogo_api.urls' from 'D:\\Project\\redcashier\\redcashier_service\\redcashier_service_apps\\catalogo_api\\urls.py'> (None:None) ^api/catalogo/>], [<RegexURLResolver <module 'redcashier_service_apps.caja_api.urls' from 'D:\\Project\\redcashier\\redcashier_service\\redcashier_service_apps\\caja_api\\urls.py'> (None:None) ^api/caja/>]], 'path': ''}

During handling of the above exception, another exception occurred:

Traceback (most recent call last):
  File "D:\Project\redcashier\ve_redcashier\lib\site-packages\django\template\base.py", line 885, in _resolve_lookup
    current = current[bit]
TypeError: 'RegexURLResolver' object is not subscriptable

During handling of the above exception, another exception occurred:

Traceback (most recent call last):
  File "D:\Project\redcashier\ve_redcashier\lib\site-packages\django\template\base.py", line 893, in _resolve_lookup
    current = getattr(current, bit)
AttributeError: 'RegexURLResolver' object has no attribute 'name'

During handling of the above exception, another exception occurred:

Traceback (most recent call last):
  File "D:\Project\redcashier\ve_redcashier\lib\site-packages\django\template\base.py", line 900, in _resolve_lookup
    current = current[int(bit)]
ValueError: invalid literal for int() with base 10: 'name'

During handling of the above exception, another exception occurred:

Traceback (most recent call last):
  File "D:\Project\redcashier\ve_redcashier\lib\site-packages\django\template\base.py", line 907, in _resolve_lookup
    (bit, current))  # missing attribute
django.template.base.VariableDoesNotExist: Failed lookup for key [name] in "<RegexURLResolver <module 'redcashier_service_apps.caja_api.urls' from 'D:\\\\Project\\\\redcashier\\\\redcashier_service\\\\redcashier_service_apps\\\\caja_api\\\\urls.py'> (None:None) ^api/caja/>"
[2016-12-01 15:43:21] WARNING [django.request:152] Not Found: /
[2016-12-01 15:43:21] WARNING [django.server:131] "GET / HTTP/1.1" 404 2571
[2016-12-01 15:43:21] DEBUG [django.template:929] Exception while resolving variable 'name' in template 'unknown'.
Traceback (most recent call last):
  File "D:\Project\redcashier\ve_redcashier\lib\site-packages\django\core\handlers\exception.py", line 39, in inner
    response = get_response(request)
  File "D:\Project\redcashier\ve_redcashier\lib\site-packages\django\core\handlers\base.py", line 249, in _legacy_get_response
    response = self._get_response(request)
  File "D:\Project\redcashier\ve_redcashier\lib\site-packages\django\core\handlers\base.py", line 172, in _get_response
    resolver_match = resolver.resolve(request.path_info)
  File "D:\Project\redcashier\ve_redcashier\lib\site-packages\django\urls\resolvers.py", line 300, in resolve
    raise Resolver404({'tried': tried, 'path': new_path})
django.urls.exceptions.Resolver404: {'tried': [[<RegexURLResolver <RegexURLPattern list> (admin:admin) ^admin/>], [<RegexURLResolver <module 'django.contrib.admindocs.urls' from 'D:\\Project\\redcashier\\ve_redcashier\\lib\\site-packages\\django\\contrib\\admindocs\\urls.py'> (None:None) ^admin/doc/>], [<RegexURLResolver <module 'rest_framework.urls' from 'D:\\Project\\redcashier\\ve_redcashier\\lib\\site-packages\\rest_framework\\urls.py'> (rest_framework:rest_framework) ^api-auth/>], [<RegexURLResolver <module 'oauth2_provider.urls' from 'D:\\Project\\redcashier\\ve_redcashier\\lib\\site-packages\\oauth2_provider\\urls.py'> (None:oauth2_provider) ^o/>], [<RegexURLResolver <module 'redcashier_service_apps.auths_api.urls' from 'D:\\Project\\redcashier\\redcashier_service\\redcashier_service_apps\\auths_api\\urls.py'> (None:None) ^api/auths/>], [<RegexURLResolver <module 'redcashier_service_apps.catalogo_api.urls' from 'D:\\Project\\redcashier\\redcashier_service\\redcashier_service_apps\\catalogo_api\\urls.py'> (None:None) ^api/catalogo/>], [<RegexURLResolver <module 'redcashier_service_apps.caja_api.urls' from 'D:\\Project\\redcashier\\redcashier_service\\redcashier_service_apps\\caja_api\\urls.py'> (None:None) ^api/caja/>]], 'path': 'favicon.ico'}

During handling of the above exception, another exception occurred:

Traceback (most recent call last):
  File "D:\Project\redcashier\ve_redcashier\lib\site-packages\django\template\base.py", line 885, in _resolve_lookup
    current = current[bit]
TypeError: 'RegexURLResolver' object is not subscriptable

During handling of the above exception, another exception occurred:

Traceback (most recent call last):
  File "D:\Project\redcashier\ve_redcashier\lib\site-packages\django\template\base.py", line 893, in _resolve_lookup
    current = getattr(current, bit)
AttributeError: 'RegexURLResolver' object has no attribute 'name'

During handling of the above exception, another exception occurred:

Traceback (most recent call last):
  File "D:\Project\redcashier\ve_redcashier\lib\site-packages\django\template\base.py", line 900, in _resolve_lookup
    current = current[int(bit)]
ValueError: invalid literal for int() with base 10: 'name'

During handling of the above exception, another exception occurred:

Traceback (most recent call last):
  File "D:\Project\redcashier\ve_redcashier\lib\site-packages\django\template\base.py", line 907, in _resolve_lookup
    (bit, current))  # missing attribute
django.template.base.VariableDoesNotExist: Failed lookup for key [name] in '<RegexURLResolver <RegexURLPattern list> (admin:admin) ^admin/>'
[2016-12-01 15:43:21] DEBUG [django.template:929] Exception while resolving variable 'name' in template 'unknown'.
Traceback (most recent call last):
  File "D:\Project\redcashier\ve_redcashier\lib\site-packages\django\core\handlers\exception.py", line 39, in inner
    response = get_response(request)
  File "D:\Project\redcashier\ve_redcashier\lib\site-packages\django\core\handlers\base.py", line 249, in _legacy_get_response
    response = self._get_response(request)
  File "D:\Project\redcashier\ve_redcashier\lib\site-packages\django\core\handlers\base.py", line 172, in _get_response
    resolver_match = resolver.resolve(request.path_info)
  File "D:\Project\redcashier\ve_redcashier\lib\site-packages\django\urls\resolvers.py", line 300, in resolve
    raise Resolver404({'tried': tried, 'path': new_path})
django.urls.exceptions.Resolver404: {'tried': [[<RegexURLResolver <RegexURLPattern list> (admin:admin) ^admin/>], [<RegexURLResolver <module 'django.contrib.admindocs.urls' from 'D:\\Project\\redcashier\\ve_redcashier\\lib\\site-packages\\django\\contrib\\admindocs\\urls.py'> (None:None) ^admin/doc/>], [<RegexURLResolver <module 'rest_framework.urls' from 'D:\\Project\\redcashier\\ve_redcashier\\lib\\site-packages\\rest_framework\\urls.py'> (rest_framework:rest_framework) ^api-auth/>], [<RegexURLResolver <module 'oauth2_provider.urls' from 'D:\\Project\\redcashier\\ve_redcashier\\lib\\site-packages\\oauth2_provider\\urls.py'> (None:oauth2_provider) ^o/>], [<RegexURLResolver <module 'redcashier_service_apps.auths_api.urls' from 'D:\\Project\\redcashier\\redcashier_service\\redcashier_service_apps\\auths_api\\urls.py'> (None:None) ^api/auths/>], [<RegexURLResolver <module 'redcashier_service_apps.catalogo_api.urls' from 'D:\\Project\\redcashier\\redcashier_service\\redcashier_service_apps\\catalogo_api\\urls.py'> (None:None) ^api/catalogo/>], [<RegexURLResolver <module 'redcashier_service_apps.caja_api.urls' from 'D:\\Project\\redcashier\\redcashier_service\\redcashier_service_apps\\caja_api\\urls.py'> (None:None) ^api/caja/>]], 'path': 'favicon.ico'}

During handling of the above exception, another exception occurred:

Traceback (most recent call last):
  File "D:\Project\redcashier\ve_redcashier\lib\site-packages\django\template\base.py", line 885, in _resolve_lookup
    current = current[bit]
TypeError: 'RegexURLResolver' object is not subscriptable

During handling of the above exception, another exception occurred:

Traceback (most recent call last):
  File "D:\Project\redcashier\ve_redcashier\lib\site-packages\django\template\base.py", line 893, in _resolve_lookup
    current = getattr(current, bit)
AttributeError: 'RegexURLResolver' object has no attribute 'name'

During handling of the above exception, another exception occurred:

Traceback (most recent call last):
  File "D:\Project\redcashier\ve_redcashier\lib\site-packages\django\template\base.py", line 900, in _resolve_lookup
    current = current[int(bit)]
ValueError: invalid literal for int() with base 10: 'name'

During handling of the above exception, another exception occurred:

Traceback (most recent call last):
  File "D:\Project\redcashier\ve_redcashier\lib\site-packages\django\template\base.py", line 907, in _resolve_lookup
    (bit, current))  # missing attribute
django.template.base.VariableDoesNotExist: Failed lookup for key [name] in "<RegexURLResolver <module 'django.contrib.admindocs.urls' from 'D:\\\\Project\\\\redcashier\\\\ve_redcashier\\\\lib\\\\site-packages\\\\django\\\\contrib\\\\admindocs\\\\urls.py'> (None:None) ^admin/doc/>"
[2016-12-01 15:43:21] DEBUG [django.template:929] Exception while resolving variable 'name' in template 'unknown'.
Traceback (most recent call last):
  File "D:\Project\redcashier\ve_redcashier\lib\site-packages\django\core\handlers\exception.py", line 39, in inner
    response = get_response(request)
  File "D:\Project\redcashier\ve_redcashier\lib\site-packages\django\core\handlers\base.py", line 249, in _legacy_get_response
    response = self._get_response(request)
  File "D:\Project\redcashier\ve_redcashier\lib\site-packages\django\core\handlers\base.py", line 172, in _get_response
    resolver_match = resolver.resolve(request.path_info)
  File "D:\Project\redcashier\ve_redcashier\lib\site-packages\django\urls\resolvers.py", line 300, in resolve
    raise Resolver404({'tried': tried, 'path': new_path})
django.urls.exceptions.Resolver404: {'tried': [[<RegexURLResolver <RegexURLPattern list> (admin:admin) ^admin/>], [<RegexURLResolver <module 'django.contrib.admindocs.urls' from 'D:\\Project\\redcashier\\ve_redcashier\\lib\\site-packages\\django\\contrib\\admindocs\\urls.py'> (None:None) ^admin/doc/>], [<RegexURLResolver <module 'rest_framework.urls' from 'D:\\Project\\redcashier\\ve_redcashier\\lib\\site-packages\\rest_framework\\urls.py'> (rest_framework:rest_framework) ^api-auth/>], [<RegexURLResolver <module 'oauth2_provider.urls' from 'D:\\Project\\redcashier\\ve_redcashier\\lib\\site-packages\\oauth2_provider\\urls.py'> (None:oauth2_provider) ^o/>], [<RegexURLResolver <module 'redcashier_service_apps.auths_api.urls' from 'D:\\Project\\redcashier\\redcashier_service\\redcashier_service_apps\\auths_api\\urls.py'> (None:None) ^api/auths/>], [<RegexURLResolver <module 'redcashier_service_apps.catalogo_api.urls' from 'D:\\Project\\redcashier\\redcashier_service\\redcashier_service_apps\\catalogo_api\\urls.py'> (None:None) ^api/catalogo/>], [<RegexURLResolver <module 'redcashier_service_apps.caja_api.urls' from 'D:\\Project\\redcashier\\redcashier_service\\redcashier_service_apps\\caja_api\\urls.py'> (None:None) ^api/caja/>]], 'path': 'favicon.ico'}

During handling of the above exception, another exception occurred:

Traceback (most recent call last):
  File "D:\Project\redcashier\ve_redcashier\lib\site-packages\django\template\base.py", line 885, in _resolve_lookup
    current = current[bit]
TypeError: 'RegexURLResolver' object is not subscriptable

During handling of the above exception, another exception occurred:

Traceback (most recent call last):
  File "D:\Project\redcashier\ve_redcashier\lib\site-packages\django\template\base.py", line 893, in _resolve_lookup
    current = getattr(current, bit)
AttributeError: 'RegexURLResolver' object has no attribute 'name'

During handling of the above exception, another exception occurred:

Traceback (most recent call last):
  File "D:\Project\redcashier\ve_redcashier\lib\site-packages\django\template\base.py", line 900, in _resolve_lookup
    current = current[int(bit)]
ValueError: invalid literal for int() with base 10: 'name'

During handling of the above exception, another exception occurred:

Traceback (most recent call last):
  File "D:\Project\redcashier\ve_redcashier\lib\site-packages\django\template\base.py", line 907, in _resolve_lookup
    (bit, current))  # missing attribute
django.template.base.VariableDoesNotExist: Failed lookup for key [name] in "<RegexURLResolver <module 'rest_framework.urls' from 'D:\\\\Project\\\\redcashier\\\\ve_redcashier\\\\lib\\\\site-packages\\\\rest_framework\\\\urls.py'> (rest_framework:rest_framework) ^api-auth/>"
[2016-12-01 15:43:21] DEBUG [django.template:929] Exception while resolving variable 'name' in template 'unknown'.
Traceback (most recent call last):
  File "D:\Project\redcashier\ve_redcashier\lib\site-packages\django\core\handlers\exception.py", line 39, in inner
    response = get_response(request)
  File "D:\Project\redcashier\ve_redcashier\lib\site-packages\django\core\handlers\base.py", line 249, in _legacy_get_response
    response = self._get_response(request)
  File "D:\Project\redcashier\ve_redcashier\lib\site-packages\django\core\handlers\base.py", line 172, in _get_response
    resolver_match = resolver.resolve(request.path_info)
  File "D:\Project\redcashier\ve_redcashier\lib\site-packages\django\urls\resolvers.py", line 300, in resolve
    raise Resolver404({'tried': tried, 'path': new_path})
django.urls.exceptions.Resolver404: {'tried': [[<RegexURLResolver <RegexURLPattern list> (admin:admin) ^admin/>], [<RegexURLResolver <module 'django.contrib.admindocs.urls' from 'D:\\Project\\redcashier\\ve_redcashier\\lib\\site-packages\\django\\contrib\\admindocs\\urls.py'> (None:None) ^admin/doc/>], [<RegexURLResolver <module 'rest_framework.urls' from 'D:\\Project\\redcashier\\ve_redcashier\\lib\\site-packages\\rest_framework\\urls.py'> (rest_framework:rest_framework) ^api-auth/>], [<RegexURLResolver <module 'oauth2_provider.urls' from 'D:\\Project\\redcashier\\ve_redcashier\\lib\\site-packages\\oauth2_provider\\urls.py'> (None:oauth2_provider) ^o/>], [<RegexURLResolver <module 'redcashier_service_apps.auths_api.urls' from 'D:\\Project\\redcashier\\redcashier_service\\redcashier_service_apps\\auths_api\\urls.py'> (None:None) ^api/auths/>], [<RegexURLResolver <module 'redcashier_service_apps.catalogo_api.urls' from 'D:\\Project\\redcashier\\redcashier_service\\redcashier_service_apps\\catalogo_api\\urls.py'> (None:None) ^api/catalogo/>], [<RegexURLResolver <module 'redcashier_service_apps.caja_api.urls' from 'D:\\Project\\redcashier\\redcashier_service\\redcashier_service_apps\\caja_api\\urls.py'> (None:None) ^api/caja/>]], 'path': 'favicon.ico'}

During handling of the above exception, another exception occurred:

Traceback (most recent call last):
  File "D:\Project\redcashier\ve_redcashier\lib\site-packages\django\template\base.py", line 885, in _resolve_lookup
    current = current[bit]
TypeError: 'RegexURLResolver' object is not subscriptable

During handling of the above exception, another exception occurred:

Traceback (most recent call last):
  File "D:\Project\redcashier\ve_redcashier\lib\site-packages\django\template\base.py", line 893, in _resolve_lookup
    current = getattr(current, bit)
AttributeError: 'RegexURLResolver' object has no attribute 'name'

During handling of the above exception, another exception occurred:

Traceback (most recent call last):
  File "D:\Project\redcashier\ve_redcashier\lib\site-packages\django\template\base.py", line 900, in _resolve_lookup
    current = current[int(bit)]
ValueError: invalid literal for int() with base 10: 'name'

During handling of the above exception, another exception occurred:

Traceback (most recent call last):
  File "D:\Project\redcashier\ve_redcashier\lib\site-packages\django\template\base.py", line 907, in _resolve_lookup
    (bit, current))  # missing attribute
django.template.base.VariableDoesNotExist: Failed lookup for key [name] in "<RegexURLResolver <module 'oauth2_provider.urls' from 'D:\\\\Project\\\\redcashier\\\\ve_redcashier\\\\lib\\\\site-packages\\\\oauth2_provider\\\\urls.py'> (None:oauth2_provider) ^o/>"
[2016-12-01 15:43:21] DEBUG [django.template:929] Exception while resolving variable 'name' in template 'unknown'.
Traceback (most recent call last):
  File "D:\Project\redcashier\ve_redcashier\lib\site-packages\django\core\handlers\exception.py", line 39, in inner
    response = get_response(request)
  File "D:\Project\redcashier\ve_redcashier\lib\site-packages\django\core\handlers\base.py", line 249, in _legacy_get_response
    response = self._get_response(request)
  File "D:\Project\redcashier\ve_redcashier\lib\site-packages\django\core\handlers\base.py", line 172, in _get_response
    resolver_match = resolver.resolve(request.path_info)
  File "D:\Project\redcashier\ve_redcashier\lib\site-packages\django\urls\resolvers.py", line 300, in resolve
    raise Resolver404({'tried': tried, 'path': new_path})
django.urls.exceptions.Resolver404: {'tried': [[<RegexURLResolver <RegexURLPattern list> (admin:admin) ^admin/>], [<RegexURLResolver <module 'django.contrib.admindocs.urls' from 'D:\\Project\\redcashier\\ve_redcashier\\lib\\site-packages\\django\\contrib\\admindocs\\urls.py'> (None:None) ^admin/doc/>], [<RegexURLResolver <module 'rest_framework.urls' from 'D:\\Project\\redcashier\\ve_redcashier\\lib\\site-packages\\rest_framework\\urls.py'> (rest_framework:rest_framework) ^api-auth/>], [<RegexURLResolver <module 'oauth2_provider.urls' from 'D:\\Project\\redcashier\\ve_redcashier\\lib\\site-packages\\oauth2_provider\\urls.py'> (None:oauth2_provider) ^o/>], [<RegexURLResolver <module 'redcashier_service_apps.auths_api.urls' from 'D:\\Project\\redcashier\\redcashier_service\\redcashier_service_apps\\auths_api\\urls.py'> (None:None) ^api/auths/>], [<RegexURLResolver <module 'redcashier_service_apps.catalogo_api.urls' from 'D:\\Project\\redcashier\\redcashier_service\\redcashier_service_apps\\catalogo_api\\urls.py'> (None:None) ^api/catalogo/>], [<RegexURLResolver <module 'redcashier_service_apps.caja_api.urls' from 'D:\\Project\\redcashier\\redcashier_service\\redcashier_service_apps\\caja_api\\urls.py'> (None:None) ^api/caja/>]], 'path': 'favicon.ico'}

During handling of the above exception, another exception occurred:

Traceback (most recent call last):
  File "D:\Project\redcashier\ve_redcashier\lib\site-packages\django\template\base.py", line 885, in _resolve_lookup
    current = current[bit]
TypeError: 'RegexURLResolver' object is not subscriptable

During handling of the above exception, another exception occurred:

Traceback (most recent call last):
  File "D:\Project\redcashier\ve_redcashier\lib\site-packages\django\template\base.py", line 893, in _resolve_lookup
    current = getattr(current, bit)
AttributeError: 'RegexURLResolver' object has no attribute 'name'

During handling of the above exception, another exception occurred:

Traceback (most recent call last):
  File "D:\Project\redcashier\ve_redcashier\lib\site-packages\django\template\base.py", line 900, in _resolve_lookup
    current = current[int(bit)]
ValueError: invalid literal for int() with base 10: 'name'

During handling of the above exception, another exception occurred:

Traceback (most recent call last):
  File "D:\Project\redcashier\ve_redcashier\lib\site-packages\django\template\base.py", line 907, in _resolve_lookup
    (bit, current))  # missing attribute
django.template.base.VariableDoesNotExist: Failed lookup for key [name] in "<RegexURLResolver <module 'redcashier_service_apps.auths_api.urls' from 'D:\\\\Project\\\\redcashier\\\\redcashier_service\\\\redcashier_service_apps\\\\auths_api\\\\urls.py'> (None:None) ^api/auths/>"
[2016-12-01 15:43:21] DEBUG [django.template:929] Exception while resolving variable 'name' in template 'unknown'.
Traceback (most recent call last):
  File "D:\Project\redcashier\ve_redcashier\lib\site-packages\django\core\handlers\exception.py", line 39, in inner
    response = get_response(request)
  File "D:\Project\redcashier\ve_redcashier\lib\site-packages\django\core\handlers\base.py", line 249, in _legacy_get_response
    response = self._get_response(request)
  File "D:\Project\redcashier\ve_redcashier\lib\site-packages\django\core\handlers\base.py", line 172, in _get_response
    resolver_match = resolver.resolve(request.path_info)
  File "D:\Project\redcashier\ve_redcashier\lib\site-packages\django\urls\resolvers.py", line 300, in resolve
    raise Resolver404({'tried': tried, 'path': new_path})
django.urls.exceptions.Resolver404: {'tried': [[<RegexURLResolver <RegexURLPattern list> (admin:admin) ^admin/>], [<RegexURLResolver <module 'django.contrib.admindocs.urls' from 'D:\\Project\\redcashier\\ve_redcashier\\lib\\site-packages\\django\\contrib\\admindocs\\urls.py'> (None:None) ^admin/doc/>], [<RegexURLResolver <module 'rest_framework.urls' from 'D:\\Project\\redcashier\\ve_redcashier\\lib\\site-packages\\rest_framework\\urls.py'> (rest_framework:rest_framework) ^api-auth/>], [<RegexURLResolver <module 'oauth2_provider.urls' from 'D:\\Project\\redcashier\\ve_redcashier\\lib\\site-packages\\oauth2_provider\\urls.py'> (None:oauth2_provider) ^o/>], [<RegexURLResolver <module 'redcashier_service_apps.auths_api.urls' from 'D:\\Project\\redcashier\\redcashier_service\\redcashier_service_apps\\auths_api\\urls.py'> (None:None) ^api/auths/>], [<RegexURLResolver <module 'redcashier_service_apps.catalogo_api.urls' from 'D:\\Project\\redcashier\\redcashier_service\\redcashier_service_apps\\catalogo_api\\urls.py'> (None:None) ^api/catalogo/>], [<RegexURLResolver <module 'redcashier_service_apps.caja_api.urls' from 'D:\\Project\\redcashier\\redcashier_service\\redcashier_service_apps\\caja_api\\urls.py'> (None:None) ^api/caja/>]], 'path': 'favicon.ico'}

During handling of the above exception, another exception occurred:

Traceback (most recent call last):
  File "D:\Project\redcashier\ve_redcashier\lib\site-packages\django\template\base.py", line 885, in _resolve_lookup
    current = current[bit]
TypeError: 'RegexURLResolver' object is not subscriptable

During handling of the above exception, another exception occurred:

Traceback (most recent call last):
  File "D:\Project\redcashier\ve_redcashier\lib\site-packages\django\template\base.py", line 893, in _resolve_lookup
    current = getattr(current, bit)
AttributeError: 'RegexURLResolver' object has no attribute 'name'

During handling of the above exception, another exception occurred:

Traceback (most recent call last):
  File "D:\Project\redcashier\ve_redcashier\lib\site-packages\django\template\base.py", line 900, in _resolve_lookup
    current = current[int(bit)]
ValueError: invalid literal for int() with base 10: 'name'

During handling of the above exception, another exception occurred:

Traceback (most recent call last):
  File "D:\Project\redcashier\ve_redcashier\lib\site-packages\django\template\base.py", line 907, in _resolve_lookup
    (bit, current))  # missing attribute
django.template.base.VariableDoesNotExist: Failed lookup for key [name] in "<RegexURLResolver <module 'redcashier_service_apps.catalogo_api.urls' from 'D:\\\\Project\\\\redcashier\\\\redcashier_service\\\\redcashier_service_apps\\\\catalogo_api\\\\urls.py'> (None:None) ^api/catalogo/>"
[2016-12-01 15:43:21] DEBUG [django.template:929] Exception while resolving variable 'name' in template 'unknown'.
Traceback (most recent call last):
  File "D:\Project\redcashier\ve_redcashier\lib\site-packages\django\core\handlers\exception.py", line 39, in inner
    response = get_response(request)
  File "D:\Project\redcashier\ve_redcashier\lib\site-packages\django\core\handlers\base.py", line 249, in _legacy_get_response
    response = self._get_response(request)
  File "D:\Project\redcashier\ve_redcashier\lib\site-packages\django\core\handlers\base.py", line 172, in _get_response
    resolver_match = resolver.resolve(request.path_info)
  File "D:\Project\redcashier\ve_redcashier\lib\site-packages\django\urls\resolvers.py", line 300, in resolve
    raise Resolver404({'tried': tried, 'path': new_path})
django.urls.exceptions.Resolver404: {'tried': [[<RegexURLResolver <RegexURLPattern list> (admin:admin) ^admin/>], [<RegexURLResolver <module 'django.contrib.admindocs.urls' from 'D:\\Project\\redcashier\\ve_redcashier\\lib\\site-packages\\django\\contrib\\admindocs\\urls.py'> (None:None) ^admin/doc/>], [<RegexURLResolver <module 'rest_framework.urls' from 'D:\\Project\\redcashier\\ve_redcashier\\lib\\site-packages\\rest_framework\\urls.py'> (rest_framework:rest_framework) ^api-auth/>], [<RegexURLResolver <module 'oauth2_provider.urls' from 'D:\\Project\\redcashier\\ve_redcashier\\lib\\site-packages\\oauth2_provider\\urls.py'> (None:oauth2_provider) ^o/>], [<RegexURLResolver <module 'redcashier_service_apps.auths_api.urls' from 'D:\\Project\\redcashier\\redcashier_service\\redcashier_service_apps\\auths_api\\urls.py'> (None:None) ^api/auths/>], [<RegexURLResolver <module 'redcashier_service_apps.catalogo_api.urls' from 'D:\\Project\\redcashier\\redcashier_service\\redcashier_service_apps\\catalogo_api\\urls.py'> (None:None) ^api/catalogo/>], [<RegexURLResolver <module 'redcashier_service_apps.caja_api.urls' from 'D:\\Project\\redcashier\\redcashier_service\\redcashier_service_apps\\caja_api\\urls.py'> (None:None) ^api/caja/>]], 'path': 'favicon.ico'}

During handling of the above exception, another exception occurred:

Traceback (most recent call last):
  File "D:\Project\redcashier\ve_redcashier\lib\site-packages\django\template\base.py", line 885, in _resolve_lookup
    current = current[bit]
TypeError: 'RegexURLResolver' object is not subscriptable

During handling of the above exception, another exception occurred:

Traceback (most recent call last):
  File "D:\Project\redcashier\ve_redcashier\lib\site-packages\django\template\base.py", line 893, in _resolve_lookup
    current = getattr(current, bit)
AttributeError: 'RegexURLResolver' object has no attribute 'name'

During handling of the above exception, another exception occurred:

Traceback (most recent call last):
  File "D:\Project\redcashier\ve_redcashier\lib\site-packages\django\template\base.py", line 900, in _resolve_lookup
    current = current[int(bit)]
ValueError: invalid literal for int() with base 10: 'name'

During handling of the above exception, another exception occurred:

Traceback (most recent call last):
  File "D:\Project\redcashier\ve_redcashier\lib\site-packages\django\template\base.py", line 907, in _resolve_lookup
    (bit, current))  # missing attribute
django.template.base.VariableDoesNotExist: Failed lookup for key [name] in "<RegexURLResolver <module 'redcashier_service_apps.caja_api.urls' from 'D:\\\\Project\\\\redcashier\\\\redcashier_service\\\\redcashier_service_apps\\\\caja_api\\\\urls.py'> (None:None) ^api/caja/>"
[2016-12-01 15:43:21] WARNING [django.request:152] Not Found: /favicon.ico
[2016-12-01 15:43:21] WARNING [django.server:131] "GET /favicon.ico HTTP/1.1" 404 2604
[2016-12-01 15:43:24] DEBUG [django.db.backends:90] (0.004) SELECT "auths_menu"."router_json" FROM "auths_menu" ORDER BY "auths_menu"."pos" ASC; args=()
[2016-12-01 15:43:24] INFO [django.server:131] "GET /api/auths/routers/ HTTP/1.1" 200 2
[2016-12-01 15:43:30] DEBUG [django.db.backends:90] (0.002) SELECT "oauth2_provider_application"."id", "oauth2_provider_application"."client_id", "oauth2_provider_application"."user_id", "oauth2_provider_application"."redirect_uris", "oauth2_provider_application"."client_type", "oauth2_provider_application"."authorization_grant_type", "oauth2_provider_application"."client_secret", "oauth2_provider_application"."name", "oauth2_provider_application"."skip_authorization" FROM "oauth2_provider_application" WHERE "oauth2_provider_application"."client_id" = '9xrM04wZYb2KK8wk4ye9zm3K12JlMcU2k0ozcIAz'; args=('9xrM04wZYb2KK8wk4ye9zm3K12JlMcU2k0ozcIAz',)
[2016-12-01 15:43:30] DEBUG [django.db.backends:90] (0.001) SELECT "auths_user"."password", "auths_user"."last_login", "auths_user"."is_superuser", "auths_user"."username", "auths_user"."first_name", "auths_user"."last_name", "auths_user"."email", "auths_user"."is_staff", "auths_user"."is_active", "auths_user"."date_joined", "auths_user"."id", "auths_user"."last_hierarchy_id", "auths_user"."last_module_id", "auths_user"."person_id", "auths_user"."updated_at", "auths_user"."registered_by" FROM "auths_user" WHERE "auths_user"."username" = 'sal'; args=('sal',)
[2016-12-01 15:43:30] DEBUG [django.db.backends:90] (0.000) BEGIN; args=None
[2016-12-01 15:43:30] DEBUG [django.db.backends:90] (0.033) INSERT INTO "oauth2_provider_accesstoken" ("user_id", "token", "application_id", "expires", "scope") VALUES ('c6b3d7e2d92447bb837367847ca01ec7', 'stEVxSZakB8SeaEYPjnWdBXj9eWtgI', 1, '2016-12-02 07:43:30.646669', 'write read'); args=['c6b3d7e2d92447bb837367847ca01ec7', 'stEVxSZakB8SeaEYPjnWdBXj9eWtgI', 1, '2016-12-02 07:43:30.646669', 'write read']
[2016-12-01 15:43:30] DEBUG [django.db.backends:90] (0.000) BEGIN; args=None
[2016-12-01 15:43:30] DEBUG [django.db.backends:90] (0.002) INSERT INTO "oauth2_provider_refreshtoken" ("user_id", "token", "application_id", "access_token_id") VALUES ('c6b3d7e2d92447bb837367847ca01ec7', '31dXkqMB0XaysIHFwNxSMlR6V2UPOZ', 1, 5); args=['c6b3d7e2d92447bb837367847ca01ec7', '31dXkqMB0XaysIHFwNxSMlR6V2UPOZ', 1, 5]
[2016-12-01 15:43:30] INFO [django.server:131] "POST /o/token/ HTTP/1.1" 200 169
[2016-12-01 15:43:33] INFO [django.server:131] "OPTIONS /api/auths/localuserinfo/ HTTP/1.1" 200 0
[2016-12-01 15:43:33] DEBUG [django.db.backends:90] (0.006) SELECT "oauth2_provider_accesstoken"."id", "oauth2_provider_accesstoken"."user_id", "oauth2_provider_accesstoken"."token", "oauth2_provider_accesstoken"."application_id", "oauth2_provider_accesstoken"."expires", "oauth2_provider_accesstoken"."scope", "auths_user"."password", "auths_user"."last_login", "auths_user"."is_superuser", "auths_user"."username", "auths_user"."first_name", "auths_user"."last_name", "auths_user"."email", "auths_user"."is_staff", "auths_user"."is_active", "auths_user"."date_joined", "auths_user"."id", "auths_user"."last_hierarchy_id", "auths_user"."last_module_id", "auths_user"."person_id", "auths_user"."updated_at", "auths_user"."registered_by", "oauth2_provider_application"."id", "oauth2_provider_application"."client_id", "oauth2_provider_application"."user_id", "oauth2_provider_application"."redirect_uris", "oauth2_provider_application"."client_type", "oauth2_provider_application"."authorization_grant_type", "oauth2_provider_application"."client_secret", "oauth2_provider_application"."name", "oauth2_provider_application"."skip_authorization" FROM "oauth2_provider_accesstoken" LEFT OUTER JOIN "auths_user" ON ("oauth2_provider_accesstoken"."user_id" = "auths_user"."id") INNER JOIN "oauth2_provider_application" ON ("oauth2_provider_accesstoken"."application_id" = "oauth2_provider_application"."id") WHERE "oauth2_provider_accesstoken"."token" = 'stEVxSZakB8SeaEYPjnWdBXj9eWtgI'; args=('stEVxSZakB8SeaEYPjnWdBXj9eWtgI',)
[2016-12-01 15:43:33] DEBUG [django.db.backends:90] (0.001) SELECT "oauth2_provider_accesstoken"."id", "oauth2_provider_accesstoken"."user_id", "oauth2_provider_accesstoken"."token", "oauth2_provider_accesstoken"."application_id", "oauth2_provider_accesstoken"."expires", "oauth2_provider_accesstoken"."scope", "auths_user"."password", "auths_user"."last_login", "auths_user"."is_superuser", "auths_user"."username", "auths_user"."first_name", "auths_user"."last_name", "auths_user"."email", "auths_user"."is_staff", "auths_user"."is_active", "auths_user"."date_joined", "auths_user"."id", "auths_user"."last_hierarchy_id", "auths_user"."last_module_id", "auths_user"."person_id", "auths_user"."updated_at", "auths_user"."registered_by", "oauth2_provider_application"."id", "oauth2_provider_application"."client_id", "oauth2_provider_application"."user_id", "oauth2_provider_application"."redirect_uris", "oauth2_provider_application"."client_type", "oauth2_provider_application"."authorization_grant_type", "oauth2_provider_application"."client_secret", "oauth2_provider_application"."name", "oauth2_provider_application"."skip_authorization" FROM "oauth2_provider_accesstoken" LEFT OUTER JOIN "auths_user" ON ("oauth2_provider_accesstoken"."user_id" = "auths_user"."id") INNER JOIN "oauth2_provider_application" ON ("oauth2_provider_accesstoken"."application_id" = "oauth2_provider_application"."id") WHERE "oauth2_provider_accesstoken"."token" = 'stEVxSZakB8SeaEYPjnWdBXj9eWtgI'; args=('stEVxSZakB8SeaEYPjnWdBXj9eWtgI',)
[2016-12-01 15:43:33] INFO [django.server:131] "OPTIONS /api/auths/usermenu/ HTTP/1.1" 200 0
[2016-12-01 15:43:33] DEBUG [django.db.backends:90] (0.008) SELECT "auth_group"."id", "auth_group"."name" FROM "auth_group" INNER JOIN "auths_user_groups" ON ("auth_group"."id" = "auths_user_groups"."group_id") WHERE "auths_user_groups"."user_id" = 'c6b3d7e2d92447bb837367847ca01ec7'; args=('c6b3d7e2d92447bb837367847ca01ec7',)
[2016-12-01 15:43:33] DEBUG [django.db.backends:90] (0.001) SELECT "auth_permission"."id", "auth_permission"."name", "auth_permission"."content_type_id", "auth_permission"."codename" FROM "auth_permission" INNER JOIN "auths_user_user_permissions" ON ("auth_permission"."id" = "auths_user_user_permissions"."permission_id") INNER JOIN "django_content_type" ON ("auth_permission"."content_type_id" = "django_content_type"."id") WHERE "auths_user_user_permissions"."user_id" = 'c6b3d7e2d92447bb837367847ca01ec7' ORDER BY "django_content_type"."app_label" ASC, "django_content_type"."model" ASC, "auth_permission"."codename" ASC; args=('c6b3d7e2d92447bb837367847ca01ec7',)
[2016-12-01 15:43:33] INFO [django.server:131] "GET /api/auths/localuserinfo/ HTTP/1.1" 200 378
[2016-12-01 15:43:33] DEBUG [django.db.backends:90] (0.005) SELECT "oauth2_provider_accesstoken"."id", "oauth2_provider_accesstoken"."user_id", "oauth2_provider_accesstoken"."token", "oauth2_provider_accesstoken"."application_id", "oauth2_provider_accesstoken"."expires", "oauth2_provider_accesstoken"."scope", "auths_user"."password", "auths_user"."last_login", "auths_user"."is_superuser", "auths_user"."username", "auths_user"."first_name", "auths_user"."last_name", "auths_user"."email", "auths_user"."is_staff", "auths_user"."is_active", "auths_user"."date_joined", "auths_user"."id", "auths_user"."last_hierarchy_id", "auths_user"."last_module_id", "auths_user"."person_id", "auths_user"."updated_at", "auths_user"."registered_by", "oauth2_provider_application"."id", "oauth2_provider_application"."client_id", "oauth2_provider_application"."user_id", "oauth2_provider_application"."redirect_uris", "oauth2_provider_application"."client_type", "oauth2_provider_application"."authorization_grant_type", "oauth2_provider_application"."client_secret", "oauth2_provider_application"."name", "oauth2_provider_application"."skip_authorization" FROM "oauth2_provider_accesstoken" LEFT OUTER JOIN "auths_user" ON ("oauth2_provider_accesstoken"."user_id" = "auths_user"."id") INNER JOIN "oauth2_provider_application" ON ("oauth2_provider_accesstoken"."application_id" = "oauth2_provider_application"."id") WHERE "oauth2_provider_accesstoken"."token" = 'stEVxSZakB8SeaEYPjnWdBXj9eWtgI'; args=('stEVxSZakB8SeaEYPjnWdBXj9eWtgI',)
[2016-12-01 15:43:33] DEBUG [django.db.backends:90] (0.001) SELECT "oauth2_provider_accesstoken"."id", "oauth2_provider_accesstoken"."user_id", "oauth2_provider_accesstoken"."token", "oauth2_provider_accesstoken"."application_id", "oauth2_provider_accesstoken"."expires", "oauth2_provider_accesstoken"."scope", "auths_user"."password", "auths_user"."last_login", "auths_user"."is_superuser", "auths_user"."username", "auths_user"."first_name", "auths_user"."last_name", "auths_user"."email", "auths_user"."is_staff", "auths_user"."is_active", "auths_user"."date_joined", "auths_user"."id", "auths_user"."last_hierarchy_id", "auths_user"."last_module_id", "auths_user"."person_id", "auths_user"."updated_at", "auths_user"."registered_by", "oauth2_provider_application"."id", "oauth2_provider_application"."client_id", "oauth2_provider_application"."user_id", "oauth2_provider_application"."redirect_uris", "oauth2_provider_application"."client_type", "oauth2_provider_application"."authorization_grant_type", "oauth2_provider_application"."client_secret", "oauth2_provider_application"."name", "oauth2_provider_application"."skip_authorization" FROM "oauth2_provider_accesstoken" LEFT OUTER JOIN "auths_user" ON ("oauth2_provider_accesstoken"."user_id" = "auths_user"."id") INNER JOIN "oauth2_provider_application" ON ("oauth2_provider_accesstoken"."application_id" = "oauth2_provider_application"."id") WHERE "oauth2_provider_accesstoken"."token" = 'stEVxSZakB8SeaEYPjnWdBXj9eWtgI'; args=('stEVxSZakB8SeaEYPjnWdBXj9eWtgI',)
[2016-12-01 15:43:33] DEBUG [django.db.backends:90] (0.001) SELECT "auths_menu"."id" FROM "auths_menu" WHERE ("auths_menu"."id" IS NOT NULL AND "auths_menu"."is_active" = 1 AND "auths_menu"."module" = 'BACKEND') ORDER BY "auths_menu"."pos" ASC; args=(True, 'BACKEND')
[2016-12-01 15:43:33] DEBUG [django.db.backends:90] (0.001) SELECT (1) AS "a" FROM "django_session" WHERE "django_session"."session_key" = '5wnxi7nv0etl8oioh891h3z7r7hs0b4l' LIMIT 1; args=('5wnxi7nv0etl8oioh891h3z7r7hs0b4l',)
[2016-12-01 15:43:33] DEBUG [django.db.backends:90] (0.000) BEGIN; args=None
[2016-12-01 15:43:33] DEBUG [django.db.backends:90] (0.014) INSERT INTO "django_session" ("session_key", "session_data", "expire_date") SELECT '5wnxi7nv0etl8oioh891h3z7r7hs0b4l', 'ODY1NjFiZTY0MzBmM2M0MGUwMDNhZGY4YmJlNjRmMzUzYmRiN2M3Nzp7Il9zZXNzaW9uX2V4cGlyeSI6MzB9', '2016-12-01 21:44:03.795100'; args=('5wnxi7nv0etl8oioh891h3z7r7hs0b4l', 'ODY1NjFiZTY0MzBmM2M0MGUwMDNhZGY4YmJlNjRmMzUzYmRiN2M3Nzp7Il9zZXNzaW9uX2V4cGlyeSI6MzB9', '2016-12-01 21:44:03.795100')
[2016-12-01 15:43:33] INFO [django.server:131] "GET /api/auths/usermenu/ HTTP/1.1" 200 11
[2016-12-01 15:43:43] INFO [django.server:131] "OPTIONS /api/caja/modcontables/ HTTP/1.1" 200 0
[2016-12-01 15:43:43] DEBUG [django.db.backends:90] (0.002) SELECT "oauth2_provider_accesstoken"."id", "oauth2_provider_accesstoken"."user_id", "oauth2_provider_accesstoken"."token", "oauth2_provider_accesstoken"."application_id", "oauth2_provider_accesstoken"."expires", "oauth2_provider_accesstoken"."scope", "auths_user"."password", "auths_user"."last_login", "auths_user"."is_superuser", "auths_user"."username", "auths_user"."first_name", "auths_user"."last_name", "auths_user"."email", "auths_user"."is_staff", "auths_user"."is_active", "auths_user"."date_joined", "auths_user"."id", "auths_user"."last_hierarchy_id", "auths_user"."last_module_id", "auths_user"."person_id", "auths_user"."updated_at", "auths_user"."registered_by", "oauth2_provider_application"."id", "oauth2_provider_application"."client_id", "oauth2_provider_application"."user_id", "oauth2_provider_application"."redirect_uris", "oauth2_provider_application"."client_type", "oauth2_provider_application"."authorization_grant_type", "oauth2_provider_application"."client_secret", "oauth2_provider_application"."name", "oauth2_provider_application"."skip_authorization" FROM "oauth2_provider_accesstoken" LEFT OUTER JOIN "auths_user" ON ("oauth2_provider_accesstoken"."user_id" = "auths_user"."id") INNER JOIN "oauth2_provider_application" ON ("oauth2_provider_accesstoken"."application_id" = "oauth2_provider_application"."id") WHERE "oauth2_provider_accesstoken"."token" = 'stEVxSZakB8SeaEYPjnWdBXj9eWtgI'; args=('stEVxSZakB8SeaEYPjnWdBXj9eWtgI',)
[2016-12-01 15:43:43] DEBUG [django.db.backends:90] (0.001) SELECT "oauth2_provider_accesstoken"."id", "oauth2_provider_accesstoken"."user_id", "oauth2_provider_accesstoken"."token", "oauth2_provider_accesstoken"."application_id", "oauth2_provider_accesstoken"."expires", "oauth2_provider_accesstoken"."scope", "auths_user"."password", "auths_user"."last_login", "auths_user"."is_superuser", "auths_user"."username", "auths_user"."first_name", "auths_user"."last_name", "auths_user"."email", "auths_user"."is_staff", "auths_user"."is_active", "auths_user"."date_joined", "auths_user"."id", "auths_user"."last_hierarchy_id", "auths_user"."last_module_id", "auths_user"."person_id", "auths_user"."updated_at", "auths_user"."registered_by", "oauth2_provider_application"."id", "oauth2_provider_application"."client_id", "oauth2_provider_application"."user_id", "oauth2_provider_application"."redirect_uris", "oauth2_provider_application"."client_type", "oauth2_provider_application"."authorization_grant_type", "oauth2_provider_application"."client_secret", "oauth2_provider_application"."name", "oauth2_provider_application"."skip_authorization" FROM "oauth2_provider_accesstoken" LEFT OUTER JOIN "auths_user" ON ("oauth2_provider_accesstoken"."user_id" = "auths_user"."id") INNER JOIN "oauth2_provider_application" ON ("oauth2_provider_accesstoken"."application_id" = "oauth2_provider_application"."id") WHERE "oauth2_provider_accesstoken"."token" = 'stEVxSZakB8SeaEYPjnWdBXj9eWtgI'; args=('stEVxSZakB8SeaEYPjnWdBXj9eWtgI',)
[2016-12-01 15:43:43] DEBUG [django.db.backends:90] (0.000) SELECT "caja_modcontable"."id", "caja_modcontable"."cajaingre_id", "caja_modcontable"."nivell_id", "caja_modcontable"."periodocon_id" FROM "caja_modcontable"; args=()
[2016-12-01 15:43:43] ERROR [django.request:124] Internal Server Error: /api/caja/modcontables/
Traceback (most recent call last):
  File "D:\Project\redcashier\ve_redcashier\lib\site-packages\django\db\backends\utils.py", line 64, in execute
    return self.cursor.execute(sql, params)
  File "D:\Project\redcashier\ve_redcashier\lib\site-packages\django\db\backends\sqlite3\base.py", line 337, in execute
    return Database.Cursor.execute(self, query, params)
sqlite3.OperationalError: no such column: caja_modcontable.cajaingre_id

The above exception was the direct cause of the following exception:

Traceback (most recent call last):
  File "D:\Project\redcashier\ve_redcashier\lib\site-packages\django\core\handlers\exception.py", line 39, in inner
    response = get_response(request)
  File "D:\Project\redcashier\ve_redcashier\lib\site-packages\django\core\handlers\base.py", line 249, in _legacy_get_response
    response = self._get_response(request)
  File "D:\Project\redcashier\ve_redcashier\lib\site-packages\django\core\handlers\base.py", line 187, in _get_response
    response = self.process_exception_by_middleware(e, request)
  File "D:\Project\redcashier\ve_redcashier\lib\site-packages\django\core\handlers\base.py", line 185, in _get_response
    response = wrapped_callback(request, *callback_args, **callback_kwargs)
  File "D:\Project\redcashier\ve_redcashier\lib\site-packages\django\views\decorators\csrf.py", line 58, in wrapped_view
    return view_func(*args, **kwargs)
  File "D:\Project\redcashier\ve_redcashier\lib\site-packages\rest_framework\viewsets.py", line 83, in view
    return self.dispatch(request, *args, **kwargs)
  File "D:\Project\redcashier\ve_redcashier\lib\site-packages\rest_framework\views.py", line 477, in dispatch
    response = self.handle_exception(exc)
  File "D:\Project\redcashier\ve_redcashier\lib\site-packages\rest_framework\views.py", line 437, in handle_exception
    self.raise_uncaught_exception(exc)
  File "D:\Project\redcashier\ve_redcashier\lib\site-packages\rest_framework\views.py", line 474, in dispatch
    response = handler(request, *args, **kwargs)
  File "D:\Project\redcashier\ve_redcashier\lib\site-packages\rest_framework\mixins.py", line 48, in list
    return Response(serializer.data)
  File "D:\Project\redcashier\ve_redcashier\lib\site-packages\rest_framework\serializers.py", line 725, in data
    ret = super(ListSerializer, self).data
  File "D:\Project\redcashier\ve_redcashier\lib\site-packages\rest_framework\serializers.py", line 262, in data
    self._data = self.to_representation(self.instance)
  File "D:\Project\redcashier\ve_redcashier\lib\site-packages\rest_framework\serializers.py", line 643, in to_representation
    self.child.to_representation(item) for item in iterable
  File "D:\Project\redcashier\ve_redcashier\lib\site-packages\django\db\models\query.py", line 256, in __iter__
    self._fetch_all()
  File "D:\Project\redcashier\ve_redcashier\lib\site-packages\django\db\models\query.py", line 1087, in _fetch_all
    self._result_cache = list(self.iterator())
  File "D:\Project\redcashier\ve_redcashier\lib\site-packages\django\db\models\query.py", line 54, in __iter__
    results = compiler.execute_sql()
  File "D:\Project\redcashier\ve_redcashier\lib\site-packages\django\db\models\sql\compiler.py", line 835, in execute_sql
    cursor.execute(sql, params)
  File "D:\Project\redcashier\ve_redcashier\lib\site-packages\django\db\backends\utils.py", line 79, in execute
    return super(CursorDebugWrapper, self).execute(sql, params)
  File "D:\Project\redcashier\ve_redcashier\lib\site-packages\django\db\backends\utils.py", line 64, in execute
    return self.cursor.execute(sql, params)
  File "D:\Project\redcashier\ve_redcashier\lib\site-packages\django\db\utils.py", line 94, in __exit__
    six.reraise(dj_exc_type, dj_exc_value, traceback)
  File "D:\Project\redcashier\ve_redcashier\lib\site-packages\django\utils\six.py", line 685, in reraise
    raise value.with_traceback(tb)
  File "D:\Project\redcashier\ve_redcashier\lib\site-packages\django\db\backends\utils.py", line 64, in execute
    return self.cursor.execute(sql, params)
  File "D:\Project\redcashier\ve_redcashier\lib\site-packages\django\db\backends\sqlite3\base.py", line 337, in execute
    return Database.Cursor.execute(self, query, params)
django.db.utils.OperationalError: no such column: caja_modcontable.cajaingre_id
[2016-12-01 15:43:43] DEBUG [django.db.backends:90] (0.001) SELECT "caja_modcontable"."id", "caja_modcontable"."cajaingre_id", "caja_modcontable"."nivell_id", "caja_modcontable"."periodocon_id" FROM "caja_modcontable" LIMIT 21; args=()
[2016-12-01 15:43:43] DEBUG [django.db.backends:90] (0.000) SELECT "caja_modcontable"."id", "caja_modcontable"."cajaingre_id", "caja_modcontable"."nivell_id", "caja_modcontable"."periodocon_id" FROM "caja_modcontable" LIMIT 21; args=()
[2016-12-01 15:43:43] DEBUG [django.db.backends:90] (0.000) SELECT "caja_modcontable"."id", "caja_modcontable"."cajaingre_id", "caja_modcontable"."nivell_id", "caja_modcontable"."periodocon_id" FROM "caja_modcontable" LIMIT 21; args=()
[2016-12-01 15:43:43] DEBUG [django.db.backends:90] (0.000) SELECT "caja_modcontable"."id", "caja_modcontable"."cajaingre_id", "caja_modcontable"."nivell_id", "caja_modcontable"."periodocon_id" FROM "caja_modcontable" LIMIT 21; args=()
[2016-12-01 15:43:43] DEBUG [django.db.backends:90] (0.000) SELECT "caja_modcontable"."id", "caja_modcontable"."cajaingre_id", "caja_modcontable"."nivell_id", "caja_modcontable"."periodocon_id" FROM "caja_modcontable" LIMIT 21; args=()
[2016-12-01 15:43:43] DEBUG [django.db.backends:90] (0.000) SELECT "caja_modcontable"."id", "caja_modcontable"."cajaingre_id", "caja_modcontable"."nivell_id", "caja_modcontable"."periodocon_id" FROM "caja_modcontable" LIMIT 21; args=()
[2016-12-01 15:43:43] DEBUG [django.db.backends:90] (0.000) SELECT "caja_modcontable"."id", "caja_modcontable"."cajaingre_id", "caja_modcontable"."nivell_id", "caja_modcontable"."periodocon_id" FROM "caja_modcontable" LIMIT 21; args=()
[2016-12-01 15:43:43] DEBUG [django.db.backends:90] (0.000) SELECT "caja_modcontable"."id", "caja_modcontable"."cajaingre_id", "caja_modcontable"."nivell_id", "caja_modcontable"."periodocon_id" FROM "caja_modcontable" LIMIT 21; args=()
[2016-12-01 15:43:43] DEBUG [django.db.backends:90] (0.000) SELECT "caja_modcontable"."id", "caja_modcontable"."cajaingre_id", "caja_modcontable"."nivell_id", "caja_modcontable"."periodocon_id" FROM "caja_modcontable" LIMIT 21; args=()
[2016-12-01 15:43:43] DEBUG [django.db.backends:90] (0.000) SELECT "caja_modcontable"."id", "caja_modcontable"."cajaingre_id", "caja_modcontable"."nivell_id", "caja_modcontable"."periodocon_id" FROM "caja_modcontable" LIMIT 21; args=()
[2016-12-01 15:43:43] ERROR [django.server:131] "GET /api/caja/modcontables/ HTTP/1.1" 500 21300
[2016-12-01 15:44:45] DEBUG [django.db.backends:90] (0.003) SELECT "oauth2_provider_accesstoken"."id", "oauth2_provider_accesstoken"."user_id", "oauth2_provider_accesstoken"."token", "oauth2_provider_accesstoken"."application_id", "oauth2_provider_accesstoken"."expires", "oauth2_provider_accesstoken"."scope", "auths_user"."password", "auths_user"."last_login", "auths_user"."is_superuser", "auths_user"."username", "auths_user"."first_name", "auths_user"."last_name", "auths_user"."email", "auths_user"."is_staff", "auths_user"."is_active", "auths_user"."date_joined", "auths_user"."id", "auths_user"."last_hierarchy_id", "auths_user"."last_module_id", "auths_user"."person_id", "auths_user"."updated_at", "auths_user"."registered_by", "oauth2_provider_application"."id", "oauth2_provider_application"."client_id", "oauth2_provider_application"."user_id", "oauth2_provider_application"."redirect_uris", "oauth2_provider_application"."client_type", "oauth2_provider_application"."authorization_grant_type", "oauth2_provider_application"."client_secret", "oauth2_provider_application"."name", "oauth2_provider_application"."skip_authorization" FROM "oauth2_provider_accesstoken" LEFT OUTER JOIN "auths_user" ON ("oauth2_provider_accesstoken"."user_id" = "auths_user"."id") INNER JOIN "oauth2_provider_application" ON ("oauth2_provider_accesstoken"."application_id" = "oauth2_provider_application"."id") WHERE "oauth2_provider_accesstoken"."token" = 'stEVxSZakB8SeaEYPjnWdBXj9eWtgI'; args=('stEVxSZakB8SeaEYPjnWdBXj9eWtgI',)
[2016-12-01 15:44:45] DEBUG [django.db.backends:90] (0.001) SELECT "oauth2_provider_accesstoken"."id", "oauth2_provider_accesstoken"."user_id", "oauth2_provider_accesstoken"."token", "oauth2_provider_accesstoken"."application_id", "oauth2_provider_accesstoken"."expires", "oauth2_provider_accesstoken"."scope", "auths_user"."password", "auths_user"."last_login", "auths_user"."is_superuser", "auths_user"."username", "auths_user"."first_name", "auths_user"."last_name", "auths_user"."email", "auths_user"."is_staff", "auths_user"."is_active", "auths_user"."date_joined", "auths_user"."id", "auths_user"."last_hierarchy_id", "auths_user"."last_module_id", "auths_user"."person_id", "auths_user"."updated_at", "auths_user"."registered_by", "oauth2_provider_application"."id", "oauth2_provider_application"."client_id", "oauth2_provider_application"."user_id", "oauth2_provider_application"."redirect_uris", "oauth2_provider_application"."client_type", "oauth2_provider_application"."authorization_grant_type", "oauth2_provider_application"."client_secret", "oauth2_provider_application"."name", "oauth2_provider_application"."skip_authorization" FROM "oauth2_provider_accesstoken" LEFT OUTER JOIN "auths_user" ON ("oauth2_provider_accesstoken"."user_id" = "auths_user"."id") INNER JOIN "oauth2_provider_application" ON ("oauth2_provider_accesstoken"."application_id" = "oauth2_provider_application"."id") WHERE "oauth2_provider_accesstoken"."token" = 'stEVxSZakB8SeaEYPjnWdBXj9eWtgI'; args=('stEVxSZakB8SeaEYPjnWdBXj9eWtgI',)
[2016-12-01 15:44:45] DEBUG [django.db.backends:90] (0.000) BEGIN; args=None
[2016-12-01 15:44:45] DEBUG [django.db.backends:90] (0.001) INSERT INTO "caja_modcontable" ("id", "cajaingre_id", "nivell_id", "periodocon_id") SELECT 'a40d503cf0e14884953bca458d65da82', NULL, NULL, NULL; args=('a40d503cf0e14884953bca458d65da82', None, None, None)
[2016-12-01 15:44:45] ERROR [django.request:124] Internal Server Error: /api/caja/modcontables/
Traceback (most recent call last):
  File "D:\Project\redcashier\ve_redcashier\lib\site-packages\django\db\backends\utils.py", line 64, in execute
    return self.cursor.execute(sql, params)
  File "D:\Project\redcashier\ve_redcashier\lib\site-packages\django\db\backends\sqlite3\base.py", line 337, in execute
    return Database.Cursor.execute(self, query, params)
sqlite3.OperationalError: table caja_modcontable has no column named cajaingre_id

The above exception was the direct cause of the following exception:

Traceback (most recent call last):
  File "D:\Project\redcashier\ve_redcashier\lib\site-packages\django\core\handlers\exception.py", line 39, in inner
    response = get_response(request)
  File "D:\Project\redcashier\ve_redcashier\lib\site-packages\django\core\handlers\base.py", line 249, in _legacy_get_response
    response = self._get_response(request)
  File "D:\Project\redcashier\ve_redcashier\lib\site-packages\django\core\handlers\base.py", line 187, in _get_response
    response = self.process_exception_by_middleware(e, request)
  File "D:\Project\redcashier\ve_redcashier\lib\site-packages\django\core\handlers\base.py", line 185, in _get_response
    response = wrapped_callback(request, *callback_args, **callback_kwargs)
  File "D:\Project\redcashier\ve_redcashier\lib\site-packages\django\views\decorators\csrf.py", line 58, in wrapped_view
    return view_func(*args, **kwargs)
  File "D:\Project\redcashier\ve_redcashier\lib\site-packages\rest_framework\viewsets.py", line 83, in view
    return self.dispatch(request, *args, **kwargs)
  File "D:\Project\redcashier\ve_redcashier\lib\site-packages\rest_framework\views.py", line 477, in dispatch
    response = self.handle_exception(exc)
  File "D:\Project\redcashier\ve_redcashier\lib\site-packages\rest_framework\views.py", line 437, in handle_exception
    self.raise_uncaught_exception(exc)
  File "D:\Project\redcashier\ve_redcashier\lib\site-packages\rest_framework\views.py", line 474, in dispatch
    response = handler(request, *args, **kwargs)
  File "D:\Project\redcashier\ve_redcashier\lib\site-packages\rest_framework\mixins.py", line 21, in create
    self.perform_create(serializer)
  File "D:\Project\redcashier\ve_redcashier\lib\site-packages\rest_framework\mixins.py", line 26, in perform_create
    serializer.save()
  File "D:\Project\redcashier\ve_redcashier\lib\site-packages\rest_framework\serializers.py", line 214, in save
    self.instance = self.create(validated_data)
  File "D:\Project\redcashier\ve_redcashier\lib\site-packages\rest_framework\serializers.py", line 902, in create
    instance = ModelClass.objects.create(**validated_data)
  File "D:\Project\redcashier\ve_redcashier\lib\site-packages\django\db\models\manager.py", line 85, in manager_method
    return getattr(self.get_queryset(), name)(*args, **kwargs)
  File "D:\Project\redcashier\ve_redcashier\lib\site-packages\django\db\models\query.py", line 399, in create
    obj.save(force_insert=True, using=self.db)
  File "D:\Project\redcashier\ve_redcashier\lib\site-packages\django\db\models\base.py", line 796, in save
    force_update=force_update, update_fields=update_fields)
  File "D:\Project\redcashier\ve_redcashier\lib\site-packages\django\db\models\base.py", line 824, in save_base
    updated = self._save_table(raw, cls, force_insert, force_update, using, update_fields)
  File "D:\Project\redcashier\ve_redcashier\lib\site-packages\django\db\models\base.py", line 908, in _save_table
    result = self._do_insert(cls._base_manager, using, fields, update_pk, raw)
  File "D:\Project\redcashier\ve_redcashier\lib\site-packages\django\db\models\base.py", line 947, in _do_insert
    using=using, raw=raw)
  File "D:\Project\redcashier\ve_redcashier\lib\site-packages\django\db\models\manager.py", line 85, in manager_method
    return getattr(self.get_queryset(), name)(*args, **kwargs)
  File "D:\Project\redcashier\ve_redcashier\lib\site-packages\django\db\models\query.py", line 1045, in _insert
    return query.get_compiler(using=using).execute_sql(return_id)
  File "D:\Project\redcashier\ve_redcashier\lib\site-packages\django\db\models\sql\compiler.py", line 1054, in execute_sql
    cursor.execute(sql, params)
  File "D:\Project\redcashier\ve_redcashier\lib\site-packages\django\db\backends\utils.py", line 79, in execute
    return super(CursorDebugWrapper, self).execute(sql, params)
  File "D:\Project\redcashier\ve_redcashier\lib\site-packages\django\db\backends\utils.py", line 64, in execute
    return self.cursor.execute(sql, params)
  File "D:\Project\redcashier\ve_redcashier\lib\site-packages\django\db\utils.py", line 94, in __exit__
    six.reraise(dj_exc_type, dj_exc_value, traceback)
  File "D:\Project\redcashier\ve_redcashier\lib\site-packages\django\utils\six.py", line 685, in reraise
    raise value.with_traceback(tb)
  File "D:\Project\redcashier\ve_redcashier\lib\site-packages\django\db\backends\utils.py", line 64, in execute
    return self.cursor.execute(sql, params)
  File "D:\Project\redcashier\ve_redcashier\lib\site-packages\django\db\backends\sqlite3\base.py", line 337, in execute
    return Database.Cursor.execute(self, query, params)
django.db.utils.OperationalError: table caja_modcontable has no column named cajaingre_id
[2016-12-01 15:44:45] DEBUG [django.db.backends:90] (0.000) SELECT "caja_modcontable"."id", "caja_modcontable"."cajaingre_id", "caja_modcontable"."nivell_id", "caja_modcontable"."periodocon_id" FROM "caja_modcontable" LIMIT 21; args=()
[2016-12-01 15:44:45] DEBUG [django.db.backends:90] (0.000) SELECT "caja_modcontable"."id", "caja_modcontable"."cajaingre_id", "caja_modcontable"."nivell_id", "caja_modcontable"."periodocon_id" FROM "caja_modcontable" LIMIT 21; args=()
[2016-12-01 15:44:45] ERROR [django.server:131] "POST /api/caja/modcontables/ HTTP/1.1" 500 22330
[2016-12-01 15:44:48] DEBUG [django.db.backends:90] (0.003) SELECT "oauth2_provider_accesstoken"."id", "oauth2_provider_accesstoken"."user_id", "oauth2_provider_accesstoken"."token", "oauth2_provider_accesstoken"."application_id", "oauth2_provider_accesstoken"."expires", "oauth2_provider_accesstoken"."scope", "auths_user"."password", "auths_user"."last_login", "auths_user"."is_superuser", "auths_user"."username", "auths_user"."first_name", "auths_user"."last_name", "auths_user"."email", "auths_user"."is_staff", "auths_user"."is_active", "auths_user"."date_joined", "auths_user"."id", "auths_user"."last_hierarchy_id", "auths_user"."last_module_id", "auths_user"."person_id", "auths_user"."updated_at", "auths_user"."registered_by", "oauth2_provider_application"."id", "oauth2_provider_application"."client_id", "oauth2_provider_application"."user_id", "oauth2_provider_application"."redirect_uris", "oauth2_provider_application"."client_type", "oauth2_provider_application"."authorization_grant_type", "oauth2_provider_application"."client_secret", "oauth2_provider_application"."name", "oauth2_provider_application"."skip_authorization" FROM "oauth2_provider_accesstoken" LEFT OUTER JOIN "auths_user" ON ("oauth2_provider_accesstoken"."user_id" = "auths_user"."id") INNER JOIN "oauth2_provider_application" ON ("oauth2_provider_accesstoken"."application_id" = "oauth2_provider_application"."id") WHERE "oauth2_provider_accesstoken"."token" = 'stEVxSZakB8SeaEYPjnWdBXj9eWtgI'; args=('stEVxSZakB8SeaEYPjnWdBXj9eWtgI',)
[2016-12-01 15:44:48] DEBUG [django.db.backends:90] (0.000) SELECT "oauth2_provider_accesstoken"."id", "oauth2_provider_accesstoken"."user_id", "oauth2_provider_accesstoken"."token", "oauth2_provider_accesstoken"."application_id", "oauth2_provider_accesstoken"."expires", "oauth2_provider_accesstoken"."scope", "auths_user"."password", "auths_user"."last_login", "auths_user"."is_superuser", "auths_user"."username", "auths_user"."first_name", "auths_user"."last_name", "auths_user"."email", "auths_user"."is_staff", "auths_user"."is_active", "auths_user"."date_joined", "auths_user"."id", "auths_user"."last_hierarchy_id", "auths_user"."last_module_id", "auths_user"."person_id", "auths_user"."updated_at", "auths_user"."registered_by", "oauth2_provider_application"."id", "oauth2_provider_application"."client_id", "oauth2_provider_application"."user_id", "oauth2_provider_application"."redirect_uris", "oauth2_provider_application"."client_type", "oauth2_provider_application"."authorization_grant_type", "oauth2_provider_application"."client_secret", "oauth2_provider_application"."name", "oauth2_provider_application"."skip_authorization" FROM "oauth2_provider_accesstoken" LEFT OUTER JOIN "auths_user" ON ("oauth2_provider_accesstoken"."user_id" = "auths_user"."id") INNER JOIN "oauth2_provider_application" ON ("oauth2_provider_accesstoken"."application_id" = "oauth2_provider_application"."id") WHERE "oauth2_provider_accesstoken"."token" = 'stEVxSZakB8SeaEYPjnWdBXj9eWtgI'; args=('stEVxSZakB8SeaEYPjnWdBXj9eWtgI',)
[2016-12-01 15:44:48] DEBUG [django.db.backends:90] (0.000) SELECT "caja_modcontable"."id", "caja_modcontable"."cajaingre_id", "caja_modcontable"."nivell_id", "caja_modcontable"."periodocon_id" FROM "caja_modcontable"; args=()
[2016-12-01 15:44:48] ERROR [django.request:124] Internal Server Error: /api/caja/modcontables/
Traceback (most recent call last):
  File "D:\Project\redcashier\ve_redcashier\lib\site-packages\django\db\backends\utils.py", line 64, in execute
    return self.cursor.execute(sql, params)
  File "D:\Project\redcashier\ve_redcashier\lib\site-packages\django\db\backends\sqlite3\base.py", line 337, in execute
    return Database.Cursor.execute(self, query, params)
sqlite3.OperationalError: no such column: caja_modcontable.cajaingre_id

The above exception was the direct cause of the following exception:

Traceback (most recent call last):
  File "D:\Project\redcashier\ve_redcashier\lib\site-packages\django\core\handlers\exception.py", line 39, in inner
    response = get_response(request)
  File "D:\Project\redcashier\ve_redcashier\lib\site-packages\django\core\handlers\base.py", line 249, in _legacy_get_response
    response = self._get_response(request)
  File "D:\Project\redcashier\ve_redcashier\lib\site-packages\django\core\handlers\base.py", line 187, in _get_response
    response = self.process_exception_by_middleware(e, request)
  File "D:\Project\redcashier\ve_redcashier\lib\site-packages\django\core\handlers\base.py", line 185, in _get_response
    response = wrapped_callback(request, *callback_args, **callback_kwargs)
  File "D:\Project\redcashier\ve_redcashier\lib\site-packages\django\views\decorators\csrf.py", line 58, in wrapped_view
    return view_func(*args, **kwargs)
  File "D:\Project\redcashier\ve_redcashier\lib\site-packages\rest_framework\viewsets.py", line 83, in view
    return self.dispatch(request, *args, **kwargs)
  File "D:\Project\redcashier\ve_redcashier\lib\site-packages\rest_framework\views.py", line 477, in dispatch
    response = self.handle_exception(exc)
  File "D:\Project\redcashier\ve_redcashier\lib\site-packages\rest_framework\views.py", line 437, in handle_exception
    self.raise_uncaught_exception(exc)
  File "D:\Project\redcashier\ve_redcashier\lib\site-packages\rest_framework\views.py", line 474, in dispatch
    response = handler(request, *args, **kwargs)
  File "D:\Project\redcashier\ve_redcashier\lib\site-packages\rest_framework\mixins.py", line 48, in list
    return Response(serializer.data)
  File "D:\Project\redcashier\ve_redcashier\lib\site-packages\rest_framework\serializers.py", line 725, in data
    ret = super(ListSerializer, self).data
  File "D:\Project\redcashier\ve_redcashier\lib\site-packages\rest_framework\serializers.py", line 262, in data
    self._data = self.to_representation(self.instance)
  File "D:\Project\redcashier\ve_redcashier\lib\site-packages\rest_framework\serializers.py", line 643, in to_representation
    self.child.to_representation(item) for item in iterable
  File "D:\Project\redcashier\ve_redcashier\lib\site-packages\django\db\models\query.py", line 256, in __iter__
    self._fetch_all()
  File "D:\Project\redcashier\ve_redcashier\lib\site-packages\django\db\models\query.py", line 1087, in _fetch_all
    self._result_cache = list(self.iterator())
  File "D:\Project\redcashier\ve_redcashier\lib\site-packages\django\db\models\query.py", line 54, in __iter__
    results = compiler.execute_sql()
  File "D:\Project\redcashier\ve_redcashier\lib\site-packages\django\db\models\sql\compiler.py", line 835, in execute_sql
    cursor.execute(sql, params)
  File "D:\Project\redcashier\ve_redcashier\lib\site-packages\django\db\backends\utils.py", line 79, in execute
    return super(CursorDebugWrapper, self).execute(sql, params)
  File "D:\Project\redcashier\ve_redcashier\lib\site-packages\django\db\backends\utils.py", line 64, in execute
    return self.cursor.execute(sql, params)
  File "D:\Project\redcashier\ve_redcashier\lib\site-packages\django\db\utils.py", line 94, in __exit__
    six.reraise(dj_exc_type, dj_exc_value, traceback)
  File "D:\Project\redcashier\ve_redcashier\lib\site-packages\django\utils\six.py", line 685, in reraise
    raise value.with_traceback(tb)
  File "D:\Project\redcashier\ve_redcashier\lib\site-packages\django\db\backends\utils.py", line 64, in execute
    return self.cursor.execute(sql, params)
  File "D:\Project\redcashier\ve_redcashier\lib\site-packages\django\db\backends\sqlite3\base.py", line 337, in execute
    return Database.Cursor.execute(self, query, params)
django.db.utils.OperationalError: no such column: caja_modcontable.cajaingre_id
[2016-12-01 15:44:48] DEBUG [django.db.backends:90] (0.001) SELECT "caja_modcontable"."id", "caja_modcontable"."cajaingre_id", "caja_modcontable"."nivell_id", "caja_modcontable"."periodocon_id" FROM "caja_modcontable" LIMIT 21; args=()
[2016-12-01 15:44:48] DEBUG [django.db.backends:90] (0.001) SELECT "caja_modcontable"."id", "caja_modcontable"."cajaingre_id", "caja_modcontable"."nivell_id", "caja_modcontable"."periodocon_id" FROM "caja_modcontable" LIMIT 21; args=()
[2016-12-01 15:44:48] DEBUG [django.db.backends:90] (0.001) SELECT "caja_modcontable"."id", "caja_modcontable"."cajaingre_id", "caja_modcontable"."nivell_id", "caja_modcontable"."periodocon_id" FROM "caja_modcontable" LIMIT 21; args=()
[2016-12-01 15:44:48] DEBUG [django.db.backends:90] (0.001) SELECT "caja_modcontable"."id", "caja_modcontable"."cajaingre_id", "caja_modcontable"."nivell_id", "caja_modcontable"."periodocon_id" FROM "caja_modcontable" LIMIT 21; args=()
[2016-12-01 15:44:48] DEBUG [django.db.backends:90] (0.000) SELECT "caja_modcontable"."id", "caja_modcontable"."cajaingre_id", "caja_modcontable"."nivell_id", "caja_modcontable"."periodocon_id" FROM "caja_modcontable" LIMIT 21; args=()
[2016-12-01 15:44:48] DEBUG [django.db.backends:90] (0.000) SELECT "caja_modcontable"."id", "caja_modcontable"."cajaingre_id", "caja_modcontable"."nivell_id", "caja_modcontable"."periodocon_id" FROM "caja_modcontable" LIMIT 21; args=()
[2016-12-01 15:44:48] DEBUG [django.db.backends:90] (0.000) SELECT "caja_modcontable"."id", "caja_modcontable"."cajaingre_id", "caja_modcontable"."nivell_id", "caja_modcontable"."periodocon_id" FROM "caja_modcontable" LIMIT 21; args=()
[2016-12-01 15:44:48] DEBUG [django.db.backends:90] (0.000) SELECT "caja_modcontable"."id", "caja_modcontable"."cajaingre_id", "caja_modcontable"."nivell_id", "caja_modcontable"."periodocon_id" FROM "caja_modcontable" LIMIT 21; args=()
[2016-12-01 15:44:48] DEBUG [django.db.backends:90] (0.000) SELECT "caja_modcontable"."id", "caja_modcontable"."cajaingre_id", "caja_modcontable"."nivell_id", "caja_modcontable"."periodocon_id" FROM "caja_modcontable" LIMIT 21; args=()
[2016-12-01 15:44:48] DEBUG [django.db.backends:90] (0.000) SELECT "caja_modcontable"."id", "caja_modcontable"."cajaingre_id", "caja_modcontable"."nivell_id", "caja_modcontable"."periodocon_id" FROM "caja_modcontable" LIMIT 21; args=()
[2016-12-01 15:44:48] ERROR [django.server:131] "GET /api/caja/modcontables/ HTTP/1.1" 500 21300
