[2016-11-30 16:34:28] DEBUG [django.db.backends:90] (0.007) 
            SELECT name, type FROM sqlite_master
            WHERE type in ('table', 'view') AND NOT name='sqlite_sequence'
            ORDER BY name; args=None
[2016-11-30 16:34:28] DEBUG [django.db.backends:90] (0.000) SELECT "django_migrations"."app", "django_migrations"."name" FROM "django_migrations"; args=()
[2016-11-30 16:40:03] DEBUG [django.db.backends:90] (0.001) 
            SELECT name, type FROM sqlite_master
            WHERE type in ('table', 'view') AND NOT name='sqlite_sequence'
            ORDER BY name; args=None
[2016-11-30 16:40:03] DEBUG [django.db.backends:90] (0.000) SELECT "django_migrations"."app", "django_migrations"."name" FROM "django_migrations"; args=()
[2016-11-30 19:00:11] DEBUG [django.template:929] Exception while resolving variable 'name' in template 'unknown'.
Traceback (most recent call last):
  File "D:\Codigos\LP2\end\redcashier\ve_redcashier\lib\site-packages\django\core\handlers\exception.py", line 39, in inner
    response = get_response(request)
  File "D:\Codigos\LP2\end\redcashier\ve_redcashier\lib\site-packages\django\core\handlers\base.py", line 249, in _legacy_get_response
    response = self._get_response(request)
  File "D:\Codigos\LP2\end\redcashier\ve_redcashier\lib\site-packages\django\core\handlers\base.py", line 172, in _get_response
    resolver_match = resolver.resolve(request.path_info)
  File "D:\Codigos\LP2\end\redcashier\ve_redcashier\lib\site-packages\django\urls\resolvers.py", line 300, in resolve
    raise Resolver404({'tried': tried, 'path': new_path})
django.urls.exceptions.Resolver404: {'path': '', 'tried': [[<RegexURLResolver <RegexURLPattern list> (admin:admin) ^admin/>], [<RegexURLResolver <module 'django.contrib.admindocs.urls' from 'D:\\Codigos\\LP2\\end\\redcashier\\ve_redcashier\\lib\\site-packages\\django\\contrib\\admindocs\\urls.py'> (None:None) ^admin/doc/>], [<RegexURLResolver <module 'rest_framework.urls' from 'D:\\Codigos\\LP2\\end\\redcashier\\ve_redcashier\\lib\\site-packages\\rest_framework\\urls.py'> (rest_framework:rest_framework) ^api-auth/>], [<RegexURLResolver <module 'oauth2_provider.urls' from 'D:\\Codigos\\LP2\\end\\redcashier\\ve_redcashier\\lib\\site-packages\\oauth2_provider\\urls.py'> (None:oauth2_provider) ^o/>], [<RegexURLResolver <module 'redcashier_service_apps.auths_api.urls' from 'D:\\Codigos\\LP2\\end\\redcashier\\redcashier_service\\redcashier_service_apps\\auths_api\\urls.py'> (None:None) ^api/auths/>], [<RegexURLResolver <module 'redcashier_service_apps.catalogo_api.urls' from 'D:\\Codigos\\LP2\\end\\redcashier\\redcashier_service\\redcashier_service_apps\\catalogo_api\\urls.py'> (None:None) ^api/catalogo/>], [<RegexURLResolver <module 'redcashier_service_apps.caja_api.urls' from 'D:\\Codigos\\LP2\\end\\redcashier\\redcashier_service\\redcashier_service_apps\\caja_api\\urls.py'> (None:None) ^api/caja/>]]}

During handling of the above exception, another exception occurred:

Traceback (most recent call last):
  File "D:\Codigos\LP2\end\redcashier\ve_redcashier\lib\site-packages\django\template\base.py", line 885, in _resolve_lookup
    current = current[bit]
TypeError: 'RegexURLResolver' object is not subscriptable

During handling of the above exception, another exception occurred:

Traceback (most recent call last):
  File "D:\Codigos\LP2\end\redcashier\ve_redcashier\lib\site-packages\django\template\base.py", line 893, in _resolve_lookup
    current = getattr(current, bit)
AttributeError: 'RegexURLResolver' object has no attribute 'name'

During handling of the above exception, another exception occurred:

Traceback (most recent call last):
  File "D:\Codigos\LP2\end\redcashier\ve_redcashier\lib\site-packages\django\template\base.py", line 900, in _resolve_lookup
    current = current[int(bit)]
ValueError: invalid literal for int() with base 10: 'name'

During handling of the above exception, another exception occurred:

Traceback (most recent call last):
  File "D:\Codigos\LP2\end\redcashier\ve_redcashier\lib\site-packages\django\template\base.py", line 907, in _resolve_lookup
    (bit, current))  # missing attribute
django.template.base.VariableDoesNotExist: Failed lookup for key [name] in '<RegexURLResolver <RegexURLPattern list> (admin:admin) ^admin/>'
[2016-11-30 19:00:12] DEBUG [django.template:929] Exception while resolving variable 'name' in template 'unknown'.
Traceback (most recent call last):
  File "D:\Codigos\LP2\end\redcashier\ve_redcashier\lib\site-packages\django\core\handlers\exception.py", line 39, in inner
    response = get_response(request)
  File "D:\Codigos\LP2\end\redcashier\ve_redcashier\lib\site-packages\django\core\handlers\base.py", line 249, in _legacy_get_response
    response = self._get_response(request)
  File "D:\Codigos\LP2\end\redcashier\ve_redcashier\lib\site-packages\django\core\handlers\base.py", line 172, in _get_response
    resolver_match = resolver.resolve(request.path_info)
  File "D:\Codigos\LP2\end\redcashier\ve_redcashier\lib\site-packages\django\urls\resolvers.py", line 300, in resolve
    raise Resolver404({'tried': tried, 'path': new_path})
django.urls.exceptions.Resolver404: {'path': '', 'tried': [[<RegexURLResolver <RegexURLPattern list> (admin:admin) ^admin/>], [<RegexURLResolver <module 'django.contrib.admindocs.urls' from 'D:\\Codigos\\LP2\\end\\redcashier\\ve_redcashier\\lib\\site-packages\\django\\contrib\\admindocs\\urls.py'> (None:None) ^admin/doc/>], [<RegexURLResolver <module 'rest_framework.urls' from 'D:\\Codigos\\LP2\\end\\redcashier\\ve_redcashier\\lib\\site-packages\\rest_framework\\urls.py'> (rest_framework:rest_framework) ^api-auth/>], [<RegexURLResolver <module 'oauth2_provider.urls' from 'D:\\Codigos\\LP2\\end\\redcashier\\ve_redcashier\\lib\\site-packages\\oauth2_provider\\urls.py'> (None:oauth2_provider) ^o/>], [<RegexURLResolver <module 'redcashier_service_apps.auths_api.urls' from 'D:\\Codigos\\LP2\\end\\redcashier\\redcashier_service\\redcashier_service_apps\\auths_api\\urls.py'> (None:None) ^api/auths/>], [<RegexURLResolver <module 'redcashier_service_apps.catalogo_api.urls' from 'D:\\Codigos\\LP2\\end\\redcashier\\redcashier_service\\redcashier_service_apps\\catalogo_api\\urls.py'> (None:None) ^api/catalogo/>], [<RegexURLResolver <module 'redcashier_service_apps.caja_api.urls' from 'D:\\Codigos\\LP2\\end\\redcashier\\redcashier_service\\redcashier_service_apps\\caja_api\\urls.py'> (None:None) ^api/caja/>]]}

During handling of the above exception, another exception occurred:

Traceback (most recent call last):
  File "D:\Codigos\LP2\end\redcashier\ve_redcashier\lib\site-packages\django\template\base.py", line 885, in _resolve_lookup
    current = current[bit]
TypeError: 'RegexURLResolver' object is not subscriptable

During handling of the above exception, another exception occurred:

Traceback (most recent call last):
  File "D:\Codigos\LP2\end\redcashier\ve_redcashier\lib\site-packages\django\template\base.py", line 893, in _resolve_lookup
    current = getattr(current, bit)
AttributeError: 'RegexURLResolver' object has no attribute 'name'

During handling of the above exception, another exception occurred:

Traceback (most recent call last):
  File "D:\Codigos\LP2\end\redcashier\ve_redcashier\lib\site-packages\django\template\base.py", line 900, in _resolve_lookup
    current = current[int(bit)]
ValueError: invalid literal for int() with base 10: 'name'

During handling of the above exception, another exception occurred:

Traceback (most recent call last):
  File "D:\Codigos\LP2\end\redcashier\ve_redcashier\lib\site-packages\django\template\base.py", line 907, in _resolve_lookup
    (bit, current))  # missing attribute
django.template.base.VariableDoesNotExist: Failed lookup for key [name] in "<RegexURLResolver <module 'django.contrib.admindocs.urls' from 'D:\\\\Codigos\\\\LP2\\\\end\\\\redcashier\\\\ve_redcashier\\\\lib\\\\site-packages\\\\django\\\\contrib\\\\admindocs\\\\urls.py'> (None:None) ^admin/doc/>"
[2016-11-30 19:00:12] DEBUG [django.template:929] Exception while resolving variable 'name' in template 'unknown'.
Traceback (most recent call last):
  File "D:\Codigos\LP2\end\redcashier\ve_redcashier\lib\site-packages\django\core\handlers\exception.py", line 39, in inner
    response = get_response(request)
  File "D:\Codigos\LP2\end\redcashier\ve_redcashier\lib\site-packages\django\core\handlers\base.py", line 249, in _legacy_get_response
    response = self._get_response(request)
  File "D:\Codigos\LP2\end\redcashier\ve_redcashier\lib\site-packages\django\core\handlers\base.py", line 172, in _get_response
    resolver_match = resolver.resolve(request.path_info)
  File "D:\Codigos\LP2\end\redcashier\ve_redcashier\lib\site-packages\django\urls\resolvers.py", line 300, in resolve
    raise Resolver404({'tried': tried, 'path': new_path})
django.urls.exceptions.Resolver404: {'path': '', 'tried': [[<RegexURLResolver <RegexURLPattern list> (admin:admin) ^admin/>], [<RegexURLResolver <module 'django.contrib.admindocs.urls' from 'D:\\Codigos\\LP2\\end\\redcashier\\ve_redcashier\\lib\\site-packages\\django\\contrib\\admindocs\\urls.py'> (None:None) ^admin/doc/>], [<RegexURLResolver <module 'rest_framework.urls' from 'D:\\Codigos\\LP2\\end\\redcashier\\ve_redcashier\\lib\\site-packages\\rest_framework\\urls.py'> (rest_framework:rest_framework) ^api-auth/>], [<RegexURLResolver <module 'oauth2_provider.urls' from 'D:\\Codigos\\LP2\\end\\redcashier\\ve_redcashier\\lib\\site-packages\\oauth2_provider\\urls.py'> (None:oauth2_provider) ^o/>], [<RegexURLResolver <module 'redcashier_service_apps.auths_api.urls' from 'D:\\Codigos\\LP2\\end\\redcashier\\redcashier_service\\redcashier_service_apps\\auths_api\\urls.py'> (None:None) ^api/auths/>], [<RegexURLResolver <module 'redcashier_service_apps.catalogo_api.urls' from 'D:\\Codigos\\LP2\\end\\redcashier\\redcashier_service\\redcashier_service_apps\\catalogo_api\\urls.py'> (None:None) ^api/catalogo/>], [<RegexURLResolver <module 'redcashier_service_apps.caja_api.urls' from 'D:\\Codigos\\LP2\\end\\redcashier\\redcashier_service\\redcashier_service_apps\\caja_api\\urls.py'> (None:None) ^api/caja/>]]}

During handling of the above exception, another exception occurred:

Traceback (most recent call last):
  File "D:\Codigos\LP2\end\redcashier\ve_redcashier\lib\site-packages\django\template\base.py", line 885, in _resolve_lookup
    current = current[bit]
TypeError: 'RegexURLResolver' object is not subscriptable

During handling of the above exception, another exception occurred:

Traceback (most recent call last):
  File "D:\Codigos\LP2\end\redcashier\ve_redcashier\lib\site-packages\django\template\base.py", line 893, in _resolve_lookup
    current = getattr(current, bit)
AttributeError: 'RegexURLResolver' object has no attribute 'name'

During handling of the above exception, another exception occurred:

Traceback (most recent call last):
  File "D:\Codigos\LP2\end\redcashier\ve_redcashier\lib\site-packages\django\template\base.py", line 900, in _resolve_lookup
    current = current[int(bit)]
ValueError: invalid literal for int() with base 10: 'name'

During handling of the above exception, another exception occurred:

Traceback (most recent call last):
  File "D:\Codigos\LP2\end\redcashier\ve_redcashier\lib\site-packages\django\template\base.py", line 907, in _resolve_lookup
    (bit, current))  # missing attribute
django.template.base.VariableDoesNotExist: Failed lookup for key [name] in "<RegexURLResolver <module 'rest_framework.urls' from 'D:\\\\Codigos\\\\LP2\\\\end\\\\redcashier\\\\ve_redcashier\\\\lib\\\\site-packages\\\\rest_framework\\\\urls.py'> (rest_framework:rest_framework) ^api-auth/>"
[2016-11-30 19:00:12] DEBUG [django.template:929] Exception while resolving variable 'name' in template 'unknown'.
Traceback (most recent call last):
  File "D:\Codigos\LP2\end\redcashier\ve_redcashier\lib\site-packages\django\core\handlers\exception.py", line 39, in inner
    response = get_response(request)
  File "D:\Codigos\LP2\end\redcashier\ve_redcashier\lib\site-packages\django\core\handlers\base.py", line 249, in _legacy_get_response
    response = self._get_response(request)
  File "D:\Codigos\LP2\end\redcashier\ve_redcashier\lib\site-packages\django\core\handlers\base.py", line 172, in _get_response
    resolver_match = resolver.resolve(request.path_info)
  File "D:\Codigos\LP2\end\redcashier\ve_redcashier\lib\site-packages\django\urls\resolvers.py", line 300, in resolve
    raise Resolver404({'tried': tried, 'path': new_path})
django.urls.exceptions.Resolver404: {'path': '', 'tried': [[<RegexURLResolver <RegexURLPattern list> (admin:admin) ^admin/>], [<RegexURLResolver <module 'django.contrib.admindocs.urls' from 'D:\\Codigos\\LP2\\end\\redcashier\\ve_redcashier\\lib\\site-packages\\django\\contrib\\admindocs\\urls.py'> (None:None) ^admin/doc/>], [<RegexURLResolver <module 'rest_framework.urls' from 'D:\\Codigos\\LP2\\end\\redcashier\\ve_redcashier\\lib\\site-packages\\rest_framework\\urls.py'> (rest_framework:rest_framework) ^api-auth/>], [<RegexURLResolver <module 'oauth2_provider.urls' from 'D:\\Codigos\\LP2\\end\\redcashier\\ve_redcashier\\lib\\site-packages\\oauth2_provider\\urls.py'> (None:oauth2_provider) ^o/>], [<RegexURLResolver <module 'redcashier_service_apps.auths_api.urls' from 'D:\\Codigos\\LP2\\end\\redcashier\\redcashier_service\\redcashier_service_apps\\auths_api\\urls.py'> (None:None) ^api/auths/>], [<RegexURLResolver <module 'redcashier_service_apps.catalogo_api.urls' from 'D:\\Codigos\\LP2\\end\\redcashier\\redcashier_service\\redcashier_service_apps\\catalogo_api\\urls.py'> (None:None) ^api/catalogo/>], [<RegexURLResolver <module 'redcashier_service_apps.caja_api.urls' from 'D:\\Codigos\\LP2\\end\\redcashier\\redcashier_service\\redcashier_service_apps\\caja_api\\urls.py'> (None:None) ^api/caja/>]]}

During handling of the above exception, another exception occurred:

Traceback (most recent call last):
  File "D:\Codigos\LP2\end\redcashier\ve_redcashier\lib\site-packages\django\template\base.py", line 885, in _resolve_lookup
    current = current[bit]
TypeError: 'RegexURLResolver' object is not subscriptable

During handling of the above exception, another exception occurred:

Traceback (most recent call last):
  File "D:\Codigos\LP2\end\redcashier\ve_redcashier\lib\site-packages\django\template\base.py", line 893, in _resolve_lookup
    current = getattr(current, bit)
AttributeError: 'RegexURLResolver' object has no attribute 'name'

During handling of the above exception, another exception occurred:

Traceback (most recent call last):
  File "D:\Codigos\LP2\end\redcashier\ve_redcashier\lib\site-packages\django\template\base.py", line 900, in _resolve_lookup
    current = current[int(bit)]
ValueError: invalid literal for int() with base 10: 'name'

During handling of the above exception, another exception occurred:

Traceback (most recent call last):
  File "D:\Codigos\LP2\end\redcashier\ve_redcashier\lib\site-packages\django\template\base.py", line 907, in _resolve_lookup
    (bit, current))  # missing attribute
django.template.base.VariableDoesNotExist: Failed lookup for key [name] in "<RegexURLResolver <module 'oauth2_provider.urls' from 'D:\\\\Codigos\\\\LP2\\\\end\\\\redcashier\\\\ve_redcashier\\\\lib\\\\site-packages\\\\oauth2_provider\\\\urls.py'> (None:oauth2_provider) ^o/>"
[2016-11-30 19:00:12] DEBUG [django.template:929] Exception while resolving variable 'name' in template 'unknown'.
Traceback (most recent call last):
  File "D:\Codigos\LP2\end\redcashier\ve_redcashier\lib\site-packages\django\core\handlers\exception.py", line 39, in inner
    response = get_response(request)
  File "D:\Codigos\LP2\end\redcashier\ve_redcashier\lib\site-packages\django\core\handlers\base.py", line 249, in _legacy_get_response
    response = self._get_response(request)
  File "D:\Codigos\LP2\end\redcashier\ve_redcashier\lib\site-packages\django\core\handlers\base.py", line 172, in _get_response
    resolver_match = resolver.resolve(request.path_info)
  File "D:\Codigos\LP2\end\redcashier\ve_redcashier\lib\site-packages\django\urls\resolvers.py", line 300, in resolve
    raise Resolver404({'tried': tried, 'path': new_path})
django.urls.exceptions.Resolver404: {'path': '', 'tried': [[<RegexURLResolver <RegexURLPattern list> (admin:admin) ^admin/>], [<RegexURLResolver <module 'django.contrib.admindocs.urls' from 'D:\\Codigos\\LP2\\end\\redcashier\\ve_redcashier\\lib\\site-packages\\django\\contrib\\admindocs\\urls.py'> (None:None) ^admin/doc/>], [<RegexURLResolver <module 'rest_framework.urls' from 'D:\\Codigos\\LP2\\end\\redcashier\\ve_redcashier\\lib\\site-packages\\rest_framework\\urls.py'> (rest_framework:rest_framework) ^api-auth/>], [<RegexURLResolver <module 'oauth2_provider.urls' from 'D:\\Codigos\\LP2\\end\\redcashier\\ve_redcashier\\lib\\site-packages\\oauth2_provider\\urls.py'> (None:oauth2_provider) ^o/>], [<RegexURLResolver <module 'redcashier_service_apps.auths_api.urls' from 'D:\\Codigos\\LP2\\end\\redcashier\\redcashier_service\\redcashier_service_apps\\auths_api\\urls.py'> (None:None) ^api/auths/>], [<RegexURLResolver <module 'redcashier_service_apps.catalogo_api.urls' from 'D:\\Codigos\\LP2\\end\\redcashier\\redcashier_service\\redcashier_service_apps\\catalogo_api\\urls.py'> (None:None) ^api/catalogo/>], [<RegexURLResolver <module 'redcashier_service_apps.caja_api.urls' from 'D:\\Codigos\\LP2\\end\\redcashier\\redcashier_service\\redcashier_service_apps\\caja_api\\urls.py'> (None:None) ^api/caja/>]]}

During handling of the above exception, another exception occurred:

Traceback (most recent call last):
  File "D:\Codigos\LP2\end\redcashier\ve_redcashier\lib\site-packages\django\template\base.py", line 885, in _resolve_lookup
    current = current[bit]
TypeError: 'RegexURLResolver' object is not subscriptable

During handling of the above exception, another exception occurred:

Traceback (most recent call last):
  File "D:\Codigos\LP2\end\redcashier\ve_redcashier\lib\site-packages\django\template\base.py", line 893, in _resolve_lookup
    current = getattr(current, bit)
AttributeError: 'RegexURLResolver' object has no attribute 'name'

During handling of the above exception, another exception occurred:

Traceback (most recent call last):
  File "D:\Codigos\LP2\end\redcashier\ve_redcashier\lib\site-packages\django\template\base.py", line 900, in _resolve_lookup
    current = current[int(bit)]
ValueError: invalid literal for int() with base 10: 'name'

During handling of the above exception, another exception occurred:

Traceback (most recent call last):
  File "D:\Codigos\LP2\end\redcashier\ve_redcashier\lib\site-packages\django\template\base.py", line 907, in _resolve_lookup
    (bit, current))  # missing attribute
django.template.base.VariableDoesNotExist: Failed lookup for key [name] in "<RegexURLResolver <module 'redcashier_service_apps.auths_api.urls' from 'D:\\\\Codigos\\\\LP2\\\\end\\\\redcashier\\\\redcashier_service\\\\redcashier_service_apps\\\\auths_api\\\\urls.py'> (None:None) ^api/auths/>"
[2016-11-30 19:00:12] DEBUG [django.template:929] Exception while resolving variable 'name' in template 'unknown'.
Traceback (most recent call last):
  File "D:\Codigos\LP2\end\redcashier\ve_redcashier\lib\site-packages\django\core\handlers\exception.py", line 39, in inner
    response = get_response(request)
  File "D:\Codigos\LP2\end\redcashier\ve_redcashier\lib\site-packages\django\core\handlers\base.py", line 249, in _legacy_get_response
    response = self._get_response(request)
  File "D:\Codigos\LP2\end\redcashier\ve_redcashier\lib\site-packages\django\core\handlers\base.py", line 172, in _get_response
    resolver_match = resolver.resolve(request.path_info)
  File "D:\Codigos\LP2\end\redcashier\ve_redcashier\lib\site-packages\django\urls\resolvers.py", line 300, in resolve
    raise Resolver404({'tried': tried, 'path': new_path})
django.urls.exceptions.Resolver404: {'path': '', 'tried': [[<RegexURLResolver <RegexURLPattern list> (admin:admin) ^admin/>], [<RegexURLResolver <module 'django.contrib.admindocs.urls' from 'D:\\Codigos\\LP2\\end\\redcashier\\ve_redcashier\\lib\\site-packages\\django\\contrib\\admindocs\\urls.py'> (None:None) ^admin/doc/>], [<RegexURLResolver <module 'rest_framework.urls' from 'D:\\Codigos\\LP2\\end\\redcashier\\ve_redcashier\\lib\\site-packages\\rest_framework\\urls.py'> (rest_framework:rest_framework) ^api-auth/>], [<RegexURLResolver <module 'oauth2_provider.urls' from 'D:\\Codigos\\LP2\\end\\redcashier\\ve_redcashier\\lib\\site-packages\\oauth2_provider\\urls.py'> (None:oauth2_provider) ^o/>], [<RegexURLResolver <module 'redcashier_service_apps.auths_api.urls' from 'D:\\Codigos\\LP2\\end\\redcashier\\redcashier_service\\redcashier_service_apps\\auths_api\\urls.py'> (None:None) ^api/auths/>], [<RegexURLResolver <module 'redcashier_service_apps.catalogo_api.urls' from 'D:\\Codigos\\LP2\\end\\redcashier\\redcashier_service\\redcashier_service_apps\\catalogo_api\\urls.py'> (None:None) ^api/catalogo/>], [<RegexURLResolver <module 'redcashier_service_apps.caja_api.urls' from 'D:\\Codigos\\LP2\\end\\redcashier\\redcashier_service\\redcashier_service_apps\\caja_api\\urls.py'> (None:None) ^api/caja/>]]}

During handling of the above exception, another exception occurred:

Traceback (most recent call last):
  File "D:\Codigos\LP2\end\redcashier\ve_redcashier\lib\site-packages\django\template\base.py", line 885, in _resolve_lookup
    current = current[bit]
TypeError: 'RegexURLResolver' object is not subscriptable

During handling of the above exception, another exception occurred:

Traceback (most recent call last):
  File "D:\Codigos\LP2\end\redcashier\ve_redcashier\lib\site-packages\django\template\base.py", line 893, in _resolve_lookup
    current = getattr(current, bit)
AttributeError: 'RegexURLResolver' object has no attribute 'name'

During handling of the above exception, another exception occurred:

Traceback (most recent call last):
  File "D:\Codigos\LP2\end\redcashier\ve_redcashier\lib\site-packages\django\template\base.py", line 900, in _resolve_lookup
    current = current[int(bit)]
ValueError: invalid literal for int() with base 10: 'name'

During handling of the above exception, another exception occurred:

Traceback (most recent call last):
  File "D:\Codigos\LP2\end\redcashier\ve_redcashier\lib\site-packages\django\template\base.py", line 907, in _resolve_lookup
    (bit, current))  # missing attribute
django.template.base.VariableDoesNotExist: Failed lookup for key [name] in "<RegexURLResolver <module 'redcashier_service_apps.catalogo_api.urls' from 'D:\\\\Codigos\\\\LP2\\\\end\\\\redcashier\\\\redcashier_service\\\\redcashier_service_apps\\\\catalogo_api\\\\urls.py'> (None:None) ^api/catalogo/>"
[2016-11-30 19:00:12] DEBUG [django.template:929] Exception while resolving variable 'name' in template 'unknown'.
Traceback (most recent call last):
  File "D:\Codigos\LP2\end\redcashier\ve_redcashier\lib\site-packages\django\core\handlers\exception.py", line 39, in inner
    response = get_response(request)
  File "D:\Codigos\LP2\end\redcashier\ve_redcashier\lib\site-packages\django\core\handlers\base.py", line 249, in _legacy_get_response
    response = self._get_response(request)
  File "D:\Codigos\LP2\end\redcashier\ve_redcashier\lib\site-packages\django\core\handlers\base.py", line 172, in _get_response
    resolver_match = resolver.resolve(request.path_info)
  File "D:\Codigos\LP2\end\redcashier\ve_redcashier\lib\site-packages\django\urls\resolvers.py", line 300, in resolve
    raise Resolver404({'tried': tried, 'path': new_path})
django.urls.exceptions.Resolver404: {'path': '', 'tried': [[<RegexURLResolver <RegexURLPattern list> (admin:admin) ^admin/>], [<RegexURLResolver <module 'django.contrib.admindocs.urls' from 'D:\\Codigos\\LP2\\end\\redcashier\\ve_redcashier\\lib\\site-packages\\django\\contrib\\admindocs\\urls.py'> (None:None) ^admin/doc/>], [<RegexURLResolver <module 'rest_framework.urls' from 'D:\\Codigos\\LP2\\end\\redcashier\\ve_redcashier\\lib\\site-packages\\rest_framework\\urls.py'> (rest_framework:rest_framework) ^api-auth/>], [<RegexURLResolver <module 'oauth2_provider.urls' from 'D:\\Codigos\\LP2\\end\\redcashier\\ve_redcashier\\lib\\site-packages\\oauth2_provider\\urls.py'> (None:oauth2_provider) ^o/>], [<RegexURLResolver <module 'redcashier_service_apps.auths_api.urls' from 'D:\\Codigos\\LP2\\end\\redcashier\\redcashier_service\\redcashier_service_apps\\auths_api\\urls.py'> (None:None) ^api/auths/>], [<RegexURLResolver <module 'redcashier_service_apps.catalogo_api.urls' from 'D:\\Codigos\\LP2\\end\\redcashier\\redcashier_service\\redcashier_service_apps\\catalogo_api\\urls.py'> (None:None) ^api/catalogo/>], [<RegexURLResolver <module 'redcashier_service_apps.caja_api.urls' from 'D:\\Codigos\\LP2\\end\\redcashier\\redcashier_service\\redcashier_service_apps\\caja_api\\urls.py'> (None:None) ^api/caja/>]]}

During handling of the above exception, another exception occurred:

Traceback (most recent call last):
  File "D:\Codigos\LP2\end\redcashier\ve_redcashier\lib\site-packages\django\template\base.py", line 885, in _resolve_lookup
    current = current[bit]
TypeError: 'RegexURLResolver' object is not subscriptable

During handling of the above exception, another exception occurred:

Traceback (most recent call last):
  File "D:\Codigos\LP2\end\redcashier\ve_redcashier\lib\site-packages\django\template\base.py", line 893, in _resolve_lookup
    current = getattr(current, bit)
AttributeError: 'RegexURLResolver' object has no attribute 'name'

During handling of the above exception, another exception occurred:

Traceback (most recent call last):
  File "D:\Codigos\LP2\end\redcashier\ve_redcashier\lib\site-packages\django\template\base.py", line 900, in _resolve_lookup
    current = current[int(bit)]
ValueError: invalid literal for int() with base 10: 'name'

During handling of the above exception, another exception occurred:

Traceback (most recent call last):
  File "D:\Codigos\LP2\end\redcashier\ve_redcashier\lib\site-packages\django\template\base.py", line 907, in _resolve_lookup
    (bit, current))  # missing attribute
django.template.base.VariableDoesNotExist: Failed lookup for key [name] in "<RegexURLResolver <module 'redcashier_service_apps.caja_api.urls' from 'D:\\\\Codigos\\\\LP2\\\\end\\\\redcashier\\\\redcashier_service\\\\redcashier_service_apps\\\\caja_api\\\\urls.py'> (None:None) ^api/caja/>"
[2016-11-30 19:00:12] WARNING [django.request:152] Not Found: /
[2016-11-30 19:00:12] WARNING [django.server:131] "GET / HTTP/1.1" 404 2571
[2016-11-30 19:00:12] DEBUG [django.template:929] Exception while resolving variable 'name' in template 'unknown'.
Traceback (most recent call last):
  File "D:\Codigos\LP2\end\redcashier\ve_redcashier\lib\site-packages\django\core\handlers\exception.py", line 39, in inner
    response = get_response(request)
  File "D:\Codigos\LP2\end\redcashier\ve_redcashier\lib\site-packages\django\core\handlers\base.py", line 249, in _legacy_get_response
    response = self._get_response(request)
  File "D:\Codigos\LP2\end\redcashier\ve_redcashier\lib\site-packages\django\core\handlers\base.py", line 172, in _get_response
    resolver_match = resolver.resolve(request.path_info)
  File "D:\Codigos\LP2\end\redcashier\ve_redcashier\lib\site-packages\django\urls\resolvers.py", line 300, in resolve
    raise Resolver404({'tried': tried, 'path': new_path})
django.urls.exceptions.Resolver404: {'path': 'favicon.ico', 'tried': [[<RegexURLResolver <RegexURLPattern list> (admin:admin) ^admin/>], [<RegexURLResolver <module 'django.contrib.admindocs.urls' from 'D:\\Codigos\\LP2\\end\\redcashier\\ve_redcashier\\lib\\site-packages\\django\\contrib\\admindocs\\urls.py'> (None:None) ^admin/doc/>], [<RegexURLResolver <module 'rest_framework.urls' from 'D:\\Codigos\\LP2\\end\\redcashier\\ve_redcashier\\lib\\site-packages\\rest_framework\\urls.py'> (rest_framework:rest_framework) ^api-auth/>], [<RegexURLResolver <module 'oauth2_provider.urls' from 'D:\\Codigos\\LP2\\end\\redcashier\\ve_redcashier\\lib\\site-packages\\oauth2_provider\\urls.py'> (None:oauth2_provider) ^o/>], [<RegexURLResolver <module 'redcashier_service_apps.auths_api.urls' from 'D:\\Codigos\\LP2\\end\\redcashier\\redcashier_service\\redcashier_service_apps\\auths_api\\urls.py'> (None:None) ^api/auths/>], [<RegexURLResolver <module 'redcashier_service_apps.catalogo_api.urls' from 'D:\\Codigos\\LP2\\end\\redcashier\\redcashier_service\\redcashier_service_apps\\catalogo_api\\urls.py'> (None:None) ^api/catalogo/>], [<RegexURLResolver <module 'redcashier_service_apps.caja_api.urls' from 'D:\\Codigos\\LP2\\end\\redcashier\\redcashier_service\\redcashier_service_apps\\caja_api\\urls.py'> (None:None) ^api/caja/>]]}

During handling of the above exception, another exception occurred:

Traceback (most recent call last):
  File "D:\Codigos\LP2\end\redcashier\ve_redcashier\lib\site-packages\django\template\base.py", line 885, in _resolve_lookup
    current = current[bit]
TypeError: 'RegexURLResolver' object is not subscriptable

During handling of the above exception, another exception occurred:

Traceback (most recent call last):
  File "D:\Codigos\LP2\end\redcashier\ve_redcashier\lib\site-packages\django\template\base.py", line 893, in _resolve_lookup
    current = getattr(current, bit)
AttributeError: 'RegexURLResolver' object has no attribute 'name'

During handling of the above exception, another exception occurred:

Traceback (most recent call last):
  File "D:\Codigos\LP2\end\redcashier\ve_redcashier\lib\site-packages\django\template\base.py", line 900, in _resolve_lookup
    current = current[int(bit)]
ValueError: invalid literal for int() with base 10: 'name'

During handling of the above exception, another exception occurred:

Traceback (most recent call last):
  File "D:\Codigos\LP2\end\redcashier\ve_redcashier\lib\site-packages\django\template\base.py", line 907, in _resolve_lookup
    (bit, current))  # missing attribute
django.template.base.VariableDoesNotExist: Failed lookup for key [name] in '<RegexURLResolver <RegexURLPattern list> (admin:admin) ^admin/>'
[2016-11-30 19:00:12] DEBUG [django.template:929] Exception while resolving variable 'name' in template 'unknown'.
Traceback (most recent call last):
  File "D:\Codigos\LP2\end\redcashier\ve_redcashier\lib\site-packages\django\core\handlers\exception.py", line 39, in inner
    response = get_response(request)
  File "D:\Codigos\LP2\end\redcashier\ve_redcashier\lib\site-packages\django\core\handlers\base.py", line 249, in _legacy_get_response
    response = self._get_response(request)
  File "D:\Codigos\LP2\end\redcashier\ve_redcashier\lib\site-packages\django\core\handlers\base.py", line 172, in _get_response
    resolver_match = resolver.resolve(request.path_info)
  File "D:\Codigos\LP2\end\redcashier\ve_redcashier\lib\site-packages\django\urls\resolvers.py", line 300, in resolve
    raise Resolver404({'tried': tried, 'path': new_path})
django.urls.exceptions.Resolver404: {'path': 'favicon.ico', 'tried': [[<RegexURLResolver <RegexURLPattern list> (admin:admin) ^admin/>], [<RegexURLResolver <module 'django.contrib.admindocs.urls' from 'D:\\Codigos\\LP2\\end\\redcashier\\ve_redcashier\\lib\\site-packages\\django\\contrib\\admindocs\\urls.py'> (None:None) ^admin/doc/>], [<RegexURLResolver <module 'rest_framework.urls' from 'D:\\Codigos\\LP2\\end\\redcashier\\ve_redcashier\\lib\\site-packages\\rest_framework\\urls.py'> (rest_framework:rest_framework) ^api-auth/>], [<RegexURLResolver <module 'oauth2_provider.urls' from 'D:\\Codigos\\LP2\\end\\redcashier\\ve_redcashier\\lib\\site-packages\\oauth2_provider\\urls.py'> (None:oauth2_provider) ^o/>], [<RegexURLResolver <module 'redcashier_service_apps.auths_api.urls' from 'D:\\Codigos\\LP2\\end\\redcashier\\redcashier_service\\redcashier_service_apps\\auths_api\\urls.py'> (None:None) ^api/auths/>], [<RegexURLResolver <module 'redcashier_service_apps.catalogo_api.urls' from 'D:\\Codigos\\LP2\\end\\redcashier\\redcashier_service\\redcashier_service_apps\\catalogo_api\\urls.py'> (None:None) ^api/catalogo/>], [<RegexURLResolver <module 'redcashier_service_apps.caja_api.urls' from 'D:\\Codigos\\LP2\\end\\redcashier\\redcashier_service\\redcashier_service_apps\\caja_api\\urls.py'> (None:None) ^api/caja/>]]}

During handling of the above exception, another exception occurred:

Traceback (most recent call last):
  File "D:\Codigos\LP2\end\redcashier\ve_redcashier\lib\site-packages\django\template\base.py", line 885, in _resolve_lookup
    current = current[bit]
TypeError: 'RegexURLResolver' object is not subscriptable

During handling of the above exception, another exception occurred:

Traceback (most recent call last):
  File "D:\Codigos\LP2\end\redcashier\ve_redcashier\lib\site-packages\django\template\base.py", line 893, in _resolve_lookup
    current = getattr(current, bit)
AttributeError: 'RegexURLResolver' object has no attribute 'name'

During handling of the above exception, another exception occurred:

Traceback (most recent call last):
  File "D:\Codigos\LP2\end\redcashier\ve_redcashier\lib\site-packages\django\template\base.py", line 900, in _resolve_lookup
    current = current[int(bit)]
ValueError: invalid literal for int() with base 10: 'name'

During handling of the above exception, another exception occurred:

Traceback (most recent call last):
  File "D:\Codigos\LP2\end\redcashier\ve_redcashier\lib\site-packages\django\template\base.py", line 907, in _resolve_lookup
    (bit, current))  # missing attribute
django.template.base.VariableDoesNotExist: Failed lookup for key [name] in "<RegexURLResolver <module 'django.contrib.admindocs.urls' from 'D:\\\\Codigos\\\\LP2\\\\end\\\\redcashier\\\\ve_redcashier\\\\lib\\\\site-packages\\\\django\\\\contrib\\\\admindocs\\\\urls.py'> (None:None) ^admin/doc/>"
[2016-11-30 19:00:12] DEBUG [django.template:929] Exception while resolving variable 'name' in template 'unknown'.
Traceback (most recent call last):
  File "D:\Codigos\LP2\end\redcashier\ve_redcashier\lib\site-packages\django\core\handlers\exception.py", line 39, in inner
    response = get_response(request)
  File "D:\Codigos\LP2\end\redcashier\ve_redcashier\lib\site-packages\django\core\handlers\base.py", line 249, in _legacy_get_response
    response = self._get_response(request)
  File "D:\Codigos\LP2\end\redcashier\ve_redcashier\lib\site-packages\django\core\handlers\base.py", line 172, in _get_response
    resolver_match = resolver.resolve(request.path_info)
  File "D:\Codigos\LP2\end\redcashier\ve_redcashier\lib\site-packages\django\urls\resolvers.py", line 300, in resolve
    raise Resolver404({'tried': tried, 'path': new_path})
django.urls.exceptions.Resolver404: {'path': 'favicon.ico', 'tried': [[<RegexURLResolver <RegexURLPattern list> (admin:admin) ^admin/>], [<RegexURLResolver <module 'django.contrib.admindocs.urls' from 'D:\\Codigos\\LP2\\end\\redcashier\\ve_redcashier\\lib\\site-packages\\django\\contrib\\admindocs\\urls.py'> (None:None) ^admin/doc/>], [<RegexURLResolver <module 'rest_framework.urls' from 'D:\\Codigos\\LP2\\end\\redcashier\\ve_redcashier\\lib\\site-packages\\rest_framework\\urls.py'> (rest_framework:rest_framework) ^api-auth/>], [<RegexURLResolver <module 'oauth2_provider.urls' from 'D:\\Codigos\\LP2\\end\\redcashier\\ve_redcashier\\lib\\site-packages\\oauth2_provider\\urls.py'> (None:oauth2_provider) ^o/>], [<RegexURLResolver <module 'redcashier_service_apps.auths_api.urls' from 'D:\\Codigos\\LP2\\end\\redcashier\\redcashier_service\\redcashier_service_apps\\auths_api\\urls.py'> (None:None) ^api/auths/>], [<RegexURLResolver <module 'redcashier_service_apps.catalogo_api.urls' from 'D:\\Codigos\\LP2\\end\\redcashier\\redcashier_service\\redcashier_service_apps\\catalogo_api\\urls.py'> (None:None) ^api/catalogo/>], [<RegexURLResolver <module 'redcashier_service_apps.caja_api.urls' from 'D:\\Codigos\\LP2\\end\\redcashier\\redcashier_service\\redcashier_service_apps\\caja_api\\urls.py'> (None:None) ^api/caja/>]]}

During handling of the above exception, another exception occurred:

Traceback (most recent call last):
  File "D:\Codigos\LP2\end\redcashier\ve_redcashier\lib\site-packages\django\template\base.py", line 885, in _resolve_lookup
    current = current[bit]
TypeError: 'RegexURLResolver' object is not subscriptable

During handling of the above exception, another exception occurred:

Traceback (most recent call last):
  File "D:\Codigos\LP2\end\redcashier\ve_redcashier\lib\site-packages\django\template\base.py", line 893, in _resolve_lookup
    current = getattr(current, bit)
AttributeError: 'RegexURLResolver' object has no attribute 'name'

During handling of the above exception, another exception occurred:

Traceback (most recent call last):
  File "D:\Codigos\LP2\end\redcashier\ve_redcashier\lib\site-packages\django\template\base.py", line 900, in _resolve_lookup
    current = current[int(bit)]
ValueError: invalid literal for int() with base 10: 'name'

During handling of the above exception, another exception occurred:

Traceback (most recent call last):
  File "D:\Codigos\LP2\end\redcashier\ve_redcashier\lib\site-packages\django\template\base.py", line 907, in _resolve_lookup
    (bit, current))  # missing attribute
django.template.base.VariableDoesNotExist: Failed lookup for key [name] in "<RegexURLResolver <module 'rest_framework.urls' from 'D:\\\\Codigos\\\\LP2\\\\end\\\\redcashier\\\\ve_redcashier\\\\lib\\\\site-packages\\\\rest_framework\\\\urls.py'> (rest_framework:rest_framework) ^api-auth/>"
[2016-11-30 19:00:12] DEBUG [django.template:929] Exception while resolving variable 'name' in template 'unknown'.
Traceback (most recent call last):
  File "D:\Codigos\LP2\end\redcashier\ve_redcashier\lib\site-packages\django\core\handlers\exception.py", line 39, in inner
    response = get_response(request)
  File "D:\Codigos\LP2\end\redcashier\ve_redcashier\lib\site-packages\django\core\handlers\base.py", line 249, in _legacy_get_response
    response = self._get_response(request)
  File "D:\Codigos\LP2\end\redcashier\ve_redcashier\lib\site-packages\django\core\handlers\base.py", line 172, in _get_response
    resolver_match = resolver.resolve(request.path_info)
  File "D:\Codigos\LP2\end\redcashier\ve_redcashier\lib\site-packages\django\urls\resolvers.py", line 300, in resolve
    raise Resolver404({'tried': tried, 'path': new_path})
django.urls.exceptions.Resolver404: {'path': 'favicon.ico', 'tried': [[<RegexURLResolver <RegexURLPattern list> (admin:admin) ^admin/>], [<RegexURLResolver <module 'django.contrib.admindocs.urls' from 'D:\\Codigos\\LP2\\end\\redcashier\\ve_redcashier\\lib\\site-packages\\django\\contrib\\admindocs\\urls.py'> (None:None) ^admin/doc/>], [<RegexURLResolver <module 'rest_framework.urls' from 'D:\\Codigos\\LP2\\end\\redcashier\\ve_redcashier\\lib\\site-packages\\rest_framework\\urls.py'> (rest_framework:rest_framework) ^api-auth/>], [<RegexURLResolver <module 'oauth2_provider.urls' from 'D:\\Codigos\\LP2\\end\\redcashier\\ve_redcashier\\lib\\site-packages\\oauth2_provider\\urls.py'> (None:oauth2_provider) ^o/>], [<RegexURLResolver <module 'redcashier_service_apps.auths_api.urls' from 'D:\\Codigos\\LP2\\end\\redcashier\\redcashier_service\\redcashier_service_apps\\auths_api\\urls.py'> (None:None) ^api/auths/>], [<RegexURLResolver <module 'redcashier_service_apps.catalogo_api.urls' from 'D:\\Codigos\\LP2\\end\\redcashier\\redcashier_service\\redcashier_service_apps\\catalogo_api\\urls.py'> (None:None) ^api/catalogo/>], [<RegexURLResolver <module 'redcashier_service_apps.caja_api.urls' from 'D:\\Codigos\\LP2\\end\\redcashier\\redcashier_service\\redcashier_service_apps\\caja_api\\urls.py'> (None:None) ^api/caja/>]]}

During handling of the above exception, another exception occurred:

Traceback (most recent call last):
  File "D:\Codigos\LP2\end\redcashier\ve_redcashier\lib\site-packages\django\template\base.py", line 885, in _resolve_lookup
    current = current[bit]
TypeError: 'RegexURLResolver' object is not subscriptable

During handling of the above exception, another exception occurred:

Traceback (most recent call last):
  File "D:\Codigos\LP2\end\redcashier\ve_redcashier\lib\site-packages\django\template\base.py", line 893, in _resolve_lookup
    current = getattr(current, bit)
AttributeError: 'RegexURLResolver' object has no attribute 'name'

During handling of the above exception, another exception occurred:

Traceback (most recent call last):
  File "D:\Codigos\LP2\end\redcashier\ve_redcashier\lib\site-packages\django\template\base.py", line 900, in _resolve_lookup
    current = current[int(bit)]
ValueError: invalid literal for int() with base 10: 'name'

During handling of the above exception, another exception occurred:

Traceback (most recent call last):
  File "D:\Codigos\LP2\end\redcashier\ve_redcashier\lib\site-packages\django\template\base.py", line 907, in _resolve_lookup
    (bit, current))  # missing attribute
django.template.base.VariableDoesNotExist: Failed lookup for key [name] in "<RegexURLResolver <module 'oauth2_provider.urls' from 'D:\\\\Codigos\\\\LP2\\\\end\\\\redcashier\\\\ve_redcashier\\\\lib\\\\site-packages\\\\oauth2_provider\\\\urls.py'> (None:oauth2_provider) ^o/>"
[2016-11-30 19:00:12] DEBUG [django.template:929] Exception while resolving variable 'name' in template 'unknown'.
Traceback (most recent call last):
  File "D:\Codigos\LP2\end\redcashier\ve_redcashier\lib\site-packages\django\core\handlers\exception.py", line 39, in inner
    response = get_response(request)
  File "D:\Codigos\LP2\end\redcashier\ve_redcashier\lib\site-packages\django\core\handlers\base.py", line 249, in _legacy_get_response
    response = self._get_response(request)
  File "D:\Codigos\LP2\end\redcashier\ve_redcashier\lib\site-packages\django\core\handlers\base.py", line 172, in _get_response
    resolver_match = resolver.resolve(request.path_info)
  File "D:\Codigos\LP2\end\redcashier\ve_redcashier\lib\site-packages\django\urls\resolvers.py", line 300, in resolve
    raise Resolver404({'tried': tried, 'path': new_path})
django.urls.exceptions.Resolver404: {'path': 'favicon.ico', 'tried': [[<RegexURLResolver <RegexURLPattern list> (admin:admin) ^admin/>], [<RegexURLResolver <module 'django.contrib.admindocs.urls' from 'D:\\Codigos\\LP2\\end\\redcashier\\ve_redcashier\\lib\\site-packages\\django\\contrib\\admindocs\\urls.py'> (None:None) ^admin/doc/>], [<RegexURLResolver <module 'rest_framework.urls' from 'D:\\Codigos\\LP2\\end\\redcashier\\ve_redcashier\\lib\\site-packages\\rest_framework\\urls.py'> (rest_framework:rest_framework) ^api-auth/>], [<RegexURLResolver <module 'oauth2_provider.urls' from 'D:\\Codigos\\LP2\\end\\redcashier\\ve_redcashier\\lib\\site-packages\\oauth2_provider\\urls.py'> (None:oauth2_provider) ^o/>], [<RegexURLResolver <module 'redcashier_service_apps.auths_api.urls' from 'D:\\Codigos\\LP2\\end\\redcashier\\redcashier_service\\redcashier_service_apps\\auths_api\\urls.py'> (None:None) ^api/auths/>], [<RegexURLResolver <module 'redcashier_service_apps.catalogo_api.urls' from 'D:\\Codigos\\LP2\\end\\redcashier\\redcashier_service\\redcashier_service_apps\\catalogo_api\\urls.py'> (None:None) ^api/catalogo/>], [<RegexURLResolver <module 'redcashier_service_apps.caja_api.urls' from 'D:\\Codigos\\LP2\\end\\redcashier\\redcashier_service\\redcashier_service_apps\\caja_api\\urls.py'> (None:None) ^api/caja/>]]}

During handling of the above exception, another exception occurred:

Traceback (most recent call last):
  File "D:\Codigos\LP2\end\redcashier\ve_redcashier\lib\site-packages\django\template\base.py", line 885, in _resolve_lookup
    current = current[bit]
TypeError: 'RegexURLResolver' object is not subscriptable

During handling of the above exception, another exception occurred:

Traceback (most recent call last):
  File "D:\Codigos\LP2\end\redcashier\ve_redcashier\lib\site-packages\django\template\base.py", line 893, in _resolve_lookup
    current = getattr(current, bit)
AttributeError: 'RegexURLResolver' object has no attribute 'name'

During handling of the above exception, another exception occurred:

Traceback (most recent call last):
  File "D:\Codigos\LP2\end\redcashier\ve_redcashier\lib\site-packages\django\template\base.py", line 900, in _resolve_lookup
    current = current[int(bit)]
ValueError: invalid literal for int() with base 10: 'name'

During handling of the above exception, another exception occurred:

Traceback (most recent call last):
  File "D:\Codigos\LP2\end\redcashier\ve_redcashier\lib\site-packages\django\template\base.py", line 907, in _resolve_lookup
    (bit, current))  # missing attribute
django.template.base.VariableDoesNotExist: Failed lookup for key [name] in "<RegexURLResolver <module 'redcashier_service_apps.auths_api.urls' from 'D:\\\\Codigos\\\\LP2\\\\end\\\\redcashier\\\\redcashier_service\\\\redcashier_service_apps\\\\auths_api\\\\urls.py'> (None:None) ^api/auths/>"
[2016-11-30 19:00:12] DEBUG [django.template:929] Exception while resolving variable 'name' in template 'unknown'.
Traceback (most recent call last):
  File "D:\Codigos\LP2\end\redcashier\ve_redcashier\lib\site-packages\django\core\handlers\exception.py", line 39, in inner
    response = get_response(request)
  File "D:\Codigos\LP2\end\redcashier\ve_redcashier\lib\site-packages\django\core\handlers\base.py", line 249, in _legacy_get_response
    response = self._get_response(request)
  File "D:\Codigos\LP2\end\redcashier\ve_redcashier\lib\site-packages\django\core\handlers\base.py", line 172, in _get_response
    resolver_match = resolver.resolve(request.path_info)
  File "D:\Codigos\LP2\end\redcashier\ve_redcashier\lib\site-packages\django\urls\resolvers.py", line 300, in resolve
    raise Resolver404({'tried': tried, 'path': new_path})
django.urls.exceptions.Resolver404: {'path': 'favicon.ico', 'tried': [[<RegexURLResolver <RegexURLPattern list> (admin:admin) ^admin/>], [<RegexURLResolver <module 'django.contrib.admindocs.urls' from 'D:\\Codigos\\LP2\\end\\redcashier\\ve_redcashier\\lib\\site-packages\\django\\contrib\\admindocs\\urls.py'> (None:None) ^admin/doc/>], [<RegexURLResolver <module 'rest_framework.urls' from 'D:\\Codigos\\LP2\\end\\redcashier\\ve_redcashier\\lib\\site-packages\\rest_framework\\urls.py'> (rest_framework:rest_framework) ^api-auth/>], [<RegexURLResolver <module 'oauth2_provider.urls' from 'D:\\Codigos\\LP2\\end\\redcashier\\ve_redcashier\\lib\\site-packages\\oauth2_provider\\urls.py'> (None:oauth2_provider) ^o/>], [<RegexURLResolver <module 'redcashier_service_apps.auths_api.urls' from 'D:\\Codigos\\LP2\\end\\redcashier\\redcashier_service\\redcashier_service_apps\\auths_api\\urls.py'> (None:None) ^api/auths/>], [<RegexURLResolver <module 'redcashier_service_apps.catalogo_api.urls' from 'D:\\Codigos\\LP2\\end\\redcashier\\redcashier_service\\redcashier_service_apps\\catalogo_api\\urls.py'> (None:None) ^api/catalogo/>], [<RegexURLResolver <module 'redcashier_service_apps.caja_api.urls' from 'D:\\Codigos\\LP2\\end\\redcashier\\redcashier_service\\redcashier_service_apps\\caja_api\\urls.py'> (None:None) ^api/caja/>]]}

During handling of the above exception, another exception occurred:

Traceback (most recent call last):
  File "D:\Codigos\LP2\end\redcashier\ve_redcashier\lib\site-packages\django\template\base.py", line 885, in _resolve_lookup
    current = current[bit]
TypeError: 'RegexURLResolver' object is not subscriptable

During handling of the above exception, another exception occurred:

Traceback (most recent call last):
  File "D:\Codigos\LP2\end\redcashier\ve_redcashier\lib\site-packages\django\template\base.py", line 893, in _resolve_lookup
    current = getattr(current, bit)
AttributeError: 'RegexURLResolver' object has no attribute 'name'

During handling of the above exception, another exception occurred:

Traceback (most recent call last):
  File "D:\Codigos\LP2\end\redcashier\ve_redcashier\lib\site-packages\django\template\base.py", line 900, in _resolve_lookup
    current = current[int(bit)]
ValueError: invalid literal for int() with base 10: 'name'

During handling of the above exception, another exception occurred:

Traceback (most recent call last):
  File "D:\Codigos\LP2\end\redcashier\ve_redcashier\lib\site-packages\django\template\base.py", line 907, in _resolve_lookup
    (bit, current))  # missing attribute
django.template.base.VariableDoesNotExist: Failed lookup for key [name] in "<RegexURLResolver <module 'redcashier_service_apps.catalogo_api.urls' from 'D:\\\\Codigos\\\\LP2\\\\end\\\\redcashier\\\\redcashier_service\\\\redcashier_service_apps\\\\catalogo_api\\\\urls.py'> (None:None) ^api/catalogo/>"
[2016-11-30 19:00:12] DEBUG [django.template:929] Exception while resolving variable 'name' in template 'unknown'.
Traceback (most recent call last):
  File "D:\Codigos\LP2\end\redcashier\ve_redcashier\lib\site-packages\django\core\handlers\exception.py", line 39, in inner
    response = get_response(request)
  File "D:\Codigos\LP2\end\redcashier\ve_redcashier\lib\site-packages\django\core\handlers\base.py", line 249, in _legacy_get_response
    response = self._get_response(request)
  File "D:\Codigos\LP2\end\redcashier\ve_redcashier\lib\site-packages\django\core\handlers\base.py", line 172, in _get_response
    resolver_match = resolver.resolve(request.path_info)
  File "D:\Codigos\LP2\end\redcashier\ve_redcashier\lib\site-packages\django\urls\resolvers.py", line 300, in resolve
    raise Resolver404({'tried': tried, 'path': new_path})
django.urls.exceptions.Resolver404: {'path': 'favicon.ico', 'tried': [[<RegexURLResolver <RegexURLPattern list> (admin:admin) ^admin/>], [<RegexURLResolver <module 'django.contrib.admindocs.urls' from 'D:\\Codigos\\LP2\\end\\redcashier\\ve_redcashier\\lib\\site-packages\\django\\contrib\\admindocs\\urls.py'> (None:None) ^admin/doc/>], [<RegexURLResolver <module 'rest_framework.urls' from 'D:\\Codigos\\LP2\\end\\redcashier\\ve_redcashier\\lib\\site-packages\\rest_framework\\urls.py'> (rest_framework:rest_framework) ^api-auth/>], [<RegexURLResolver <module 'oauth2_provider.urls' from 'D:\\Codigos\\LP2\\end\\redcashier\\ve_redcashier\\lib\\site-packages\\oauth2_provider\\urls.py'> (None:oauth2_provider) ^o/>], [<RegexURLResolver <module 'redcashier_service_apps.auths_api.urls' from 'D:\\Codigos\\LP2\\end\\redcashier\\redcashier_service\\redcashier_service_apps\\auths_api\\urls.py'> (None:None) ^api/auths/>], [<RegexURLResolver <module 'redcashier_service_apps.catalogo_api.urls' from 'D:\\Codigos\\LP2\\end\\redcashier\\redcashier_service\\redcashier_service_apps\\catalogo_api\\urls.py'> (None:None) ^api/catalogo/>], [<RegexURLResolver <module 'redcashier_service_apps.caja_api.urls' from 'D:\\Codigos\\LP2\\end\\redcashier\\redcashier_service\\redcashier_service_apps\\caja_api\\urls.py'> (None:None) ^api/caja/>]]}

During handling of the above exception, another exception occurred:

Traceback (most recent call last):
  File "D:\Codigos\LP2\end\redcashier\ve_redcashier\lib\site-packages\django\template\base.py", line 885, in _resolve_lookup
    current = current[bit]
TypeError: 'RegexURLResolver' object is not subscriptable

During handling of the above exception, another exception occurred:

Traceback (most recent call last):
  File "D:\Codigos\LP2\end\redcashier\ve_redcashier\lib\site-packages\django\template\base.py", line 893, in _resolve_lookup
    current = getattr(current, bit)
AttributeError: 'RegexURLResolver' object has no attribute 'name'

During handling of the above exception, another exception occurred:

Traceback (most recent call last):
  File "D:\Codigos\LP2\end\redcashier\ve_redcashier\lib\site-packages\django\template\base.py", line 900, in _resolve_lookup
    current = current[int(bit)]
ValueError: invalid literal for int() with base 10: 'name'

During handling of the above exception, another exception occurred:

Traceback (most recent call last):
  File "D:\Codigos\LP2\end\redcashier\ve_redcashier\lib\site-packages\django\template\base.py", line 907, in _resolve_lookup
    (bit, current))  # missing attribute
django.template.base.VariableDoesNotExist: Failed lookup for key [name] in "<RegexURLResolver <module 'redcashier_service_apps.caja_api.urls' from 'D:\\\\Codigos\\\\LP2\\\\end\\\\redcashier\\\\redcashier_service\\\\redcashier_service_apps\\\\caja_api\\\\urls.py'> (None:None) ^api/caja/>"
[2016-11-30 19:00:12] WARNING [django.request:152] Not Found: /favicon.ico
[2016-11-30 19:00:12] WARNING [django.server:131] "GET /favicon.ico HTTP/1.1" 404 2604
[2016-11-30 19:00:14] DEBUG [django.db.backends:90] (0.038) SELECT "auths_menu"."router_json" FROM "auths_menu" ORDER BY "auths_menu"."pos" ASC; args=()
[2016-11-30 19:00:14] INFO [django.server:131] "GET /api/auths/routers/ HTTP/1.1" 200 2
[2016-11-30 19:00:22] INFO [django.server:131] "GET /admin/ HTTP/1.1" 302 0
[2016-11-30 19:00:23] DEBUG [django.template:929] Exception while resolving variable 'is_popup' in template 'admin/login.html'.
Traceback (most recent call last):
  File "D:\Codigos\LP2\end\redcashier\ve_redcashier\lib\site-packages\django\template\base.py", line 885, in _resolve_lookup
    current = current[bit]
  File "D:\Codigos\LP2\end\redcashier\ve_redcashier\lib\site-packages\django\template\context.py", line 75, in __getitem__
    raise KeyError(key)
KeyError: 'is_popup'

During handling of the above exception, another exception occurred:

Traceback (most recent call last):
  File "D:\Codigos\LP2\end\redcashier\ve_redcashier\lib\site-packages\django\template\base.py", line 891, in _resolve_lookup
    if isinstance(current, BaseContext) and getattr(type(current), bit):
AttributeError: type object 'RequestContext' has no attribute 'is_popup'

During handling of the above exception, another exception occurred:

Traceback (most recent call last):
  File "D:\Codigos\LP2\end\redcashier\ve_redcashier\lib\site-packages\django\template\base.py", line 900, in _resolve_lookup
    current = current[int(bit)]
ValueError: invalid literal for int() with base 10: 'is_popup'

During handling of the above exception, another exception occurred:

Traceback (most recent call last):
  File "D:\Codigos\LP2\end\redcashier\ve_redcashier\lib\site-packages\django\template\base.py", line 907, in _resolve_lookup
    (bit, current))  # missing attribute
django.template.base.VariableDoesNotExist: Failed lookup for key [is_popup] in "[{'False': False, 'True': True, 'None': None}, {'request': <WSGIRequest: GET '/admin/login/?next=/admin/'>, 'perms': <django.contrib.auth.context_processors.PermWrapper object at 0x04574490>, 'csrf_token': <SimpleLazyObject: <function csrf.<locals>._get_val at 0x042558E8>>, 'user': <SimpleLazyObject: <django.contrib.auth.models.AnonymousUser object at 0x0425A6B0>>, 'messages': <django.contrib.messages.storage.fallback.FallbackStorage object at 0x044BE530>, 'DEFAULT_MESSAGE_LEVELS': {'INFO': 20, 'WARNING': 30, 'DEBUG': 10, 'SUCCESS': 25, 'ERROR': 40}}, {}, {'site_name': 'localhost:9000', 'next': '/admin/', 'LANGUAGE_BIDI': False, 'site_title': <django.utils.functional.lazy.<locals>.__proxy__ object at 0x034B4BF0>, 'site_url': '/', 'available_apps': [], 'site_header': <django.utils.functional.lazy.<locals>.__proxy__ object at 0x034B4C50>, 'username': '', 'has_permission': False, 'app_path': '/admin/login/?next=/admin/', 'form': <AdminAuthenticationForm bound=False, valid=Unknown, fields=(username;password)>, 'site': <django.contrib.sites.requests.RequestSite object at 0x04502F50>, 'LANGUAGE_CODE': 'en-us', 'title': 'Log in'}]"
[2016-11-30 19:00:23] DEBUG [django.template:929] Exception while resolving variable 'is_popup' in template 'admin/login.html'.
Traceback (most recent call last):
  File "D:\Codigos\LP2\end\redcashier\ve_redcashier\lib\site-packages\django\template\base.py", line 885, in _resolve_lookup
    current = current[bit]
  File "D:\Codigos\LP2\end\redcashier\ve_redcashier\lib\site-packages\django\template\context.py", line 75, in __getitem__
    raise KeyError(key)
KeyError: 'is_popup'

During handling of the above exception, another exception occurred:

Traceback (most recent call last):
  File "D:\Codigos\LP2\end\redcashier\ve_redcashier\lib\site-packages\django\template\base.py", line 891, in _resolve_lookup
    if isinstance(current, BaseContext) and getattr(type(current), bit):
AttributeError: type object 'RequestContext' has no attribute 'is_popup'

During handling of the above exception, another exception occurred:

Traceback (most recent call last):
  File "D:\Codigos\LP2\end\redcashier\ve_redcashier\lib\site-packages\django\template\base.py", line 900, in _resolve_lookup
    current = current[int(bit)]
ValueError: invalid literal for int() with base 10: 'is_popup'

During handling of the above exception, another exception occurred:

Traceback (most recent call last):
  File "D:\Codigos\LP2\end\redcashier\ve_redcashier\lib\site-packages\django\template\base.py", line 907, in _resolve_lookup
    (bit, current))  # missing attribute
django.template.base.VariableDoesNotExist: Failed lookup for key [is_popup] in "[{'False': False, 'True': True, 'None': None}, {'request': <WSGIRequest: GET '/admin/login/?next=/admin/'>, 'perms': <django.contrib.auth.context_processors.PermWrapper object at 0x04574490>, 'csrf_token': <SimpleLazyObject: <function csrf.<locals>._get_val at 0x042558E8>>, 'user': <SimpleLazyObject: <django.contrib.auth.models.AnonymousUser object at 0x0425A6B0>>, 'messages': <django.contrib.messages.storage.fallback.FallbackStorage object at 0x044BE530>, 'DEFAULT_MESSAGE_LEVELS': {'INFO': 20, 'WARNING': 30, 'DEBUG': 10, 'SUCCESS': 25, 'ERROR': 40}}, {}, {'site_name': 'localhost:9000', 'next': '/admin/', 'LANGUAGE_BIDI': False, 'site_title': <django.utils.functional.lazy.<locals>.__proxy__ object at 0x034B4BF0>, 'site_url': '/', 'available_apps': [], 'site_header': <django.utils.functional.lazy.<locals>.__proxy__ object at 0x034B4C50>, 'username': '', 'has_permission': False, 'app_path': '/admin/login/?next=/admin/', 'form': <AdminAuthenticationForm bound=False, valid=Unknown, fields=(username;password)>, 'site': <django.contrib.sites.requests.RequestSite object at 0x04502F50>, 'LANGUAGE_CODE': 'en-us', 'title': 'Log in'}]"
[2016-11-30 19:00:23] INFO [django.server:131] "GET /admin/login/?next=/admin/ HTTP/1.1" 200 1658
[2016-11-30 19:00:23] INFO [django.server:131] "GET /static/admin/css/login.css HTTP/1.1" 304 0
[2016-11-30 19:00:23] INFO [django.server:131] "GET /static/admin/css/base.css HTTP/1.1" 304 0
[2016-11-30 19:00:23] INFO [django.server:131] "GET /static/admin/css/fonts.css HTTP/1.1" 304 0
[2016-11-30 19:00:23] INFO [django.server:131] "GET /static/admin/fonts/Roboto-Regular-webfont.woff HTTP/1.1" 304 0
[2016-11-30 19:00:23] INFO [django.server:131] "GET /static/admin/fonts/Roboto-Light-webfont.woff HTTP/1.1" 304 0
[2016-11-30 19:00:33] DEBUG [django.db.backends:90] (0.001) SELECT "auths_user"."password", "auths_user"."last_login", "auths_user"."is_superuser", "auths_user"."username", "auths_user"."first_name", "auths_user"."last_name", "auths_user"."email", "auths_user"."is_staff", "auths_user"."is_active", "auths_user"."date_joined", "auths_user"."id", "auths_user"."last_hierarchy_id", "auths_user"."last_module_id", "auths_user"."person_id", "auths_user"."updated_at", "auths_user"."registered_by" FROM "auths_user" WHERE "auths_user"."username" = 'kenny'; args=('kenny',)
[2016-11-30 19:00:33] DEBUG [django.template:929] Exception while resolving variable 'is_popup' in template 'admin/login.html'.
Traceback (most recent call last):
  File "D:\Codigos\LP2\end\redcashier\ve_redcashier\lib\site-packages\django\template\base.py", line 885, in _resolve_lookup
    current = current[bit]
  File "D:\Codigos\LP2\end\redcashier\ve_redcashier\lib\site-packages\django\template\context.py", line 75, in __getitem__
    raise KeyError(key)
KeyError: 'is_popup'

During handling of the above exception, another exception occurred:

Traceback (most recent call last):
  File "D:\Codigos\LP2\end\redcashier\ve_redcashier\lib\site-packages\django\template\base.py", line 891, in _resolve_lookup
    if isinstance(current, BaseContext) and getattr(type(current), bit):
AttributeError: type object 'RequestContext' has no attribute 'is_popup'

During handling of the above exception, another exception occurred:

Traceback (most recent call last):
  File "D:\Codigos\LP2\end\redcashier\ve_redcashier\lib\site-packages\django\template\base.py", line 900, in _resolve_lookup
    current = current[int(bit)]
ValueError: invalid literal for int() with base 10: 'is_popup'

During handling of the above exception, another exception occurred:

Traceback (most recent call last):
  File "D:\Codigos\LP2\end\redcashier\ve_redcashier\lib\site-packages\django\template\base.py", line 907, in _resolve_lookup
    (bit, current))  # missing attribute
django.template.base.VariableDoesNotExist: Failed lookup for key [is_popup] in "[{'False': False, 'True': True, 'None': None}, {'request': <WSGIRequest: POST '/admin/login/?next=/admin/'>, 'perms': <django.contrib.auth.context_processors.PermWrapper object at 0x0425A890>, 'csrf_token': <SimpleLazyObject: <function csrf.<locals>._get_val at 0x030E5DF8>>, 'user': <SimpleLazyObject: <django.contrib.auth.models.AnonymousUser object at 0x045711F0>>, 'messages': <django.contrib.messages.storage.fallback.FallbackStorage object at 0x04571130>, 'DEFAULT_MESSAGE_LEVELS': {'INFO': 20, 'WARNING': 30, 'DEBUG': 10, 'SUCCESS': 25, 'ERROR': 40}}, {}, {'site_name': 'localhost:9000', 'next': '/admin/', 'LANGUAGE_BIDI': False, 'site_title': <django.utils.functional.lazy.<locals>.__proxy__ object at 0x034B4BF0>, 'site_url': '/', 'available_apps': [], 'site_header': <django.utils.functional.lazy.<locals>.__proxy__ object at 0x034B4C50>, 'username': '', 'has_permission': False, 'app_path': '/admin/login/?next=/admin/', 'form': <AdminAuthenticationForm bound=True, valid=False, fields=(username;password)>, 'site': <django.contrib.sites.requests.RequestSite object at 0x04571170>, 'LANGUAGE_CODE': 'en-us', 'title': 'Log in'}]"
[2016-11-30 19:00:33] DEBUG [django.template:929] Exception while resolving variable 'is_popup' in template 'admin/login.html'.
Traceback (most recent call last):
  File "D:\Codigos\LP2\end\redcashier\ve_redcashier\lib\site-packages\django\template\base.py", line 885, in _resolve_lookup
    current = current[bit]
  File "D:\Codigos\LP2\end\redcashier\ve_redcashier\lib\site-packages\django\template\context.py", line 75, in __getitem__
    raise KeyError(key)
KeyError: 'is_popup'

During handling of the above exception, another exception occurred:

Traceback (most recent call last):
  File "D:\Codigos\LP2\end\redcashier\ve_redcashier\lib\site-packages\django\template\base.py", line 891, in _resolve_lookup
    if isinstance(current, BaseContext) and getattr(type(current), bit):
AttributeError: type object 'RequestContext' has no attribute 'is_popup'

During handling of the above exception, another exception occurred:

Traceback (most recent call last):
  File "D:\Codigos\LP2\end\redcashier\ve_redcashier\lib\site-packages\django\template\base.py", line 900, in _resolve_lookup
    current = current[int(bit)]
ValueError: invalid literal for int() with base 10: 'is_popup'

During handling of the above exception, another exception occurred:

Traceback (most recent call last):
  File "D:\Codigos\LP2\end\redcashier\ve_redcashier\lib\site-packages\django\template\base.py", line 907, in _resolve_lookup
    (bit, current))  # missing attribute
django.template.base.VariableDoesNotExist: Failed lookup for key [is_popup] in "[{'False': False, 'True': True, 'None': None}, {'request': <WSGIRequest: POST '/admin/login/?next=/admin/'>, 'perms': <django.contrib.auth.context_processors.PermWrapper object at 0x0425A890>, 'csrf_token': <SimpleLazyObject: <function csrf.<locals>._get_val at 0x030E5DF8>>, 'user': <SimpleLazyObject: <django.contrib.auth.models.AnonymousUser object at 0x045711F0>>, 'messages': <django.contrib.messages.storage.fallback.FallbackStorage object at 0x04571130>, 'DEFAULT_MESSAGE_LEVELS': {'INFO': 20, 'WARNING': 30, 'DEBUG': 10, 'SUCCESS': 25, 'ERROR': 40}}, {}, {'site_name': 'localhost:9000', 'next': '/admin/', 'LANGUAGE_BIDI': False, 'site_title': <django.utils.functional.lazy.<locals>.__proxy__ object at 0x034B4BF0>, 'site_url': '/', 'available_apps': [], 'site_header': <django.utils.functional.lazy.<locals>.__proxy__ object at 0x034B4C50>, 'username': '', 'has_permission': False, 'app_path': '/admin/login/?next=/admin/', 'form': <AdminAuthenticationForm bound=True, valid=False, fields=(username;password)>, 'site': <django.contrib.sites.requests.RequestSite object at 0x04571170>, 'LANGUAGE_CODE': 'en-us', 'title': 'Log in'}]"
[2016-11-30 19:00:33] INFO [django.server:131] "POST /admin/login/?next=/admin/ HTTP/1.1" 200 1819
[2016-11-30 19:00:34] INFO [django.server:131] "GET /static/admin/fonts/Roboto-Bold-webfont.woff HTTP/1.1" 304 0
[2016-11-30 19:00:40] DEBUG [django.db.backends:90] (0.001) SELECT "auths_user"."password", "auths_user"."last_login", "auths_user"."is_superuser", "auths_user"."username", "auths_user"."first_name", "auths_user"."last_name", "auths_user"."email", "auths_user"."is_staff", "auths_user"."is_active", "auths_user"."date_joined", "auths_user"."id", "auths_user"."last_hierarchy_id", "auths_user"."last_module_id", "auths_user"."person_id", "auths_user"."updated_at", "auths_user"."registered_by" FROM "auths_user" WHERE "auths_user"."username" = 'sol'; args=('sol',)
[2016-11-30 19:00:41] DEBUG [django.template:929] Exception while resolving variable 'is_popup' in template 'admin/login.html'.
Traceback (most recent call last):
  File "D:\Codigos\LP2\end\redcashier\ve_redcashier\lib\site-packages\django\template\base.py", line 885, in _resolve_lookup
    current = current[bit]
  File "D:\Codigos\LP2\end\redcashier\ve_redcashier\lib\site-packages\django\template\context.py", line 75, in __getitem__
    raise KeyError(key)
KeyError: 'is_popup'

During handling of the above exception, another exception occurred:

Traceback (most recent call last):
  File "D:\Codigos\LP2\end\redcashier\ve_redcashier\lib\site-packages\django\template\base.py", line 891, in _resolve_lookup
    if isinstance(current, BaseContext) and getattr(type(current), bit):
AttributeError: type object 'RequestContext' has no attribute 'is_popup'

During handling of the above exception, another exception occurred:

Traceback (most recent call last):
  File "D:\Codigos\LP2\end\redcashier\ve_redcashier\lib\site-packages\django\template\base.py", line 900, in _resolve_lookup
    current = current[int(bit)]
ValueError: invalid literal for int() with base 10: 'is_popup'

During handling of the above exception, another exception occurred:

Traceback (most recent call last):
  File "D:\Codigos\LP2\end\redcashier\ve_redcashier\lib\site-packages\django\template\base.py", line 907, in _resolve_lookup
    (bit, current))  # missing attribute
django.template.base.VariableDoesNotExist: Failed lookup for key [is_popup] in "[{'False': False, 'True': True, 'None': None}, {'request': <WSGIRequest: POST '/admin/login/?next=/admin/'>, 'perms': <django.contrib.auth.context_processors.PermWrapper object at 0x045802D0>, 'csrf_token': <SimpleLazyObject: <function csrf.<locals>._get_val at 0x0459B4B0>>, 'user': <SimpleLazyObject: <django.contrib.auth.models.AnonymousUser object at 0x04571330>>, 'messages': <django.contrib.messages.storage.fallback.FallbackStorage object at 0x045713F0>, 'DEFAULT_MESSAGE_LEVELS': {'INFO': 20, 'WARNING': 30, 'DEBUG': 10, 'SUCCESS': 25, 'ERROR': 40}}, {}, {'site_name': 'localhost:9000', 'next': '/admin/', 'LANGUAGE_BIDI': False, 'site_title': <django.utils.functional.lazy.<locals>.__proxy__ object at 0x034B4BF0>, 'site_url': '/', 'available_apps': [], 'site_header': <django.utils.functional.lazy.<locals>.__proxy__ object at 0x034B4C50>, 'username': '', 'has_permission': False, 'app_path': '/admin/login/?next=/admin/', 'form': <AdminAuthenticationForm bound=True, valid=False, fields=(username;password)>, 'site': <django.contrib.sites.requests.RequestSite object at 0x04571E50>, 'LANGUAGE_CODE': 'en-us', 'title': 'Log in'}]"
[2016-11-30 19:00:41] DEBUG [django.template:929] Exception while resolving variable 'is_popup' in template 'admin/login.html'.
Traceback (most recent call last):
  File "D:\Codigos\LP2\end\redcashier\ve_redcashier\lib\site-packages\django\template\base.py", line 885, in _resolve_lookup
    current = current[bit]
  File "D:\Codigos\LP2\end\redcashier\ve_redcashier\lib\site-packages\django\template\context.py", line 75, in __getitem__
    raise KeyError(key)
KeyError: 'is_popup'

During handling of the above exception, another exception occurred:

Traceback (most recent call last):
  File "D:\Codigos\LP2\end\redcashier\ve_redcashier\lib\site-packages\django\template\base.py", line 891, in _resolve_lookup
    if isinstance(current, BaseContext) and getattr(type(current), bit):
AttributeError: type object 'RequestContext' has no attribute 'is_popup'

During handling of the above exception, another exception occurred:

Traceback (most recent call last):
  File "D:\Codigos\LP2\end\redcashier\ve_redcashier\lib\site-packages\django\template\base.py", line 900, in _resolve_lookup
    current = current[int(bit)]
ValueError: invalid literal for int() with base 10: 'is_popup'

During handling of the above exception, another exception occurred:

Traceback (most recent call last):
  File "D:\Codigos\LP2\end\redcashier\ve_redcashier\lib\site-packages\django\template\base.py", line 907, in _resolve_lookup
    (bit, current))  # missing attribute
django.template.base.VariableDoesNotExist: Failed lookup for key [is_popup] in "[{'False': False, 'True': True, 'None': None}, {'request': <WSGIRequest: POST '/admin/login/?next=/admin/'>, 'perms': <django.contrib.auth.context_processors.PermWrapper object at 0x045802D0>, 'csrf_token': <SimpleLazyObject: <function csrf.<locals>._get_val at 0x0459B4B0>>, 'user': <SimpleLazyObject: <django.contrib.auth.models.AnonymousUser object at 0x04571330>>, 'messages': <django.contrib.messages.storage.fallback.FallbackStorage object at 0x045713F0>, 'DEFAULT_MESSAGE_LEVELS': {'INFO': 20, 'WARNING': 30, 'DEBUG': 10, 'SUCCESS': 25, 'ERROR': 40}}, {}, {'site_name': 'localhost:9000', 'next': '/admin/', 'LANGUAGE_BIDI': False, 'site_title': <django.utils.functional.lazy.<locals>.__proxy__ object at 0x034B4BF0>, 'site_url': '/', 'available_apps': [], 'site_header': <django.utils.functional.lazy.<locals>.__proxy__ object at 0x034B4C50>, 'username': '', 'has_permission': False, 'app_path': '/admin/login/?next=/admin/', 'form': <AdminAuthenticationForm bound=True, valid=False, fields=(username;password)>, 'site': <django.contrib.sites.requests.RequestSite object at 0x04571E50>, 'LANGUAGE_CODE': 'en-us', 'title': 'Log in'}]"
[2016-11-30 19:00:41] INFO [django.server:131] "POST /admin/login/?next=/admin/ HTTP/1.1" 200 1817
[2016-11-30 19:00:50] DEBUG [django.db.backends:90] (0.001) SELECT "oauth2_provider_application"."id", "oauth2_provider_application"."client_id", "oauth2_provider_application"."user_id", "oauth2_provider_application"."redirect_uris", "oauth2_provider_application"."client_type", "oauth2_provider_application"."authorization_grant_type", "oauth2_provider_application"."client_secret", "oauth2_provider_application"."name", "oauth2_provider_application"."skip_authorization" FROM "oauth2_provider_application" WHERE "oauth2_provider_application"."client_id" = '9xrM04wZYb2KK8wk4ye9zm3K12JlMcU2k0ozcIAz'; args=('9xrM04wZYb2KK8wk4ye9zm3K12JlMcU2k0ozcIAz',)
[2016-11-30 19:00:50] DEBUG [django.db.backends:90] (0.001) SELECT "auths_user"."password", "auths_user"."last_login", "auths_user"."is_superuser", "auths_user"."username", "auths_user"."first_name", "auths_user"."last_name", "auths_user"."email", "auths_user"."is_staff", "auths_user"."is_active", "auths_user"."date_joined", "auths_user"."id", "auths_user"."last_hierarchy_id", "auths_user"."last_module_id", "auths_user"."person_id", "auths_user"."updated_at", "auths_user"."registered_by" FROM "auths_user" WHERE "auths_user"."username" = 'sol'; args=('sol',)
[2016-11-30 19:00:51] WARNING [django.server:131] "POST /o/token/ HTTP/1.1" 401 77
[2016-11-30 19:01:29] DEBUG [django.db.backends:90] (0.003) 
            SELECT name, type FROM sqlite_master
            WHERE type in ('table', 'view') AND NOT name='sqlite_sequence'
            ORDER BY name; args=None
[2016-11-30 19:01:29] DEBUG [django.db.backends:90] (0.028) SELECT "django_migrations"."app", "django_migrations"."name" FROM "django_migrations"; args=()
[2016-11-30 19:01:32] DEBUG [django.db.backends:90] (0.000) SELECT "auths_user"."password", "auths_user"."last_login", "auths_user"."is_superuser", "auths_user"."username", "auths_user"."first_name", "auths_user"."last_name", "auths_user"."email", "auths_user"."is_staff", "auths_user"."is_active", "auths_user"."date_joined", "auths_user"."id", "auths_user"."last_hierarchy_id", "auths_user"."last_module_id", "auths_user"."person_id", "auths_user"."updated_at", "auths_user"."registered_by" FROM "auths_user" WHERE "auths_user"."username" = 'ken'; args=('ken',)
[2016-11-30 19:01:53] DEBUG [django.db.backends:90] (0.001) 
            SELECT name, type FROM sqlite_master
            WHERE type in ('table', 'view') AND NOT name='sqlite_sequence'
            ORDER BY name; args=None
[2016-11-30 19:01:53] DEBUG [django.db.backends:90] (0.000) SELECT "django_migrations"."app", "django_migrations"."name" FROM "django_migrations"; args=()
[2016-11-30 19:01:58] DEBUG [django.db.backends:90] (0.001) SELECT "oauth2_provider_application"."id", "oauth2_provider_application"."client_id", "oauth2_provider_application"."user_id", "oauth2_provider_application"."redirect_uris", "oauth2_provider_application"."client_type", "oauth2_provider_application"."authorization_grant_type", "oauth2_provider_application"."client_secret", "oauth2_provider_application"."name", "oauth2_provider_application"."skip_authorization" FROM "oauth2_provider_application" WHERE "oauth2_provider_application"."client_id" = '9xrM04wZYb2KK8wk4ye9zm3K12JlMcU2k0ozcIAz'; args=('9xrM04wZYb2KK8wk4ye9zm3K12JlMcU2k0ozcIAz',)
[2016-11-30 19:01:58] DEBUG [django.db.backends:90] (0.000) SELECT "auths_user"."password", "auths_user"."last_login", "auths_user"."is_superuser", "auths_user"."username", "auths_user"."first_name", "auths_user"."last_name", "auths_user"."email", "auths_user"."is_staff", "auths_user"."is_active", "auths_user"."date_joined", "auths_user"."id", "auths_user"."last_hierarchy_id", "auths_user"."last_module_id", "auths_user"."person_id", "auths_user"."updated_at", "auths_user"."registered_by" FROM "auths_user" WHERE "auths_user"."username" = 'ken'; args=('ken',)
[2016-11-30 19:01:58] DEBUG [django.db.backends:90] (0.000) BEGIN; args=None
[2016-11-30 19:01:58] DEBUG [django.db.backends:90] (0.019) INSERT INTO "oauth2_provider_accesstoken" ("user_id", "token", "application_id", "expires", "scope") VALUES ('c0984be488184a5aafe26a71cd216420', '32Lj56wsSfJHc637Qhh2vAfFGUMkz0', 1, '2016-12-01 10:01:58.501142', 'read write'); args=['c0984be488184a5aafe26a71cd216420', '32Lj56wsSfJHc637Qhh2vAfFGUMkz0', 1, '2016-12-01 10:01:58.501142', 'read write']
[2016-11-30 19:01:58] DEBUG [django.db.backends:90] (0.000) BEGIN; args=None
[2016-11-30 19:01:58] DEBUG [django.db.backends:90] (0.022) INSERT INTO "oauth2_provider_refreshtoken" ("user_id", "token", "application_id", "access_token_id") VALUES ('c0984be488184a5aafe26a71cd216420', 'ZCpz2cYSDGD4MIgCphzz3PTeBe2wzh', 1, 4); args=['c0984be488184a5aafe26a71cd216420', 'ZCpz2cYSDGD4MIgCphzz3PTeBe2wzh', 1, 4]
[2016-11-30 19:01:58] INFO [django.server:131] "POST /o/token/ HTTP/1.1" 200 169
[2016-11-30 19:02:02] INFO [django.server:131] "OPTIONS /api/auths/localuserinfo/ HTTP/1.1" 200 0
[2016-11-30 19:02:02] DEBUG [django.db.backends:90] (0.002) SELECT "oauth2_provider_accesstoken"."id", "oauth2_provider_accesstoken"."user_id", "oauth2_provider_accesstoken"."token", "oauth2_provider_accesstoken"."application_id", "oauth2_provider_accesstoken"."expires", "oauth2_provider_accesstoken"."scope", "auths_user"."password", "auths_user"."last_login", "auths_user"."is_superuser", "auths_user"."username", "auths_user"."first_name", "auths_user"."last_name", "auths_user"."email", "auths_user"."is_staff", "auths_user"."is_active", "auths_user"."date_joined", "auths_user"."id", "auths_user"."last_hierarchy_id", "auths_user"."last_module_id", "auths_user"."person_id", "auths_user"."updated_at", "auths_user"."registered_by", "oauth2_provider_application"."id", "oauth2_provider_application"."client_id", "oauth2_provider_application"."user_id", "oauth2_provider_application"."redirect_uris", "oauth2_provider_application"."client_type", "oauth2_provider_application"."authorization_grant_type", "oauth2_provider_application"."client_secret", "oauth2_provider_application"."name", "oauth2_provider_application"."skip_authorization" FROM "oauth2_provider_accesstoken" LEFT OUTER JOIN "auths_user" ON ("oauth2_provider_accesstoken"."user_id" = "auths_user"."id") INNER JOIN "oauth2_provider_application" ON ("oauth2_provider_accesstoken"."application_id" = "oauth2_provider_application"."id") WHERE "oauth2_provider_accesstoken"."token" = '32Lj56wsSfJHc637Qhh2vAfFGUMkz0'; args=('32Lj56wsSfJHc637Qhh2vAfFGUMkz0',)
[2016-11-30 19:02:02] DEBUG [django.db.backends:90] (0.000) SELECT "oauth2_provider_accesstoken"."id", "oauth2_provider_accesstoken"."user_id", "oauth2_provider_accesstoken"."token", "oauth2_provider_accesstoken"."application_id", "oauth2_provider_accesstoken"."expires", "oauth2_provider_accesstoken"."scope", "auths_user"."password", "auths_user"."last_login", "auths_user"."is_superuser", "auths_user"."username", "auths_user"."first_name", "auths_user"."last_name", "auths_user"."email", "auths_user"."is_staff", "auths_user"."is_active", "auths_user"."date_joined", "auths_user"."id", "auths_user"."last_hierarchy_id", "auths_user"."last_module_id", "auths_user"."person_id", "auths_user"."updated_at", "auths_user"."registered_by", "oauth2_provider_application"."id", "oauth2_provider_application"."client_id", "oauth2_provider_application"."user_id", "oauth2_provider_application"."redirect_uris", "oauth2_provider_application"."client_type", "oauth2_provider_application"."authorization_grant_type", "oauth2_provider_application"."client_secret", "oauth2_provider_application"."name", "oauth2_provider_application"."skip_authorization" FROM "oauth2_provider_accesstoken" LEFT OUTER JOIN "auths_user" ON ("oauth2_provider_accesstoken"."user_id" = "auths_user"."id") INNER JOIN "oauth2_provider_application" ON ("oauth2_provider_accesstoken"."application_id" = "oauth2_provider_application"."id") WHERE "oauth2_provider_accesstoken"."token" = '32Lj56wsSfJHc637Qhh2vAfFGUMkz0'; args=('32Lj56wsSfJHc637Qhh2vAfFGUMkz0',)
[2016-11-30 19:02:02] DEBUG [django.db.backends:90] (0.000) SELECT "auth_group"."id", "auth_group"."name" FROM "auth_group" INNER JOIN "auths_user_groups" ON ("auth_group"."id" = "auths_user_groups"."group_id") WHERE "auths_user_groups"."user_id" = 'c0984be488184a5aafe26a71cd216420'; args=('c0984be488184a5aafe26a71cd216420',)
[2016-11-30 19:02:02] DEBUG [django.db.backends:90] (0.001) SELECT "auth_permission"."id", "auth_permission"."name", "auth_permission"."content_type_id", "auth_permission"."codename" FROM "auth_permission" INNER JOIN "auths_user_user_permissions" ON ("auth_permission"."id" = "auths_user_user_permissions"."permission_id") INNER JOIN "django_content_type" ON ("auth_permission"."content_type_id" = "django_content_type"."id") WHERE "auths_user_user_permissions"."user_id" = 'c0984be488184a5aafe26a71cd216420' ORDER BY "django_content_type"."app_label" ASC, "django_content_type"."model" ASC, "auth_permission"."codename" ASC; args=('c0984be488184a5aafe26a71cd216420',)
[2016-11-30 19:02:02] INFO [django.server:131] "GET /api/auths/localuserinfo/ HTTP/1.1" 200 403
[2016-11-30 19:02:02] INFO [django.server:131] "OPTIONS /api/auths/usermenu/ HTTP/1.1" 200 0
[2016-11-30 19:02:02] DEBUG [django.db.backends:90] (0.001) SELECT "oauth2_provider_accesstoken"."id", "oauth2_provider_accesstoken"."user_id", "oauth2_provider_accesstoken"."token", "oauth2_provider_accesstoken"."application_id", "oauth2_provider_accesstoken"."expires", "oauth2_provider_accesstoken"."scope", "auths_user"."password", "auths_user"."last_login", "auths_user"."is_superuser", "auths_user"."username", "auths_user"."first_name", "auths_user"."last_name", "auths_user"."email", "auths_user"."is_staff", "auths_user"."is_active", "auths_user"."date_joined", "auths_user"."id", "auths_user"."last_hierarchy_id", "auths_user"."last_module_id", "auths_user"."person_id", "auths_user"."updated_at", "auths_user"."registered_by", "oauth2_provider_application"."id", "oauth2_provider_application"."client_id", "oauth2_provider_application"."user_id", "oauth2_provider_application"."redirect_uris", "oauth2_provider_application"."client_type", "oauth2_provider_application"."authorization_grant_type", "oauth2_provider_application"."client_secret", "oauth2_provider_application"."name", "oauth2_provider_application"."skip_authorization" FROM "oauth2_provider_accesstoken" LEFT OUTER JOIN "auths_user" ON ("oauth2_provider_accesstoken"."user_id" = "auths_user"."id") INNER JOIN "oauth2_provider_application" ON ("oauth2_provider_accesstoken"."application_id" = "oauth2_provider_application"."id") WHERE "oauth2_provider_accesstoken"."token" = '32Lj56wsSfJHc637Qhh2vAfFGUMkz0'; args=('32Lj56wsSfJHc637Qhh2vAfFGUMkz0',)
[2016-11-30 19:02:02] DEBUG [django.db.backends:90] (0.000) SELECT "oauth2_provider_accesstoken"."id", "oauth2_provider_accesstoken"."user_id", "oauth2_provider_accesstoken"."token", "oauth2_provider_accesstoken"."application_id", "oauth2_provider_accesstoken"."expires", "oauth2_provider_accesstoken"."scope", "auths_user"."password", "auths_user"."last_login", "auths_user"."is_superuser", "auths_user"."username", "auths_user"."first_name", "auths_user"."last_name", "auths_user"."email", "auths_user"."is_staff", "auths_user"."is_active", "auths_user"."date_joined", "auths_user"."id", "auths_user"."last_hierarchy_id", "auths_user"."last_module_id", "auths_user"."person_id", "auths_user"."updated_at", "auths_user"."registered_by", "oauth2_provider_application"."id", "oauth2_provider_application"."client_id", "oauth2_provider_application"."user_id", "oauth2_provider_application"."redirect_uris", "oauth2_provider_application"."client_type", "oauth2_provider_application"."authorization_grant_type", "oauth2_provider_application"."client_secret", "oauth2_provider_application"."name", "oauth2_provider_application"."skip_authorization" FROM "oauth2_provider_accesstoken" LEFT OUTER JOIN "auths_user" ON ("oauth2_provider_accesstoken"."user_id" = "auths_user"."id") INNER JOIN "oauth2_provider_application" ON ("oauth2_provider_accesstoken"."application_id" = "oauth2_provider_application"."id") WHERE "oauth2_provider_accesstoken"."token" = '32Lj56wsSfJHc637Qhh2vAfFGUMkz0'; args=('32Lj56wsSfJHc637Qhh2vAfFGUMkz0',)
[2016-11-30 19:02:02] DEBUG [django.db.backends:90] (0.000) SELECT "auths_menu"."id" FROM "auths_menu" WHERE ("auths_menu"."id" IS NOT NULL AND "auths_menu"."is_active" = 1 AND "auths_menu"."module" = 'BACKEND') ORDER BY "auths_menu"."pos" ASC; args=(True, 'BACKEND')
[2016-11-30 19:02:02] DEBUG [django.db.backends:90] (0.000) SELECT (1) AS "a" FROM "django_session" WHERE "django_session"."session_key" = 'rghip6bf5nubjqyv52hzject45wt2631' LIMIT 1; args=('rghip6bf5nubjqyv52hzject45wt2631',)
[2016-11-30 19:02:02] DEBUG [django.db.backends:90] (0.000) BEGIN; args=None
[2016-11-30 19:02:02] DEBUG [django.db.backends:90] (0.022) INSERT INTO "django_session" ("session_key", "session_data", "expire_date") SELECT 'rghip6bf5nubjqyv52hzject45wt2631', 'ODY1NjFiZTY0MzBmM2M0MGUwMDNhZGY4YmJlNjRmMzUzYmRiN2M3Nzp7Il9zZXNzaW9uX2V4cGlyeSI6MzB9', '2016-12-01 00:02:32.510899'; args=('rghip6bf5nubjqyv52hzject45wt2631', 'ODY1NjFiZTY0MzBmM2M0MGUwMDNhZGY4YmJlNjRmMzUzYmRiN2M3Nzp7Il9zZXNzaW9uX2V4cGlyeSI6MzB9', '2016-12-01 00:02:32.510899')
[2016-11-30 19:02:02] INFO [django.server:131] "GET /api/auths/usermenu/ HTTP/1.1" 200 11
[2016-11-30 19:02:06] DEBUG [django.db.backends:90] (0.002) SELECT "auths_user"."password", "auths_user"."last_login", "auths_user"."is_superuser", "auths_user"."username", "auths_user"."first_name", "auths_user"."last_name", "auths_user"."email", "auths_user"."is_staff", "auths_user"."is_active", "auths_user"."date_joined", "auths_user"."id", "auths_user"."last_hierarchy_id", "auths_user"."last_module_id", "auths_user"."person_id", "auths_user"."updated_at", "auths_user"."registered_by" FROM "auths_user" WHERE "auths_user"."username" = 'ken'; args=('ken',)
[2016-11-30 19:02:06] DEBUG [django.db.backends:90] (0.000) SELECT (1) AS "a" FROM "django_session" WHERE "django_session"."session_key" = 'tpy3pp0aw1c6raj73fk8ocl5971hqej5' LIMIT 1; args=('tpy3pp0aw1c6raj73fk8ocl5971hqej5',)
[2016-11-30 19:02:06] DEBUG [django.db.backends:90] (0.000) BEGIN; args=None
[2016-11-30 19:02:06] DEBUG [django.db.backends:90] (0.001) INSERT INTO "django_session" ("session_key", "session_data", "expire_date") SELECT 'tpy3pp0aw1c6raj73fk8ocl5971hqej5', 'YjQyNjUzMGM0ZTg1NjNmMDFhZTFiNGZkZmExODhjNWE3MTg2YmQ5Zjp7fQ==', '2016-12-15 00:02:06.271047'; args=('tpy3pp0aw1c6raj73fk8ocl5971hqej5', 'YjQyNjUzMGM0ZTg1NjNmMDFhZTFiNGZkZmExODhjNWE3MTg2YmQ5Zjp7fQ==', '2016-12-15 00:02:06.271047')
[2016-11-30 19:02:06] DEBUG [django.db.backends:90] (0.000) BEGIN; args=None
[2016-11-30 19:02:06] DEBUG [django.db.backends:90] (0.001) UPDATE "auths_user" SET "last_login" = '2016-12-01 00:02:06.530913' WHERE "auths_user"."id" = 'c0984be488184a5aafe26a71cd216420'; args=('2016-12-01 00:02:06.530913', 'c0984be488184a5aafe26a71cd216420')
[2016-11-30 19:02:06] DEBUG [django.db.backends:90] (0.000) BEGIN; args=None
[2016-11-30 19:02:06] DEBUG [django.db.backends:90] (0.000) UPDATE "django_session" SET "session_data" = 'ZjkyMWI4MDEwMTYwMDZiMGU4M2Q4OTUxZDNjZjNmNjU3N2JkMjAwZDp7Il9hdXRoX3VzZXJfaGFzaCI6Ijc3NDBhNzNiMWE0ZWM1ZmViNTQ3M2Q3YjQxODcwNzJmYzgzNDgwMGYiLCJfYXV0aF91c2VyX2JhY2tlbmQiOiJkamFuZ28uY29udHJpYi5hdXRoLmJhY2tlbmRzLk1vZGVsQmFja2VuZCIsIl9hdXRoX3VzZXJfaWQiOiJjMDk4NGJlNC04ODE4LTRhNWEtYWZlMi02YTcxY2QyMTY0MjAifQ==', "expire_date" = '2016-12-15 00:02:06.763587' WHERE "django_session"."session_key" = 'tpy3pp0aw1c6raj73fk8ocl5971hqej5'; args=('ZjkyMWI4MDEwMTYwMDZiMGU4M2Q4OTUxZDNjZjNmNjU3N2JkMjAwZDp7Il9hdXRoX3VzZXJfaGFzaCI6Ijc3NDBhNzNiMWE0ZWM1ZmViNTQ3M2Q3YjQxODcwNzJmYzgzNDgwMGYiLCJfYXV0aF91c2VyX2JhY2tlbmQiOiJkamFuZ28uY29udHJpYi5hdXRoLmJhY2tlbmRzLk1vZGVsQmFja2VuZCIsIl9hdXRoX3VzZXJfaWQiOiJjMDk4NGJlNC04ODE4LTRhNWEtYWZlMi02YTcxY2QyMTY0MjAifQ==', '2016-12-15 00:02:06.763587', 'tpy3pp0aw1c6raj73fk8ocl5971hqej5')
[2016-11-30 19:02:06] INFO [django.server:131] "POST /admin/login/?next=/admin/ HTTP/1.1" 302 0
[2016-11-30 19:02:06] DEBUG [django.db.backends:90] (0.002) SELECT "django_session"."session_key", "django_session"."session_data", "django_session"."expire_date" FROM "django_session" WHERE ("django_session"."expire_date" > '2016-12-01 00:02:06.871664' AND "django_session"."session_key" = 'tpy3pp0aw1c6raj73fk8ocl5971hqej5'); args=('2016-12-01 00:02:06.871664', 'tpy3pp0aw1c6raj73fk8ocl5971hqej5')
[2016-11-30 19:02:06] DEBUG [django.db.backends:90] (0.001) SELECT "auths_user"."password", "auths_user"."last_login", "auths_user"."is_superuser", "auths_user"."username", "auths_user"."first_name", "auths_user"."last_name", "auths_user"."email", "auths_user"."is_staff", "auths_user"."is_active", "auths_user"."date_joined", "auths_user"."id", "auths_user"."last_hierarchy_id", "auths_user"."last_module_id", "auths_user"."person_id", "auths_user"."updated_at", "auths_user"."registered_by" FROM "auths_user" WHERE "auths_user"."id" = 'c0984be488184a5aafe26a71cd216420'; args=('c0984be488184a5aafe26a71cd216420',)
[2016-11-30 19:02:07] DEBUG [django.template:929] Exception while resolving variable 'is_popup' in template 'admin/index.html'.
Traceback (most recent call last):
  File "D:\Codigos\LP2\end\redcashier\ve_redcashier\lib\site-packages\django\template\base.py", line 885, in _resolve_lookup
    current = current[bit]
  File "D:\Codigos\LP2\end\redcashier\ve_redcashier\lib\site-packages\django\template\context.py", line 75, in __getitem__
    raise KeyError(key)
KeyError: 'is_popup'

During handling of the above exception, another exception occurred:

Traceback (most recent call last):
  File "D:\Codigos\LP2\end\redcashier\ve_redcashier\lib\site-packages\django\template\base.py", line 891, in _resolve_lookup
    if isinstance(current, BaseContext) and getattr(type(current), bit):
AttributeError: type object 'RequestContext' has no attribute 'is_popup'

During handling of the above exception, another exception occurred:

Traceback (most recent call last):
  File "D:\Codigos\LP2\end\redcashier\ve_redcashier\lib\site-packages\django\template\base.py", line 900, in _resolve_lookup
    current = current[int(bit)]
ValueError: invalid literal for int() with base 10: 'is_popup'

During handling of the above exception, another exception occurred:

Traceback (most recent call last):
  File "D:\Codigos\LP2\end\redcashier\ve_redcashier\lib\site-packages\django\template\base.py", line 907, in _resolve_lookup
    (bit, current))  # missing attribute
django.template.base.VariableDoesNotExist: Failed lookup for key [is_popup] in "[{'False': False, 'None': None, 'True': True}, {'messages': <django.contrib.messages.storage.fallback.FallbackStorage object at 0x04596C70>, 'user': <SimpleLazyObject: <User: ken>>, 'csrf_token': <SimpleLazyObject: <function csrf.<locals>._get_val at 0x04314D20>>, 'request': <WSGIRequest: GET '/admin/'>, 'perms': <django.contrib.auth.context_processors.PermWrapper object at 0x04656690>, 'DEFAULT_MESSAGE_LEVELS': {'WARNING': 30, 'DEBUG': 10, 'INFO': 20, 'SUCCESS': 25, 'ERROR': 40}}, {}, {'LANGUAGE_CODE': 'en-us', 'site_url': '/', 'site_title': <django.utils.functional.lazy.<locals>.__proxy__ object at 0x03574BF0>, 'has_permission': True, 'available_apps': [{'name': <django.utils.functional.lazy.<locals>.__proxy__ object at 0x035856F0>, 'app_url': '/admin/auth/', 'models': [{'name': <django.utils.functional.lazy.<locals>.__proxy__ object at 0x0459C650>, 'add_url': '/admin/auth/group/add/', 'object_name': 'Group', 'perms': {'delete': True, 'change': True, 'add': True}, 'admin_url': '/admin/auth/group/'}, {'name': <django.utils.functional.lazy.<locals>.__proxy__ object at 0x045D9170>, 'add_url': '/admin/auth/permission/add/', 'object_name': 'Permission', 'perms': {'delete': True, 'change': True, 'add': True}, 'admin_url': '/admin/auth/permission/'}], 'has_module_perms': True, 'app_label': 'auth'}, {'name': 'Auths', 'app_url': '/admin/auths/', 'models': [{'name': <django.utils.functional.lazy.<locals>.__proxy__ object at 0x045D9970>, 'add_url': '/admin/auths/hierarchytype/add/', 'object_name': 'HierarchyType', 'perms': {'delete': True, 'change': True, 'add': True}, 'admin_url': '/admin/auths/hierarchytype/'}, {'name': <django.utils.functional.lazy.<locals>.__proxy__ object at 0x045D9910>, 'add_url': '/admin/auths/hierarchy/add/', 'object_name': 'Hierarchy', 'perms': {'delete': True, 'change': True, 'add': True}, 'admin_url': '/admin/auths/hierarchy/'}, {'name': <django.utils.functional.lazy.<locals>.__proxy__ object at 0x045D93F0>, 'add_url': '/admin/auths/menu/add/', 'object_name': 'Menu', 'perms': {'delete': True, 'change': True, 'add': True}, 'admin_url': '/admin/auths/menu/'}, {'name': <django.utils.functional.lazy.<locals>.__proxy__ object at 0x045D93B0>, 'add_url': '/admin/auths/person/add/', 'object_name': 'Person', 'perms': {'delete': True, 'change': True, 'add': True}, 'admin_url': '/admin/auths/person/'}, {'name': <django.utils.functional.lazy.<locals>.__proxy__ object at 0x045D9AF0>, 'add_url': '/admin/auths/userhierarchygroup/add/', 'object_name': 'UserHierarchyGroup', 'perms': {'delete': True, 'change': True, 'add': True}, 'admin_url': '/admin/auths/userhierarchygroup/'}, {'name': <django.utils.functional.lazy.<locals>.__proxy__ object at 0x045D9610>, 'add_url': '/admin/auths/userhierarchypermission/add/', 'object_name': 'UserHierarchyPermission', 'perms': {'delete': True, 'change': True, 'add': True}, 'admin_url': '/admin/auths/userhierarchypermission/'}, {'name': <django.utils.functional.lazy.<locals>.__proxy__ object at 0x045D9EB0>, 'add_url': '/admin/auths/user/add/', 'object_name': 'User', 'perms': {'delete': True, 'change': True, 'add': True}, 'admin_url': '/admin/auths/user/'}], 'has_module_perms': True, 'app_label': 'auths'}, {'name': 'Caja', 'app_url': '/admin/caja/', 'models': [{'name': 'Boletas', 'add_url': '/admin/caja/boleta/add/', 'object_name': 'Boleta', 'perms': {'delete': True, 'change': True, 'add': True}, 'admin_url': '/admin/caja/boleta/'}, {'name': 'Cajaingresos', 'add_url': '/admin/caja/cajaingreso/add/', 'object_name': 'Cajaingreso', 'perms': {'delete': True, 'change': True, 'add': True}, 'admin_url': '/admin/caja/cajaingreso/'}, {'name': 'Clientes', 'add_url': '/admin/caja/cliente/add/', 'object_name': 'Cliente', 'perms': {'delete': True, 'change': True, 'add': True}, 'admin_url': '/admin/caja/cliente/'}, {'name': 'Modcontables', 'add_url': '/admin/caja/modcontable/add/', 'object_name': 'Modcontable', 'perms': {'delete': True, 'change': True, 'add': True}, 'admin_url': '/admin/caja/modcontable/'}, {'name': 'Niveles', 'add_url': '/admin/caja/nivel/add/', 'object_name': 'Nivel', 'perms': {'delete': True, 'change': True, 'add': True}, 'admin_url': '/admin/caja/nivel/'}, {'name': 'PeriodoContables', 'add_url': '/admin/caja/periodocontable/add/', 'object_name': 'PeriodoContable', 'perms': {'delete': True, 'change': True, 'add': True}, 'admin_url': '/admin/caja/periodocontable/'}, {'name': 'Usercashiers', 'add_url': '/admin/caja/usercashier/add/', 'object_name': 'Usercashier', 'perms': {'delete': True, 'change': True, 'add': True}, 'admin_url': '/admin/caja/usercashier/'}], 'has_module_perms': True, 'app_label': 'caja'}, {'name': 'Catalogo', 'app_url': '/admin/catalogo/', 'models': [{'name': 'Autores', 'add_url': '/admin/catalogo/autor/add/', 'object_name': 'Autor', 'perms': {'delete': True, 'change': True, 'add': True}, 'admin_url': '/admin/catalogo/autor/'}, {'name': 'Categorias', 'add_url': '/admin/catalogo/categoria/add/', 'object_name': 'Categoria', 'perms': {'delete': True, 'change': True, 'add': True}, 'admin_url': '/admin/catalogo/categoria/'}, {'name': 'Libros', 'add_url': '/admin/catalogo/libro/add/', 'object_name': 'Libro', 'perms': {'delete': True, 'change': True, 'add': True}, 'admin_url': '/admin/catalogo/libro/'}], 'has_module_perms': True, 'app_label': 'catalogo'}, {'name': <django.utils.functional.lazy.<locals>.__proxy__ object at 0x03585810>, 'app_url': '/admin/contenttypes/', 'models': [{'name': <django.utils.functional.lazy.<locals>.__proxy__ object at 0x0459C330>, 'add_url': '/admin/contenttypes/contenttype/add/', 'object_name': 'ContentType', 'perms': {'delete': True, 'change': True, 'add': True}, 'admin_url': '/admin/contenttypes/contenttype/'}], 'has_module_perms': True, 'app_label': 'contenttypes'}, {'name': 'Django OAuth Toolkit', 'app_url': '/admin/oauth2_provider/', 'models': [{'name': <django.utils.functional.lazy.<locals>.__proxy__ object at 0x045D9ED0>, 'add_url': '/admin/oauth2_provider/accesstoken/add/', 'object_name': 'AccessToken', 'perms': {'delete': True, 'change': True, 'add': True}, 'admin_url': '/admin/oauth2_provider/accesstoken/'}, {'name': <django.utils.functional.lazy.<locals>.__proxy__ object at 0x045D9EF0>, 'add_url': '/admin/oauth2_provider/application/add/', 'object_name': 'Application', 'perms': {'delete': True, 'change': True, 'add': True}, 'admin_url': '/admin/oauth2_provider/application/'}, {'name': <django.utils.functional.lazy.<locals>.__proxy__ object at 0x045D91F0>, 'add_url': '/admin/oauth2_provider/grant/add/', 'object_name': 'Grant', 'perms': {'delete': True, 'change': True, 'add': True}, 'admin_url': '/admin/oauth2_provider/grant/'}, {'name': <django.utils.functional.lazy.<locals>.__proxy__ object at 0x045D9370>, 'add_url': '/admin/oauth2_provider/refreshtoken/add/', 'object_name': 'RefreshToken', 'perms': {'delete': True, 'change': True, 'add': True}, 'admin_url': '/admin/oauth2_provider/refreshtoken/'}], 'has_module_perms': True, 'app_label': 'oauth2_provider'}], 'LANGUAGE_BIDI': False, 'site_header': <django.utils.functional.lazy.<locals>.__proxy__ object at 0x03574C50>, 'title': <django.utils.functional.lazy.<locals>.__proxy__ object at 0x03574CB0>, 'app_list': [{'name': <django.utils.functional.lazy.<locals>.__proxy__ object at 0x035856F0>, 'app_url': '/admin/auth/', 'models': [{'name': <django.utils.functional.lazy.<locals>.__proxy__ object at 0x04596050>, 'add_url': '/admin/auth/group/add/', 'object_name': 'Group', 'perms': {'delete': True, 'change': True, 'add': True}, 'admin_url': '/admin/auth/group/'}, {'name': <django.utils.functional.lazy.<locals>.__proxy__ object at 0x0459C9D0>, 'add_url': '/admin/auth/permission/add/', 'object_name': 'Permission', 'perms': {'delete': True, 'change': True, 'add': True}, 'admin_url': '/admin/auth/permission/'}], 'has_module_perms': True, 'app_label': 'auth'}, {'name': 'Auths', 'app_url': '/admin/auths/', 'models': [{'name': <django.utils.functional.lazy.<locals>.__proxy__ object at 0x0459CAB0>, 'add_url': '/admin/auths/hierarchytype/add/', 'object_name': 'HierarchyType', 'perms': {'delete': True, 'change': True, 'add': True}, 'admin_url': '/admin/auths/hierarchytype/'}, {'name': <django.utils.functional.lazy.<locals>.__proxy__ object at 0x045F66D0>, 'add_url': '/admin/auths/hierarchy/add/', 'object_name': 'Hierarchy', 'perms': {'delete': True, 'change': True, 'add': True}, 'admin_url': '/admin/auths/hierarchy/'}, {'name': <django.utils.functional.lazy.<locals>.__proxy__ object at 0x0459CC70>, 'add_url': '/admin/auths/menu/add/', 'object_name': 'Menu', 'perms': {'delete': True, 'change': True, 'add': True}, 'admin_url': '/admin/auths/menu/'}, {'name': <django.utils.functional.lazy.<locals>.__proxy__ object at 0x0459C7F0>, 'add_url': '/admin/auths/person/add/', 'object_name': 'Person', 'perms': {'delete': True, 'change': True, 'add': True}, 'admin_url': '/admin/auths/person/'}, {'name': <django.utils.functional.lazy.<locals>.__proxy__ object at 0x0459C5D0>, 'add_url': '/admin/auths/userhierarchygroup/add/', 'object_name': 'UserHierarchyGroup', 'perms': {'delete': True, 'change': True, 'add': True}, 'admin_url': '/admin/auths/userhierarchygroup/'}, {'name': <django.utils.functional.lazy.<locals>.__proxy__ object at 0x0459CA90>, 'add_url': '/admin/auths/userhierarchypermission/add/', 'object_name': 'UserHierarchyPermission', 'perms': {'delete': True, 'change': True, 'add': True}, 'admin_url': '/admin/auths/userhierarchypermission/'}, {'name': <django.utils.functional.lazy.<locals>.__proxy__ object at 0x045F64D0>, 'add_url': '/admin/auths/user/add/', 'object_name': 'User', 'perms': {'delete': True, 'change': True, 'add': True}, 'admin_url': '/admin/auths/user/'}], 'has_module_perms': True, 'app_label': 'auths'}, {'name': 'Caja', 'app_url': '/admin/caja/', 'models': [{'name': 'Boletas', 'add_url': '/admin/caja/boleta/add/', 'object_name': 'Boleta', 'perms': {'delete': True, 'change': True, 'add': True}, 'admin_url': '/admin/caja/boleta/'}, {'name': 'Cajaingresos', 'add_url': '/admin/caja/cajaingreso/add/', 'object_name': 'Cajaingreso', 'perms': {'delete': True, 'change': True, 'add': True}, 'admin_url': '/admin/caja/cajaingreso/'}, {'name': 'Clientes', 'add_url': '/admin/caja/cliente/add/', 'object_name': 'Cliente', 'perms': {'delete': True, 'change': True, 'add': True}, 'admin_url': '/admin/caja/cliente/'}, {'name': 'Modcontables', 'add_url': '/admin/caja/modcontable/add/', 'object_name': 'Modcontable', 'perms': {'delete': True, 'change': True, 'add': True}, 'admin_url': '/admin/caja/modcontable/'}, {'name': 'Niveles', 'add_url': '/admin/caja/nivel/add/', 'object_name': 'Nivel', 'perms': {'delete': True, 'change': True, 'add': True}, 'admin_url': '/admin/caja/nivel/'}, {'name': 'PeriodoContables', 'add_url': '/admin/caja/periodocontable/add/', 'object_name': 'PeriodoContable', 'perms': {'delete': True, 'change': True, 'add': True}, 'admin_url': '/admin/caja/periodocontable/'}, {'name': 'Usercashiers', 'add_url': '/admin/caja/usercashier/add/', 'object_name': 'Usercashier', 'perms': {'delete': True, 'change': True, 'add': True}, 'admin_url': '/admin/caja/usercashier/'}], 'has_module_perms': True, 'app_label': 'caja'}, {'name': 'Catalogo', 'app_url': '/admin/catalogo/', 'models': [{'name': 'Autores', 'add_url': '/admin/catalogo/autor/add/', 'object_name': 'Autor', 'perms': {'delete': True, 'change': True, 'add': True}, 'admin_url': '/admin/catalogo/autor/'}, {'name': 'Categorias', 'add_url': '/admin/catalogo/categoria/add/', 'object_name': 'Categoria', 'perms': {'delete': True, 'change': True, 'add': True}, 'admin_url': '/admin/catalogo/categoria/'}, {'name': 'Libros', 'add_url': '/admin/catalogo/libro/add/', 'object_name': 'Libro', 'perms': {'delete': True, 'change': True, 'add': True}, 'admin_url': '/admin/catalogo/libro/'}], 'has_module_perms': True, 'app_label': 'catalogo'}, {'name': <django.utils.functional.lazy.<locals>.__proxy__ object at 0x03585810>, 'app_url': '/admin/contenttypes/', 'models': [{'name': <django.utils.functional.lazy.<locals>.__proxy__ object at 0x04596710>, 'add_url': '/admin/contenttypes/contenttype/add/', 'object_name': 'ContentType', 'perms': {'delete': True, 'change': True, 'add': True}, 'admin_url': '/admin/contenttypes/contenttype/'}], 'has_module_perms': True, 'app_label': 'contenttypes'}, {'name': 'Django OAuth Toolkit', 'app_url': '/admin/oauth2_provider/', 'models': [{'name': <django.utils.functional.lazy.<locals>.__proxy__ object at 0x045F66B0>, 'add_url': '/admin/oauth2_provider/accesstoken/add/', 'object_name': 'AccessToken', 'perms': {'delete': True, 'change': True, 'add': True}, 'admin_url': '/admin/oauth2_provider/accesstoken/'}, {'name': <django.utils.functional.lazy.<locals>.__proxy__ object at 0x0459CA30>, 'add_url': '/admin/oauth2_provider/application/add/', 'object_name': 'Application', 'perms': {'delete': True, 'change': True, 'add': True}, 'admin_url': '/admin/oauth2_provider/application/'}, {'name': <django.utils.functional.lazy.<locals>.__proxy__ object at 0x045F6670>, 'add_url': '/admin/oauth2_provider/grant/add/', 'object_name': 'Grant', 'perms': {'delete': True, 'change': True, 'add': True}, 'admin_url': '/admin/oauth2_provider/grant/'}, {'name': <django.utils.functional.lazy.<locals>.__proxy__ object at 0x0459CBF0>, 'add_url': '/admin/oauth2_provider/refreshtoken/add/', 'object_name': 'RefreshToken', 'perms': {'delete': True, 'change': True, 'add': True}, 'admin_url': '/admin/oauth2_provider/refreshtoken/'}], 'has_module_perms': True, 'app_label': 'oauth2_provider'}]}]"
[2016-11-30 19:02:07] DEBUG [django.template:929] Exception while resolving variable 'is_popup' in template 'admin/index.html'.
Traceback (most recent call last):
  File "D:\Codigos\LP2\end\redcashier\ve_redcashier\lib\site-packages\django\template\base.py", line 885, in _resolve_lookup
    current = current[bit]
  File "D:\Codigos\LP2\end\redcashier\ve_redcashier\lib\site-packages\django\template\context.py", line 75, in __getitem__
    raise KeyError(key)
KeyError: 'is_popup'

During handling of the above exception, another exception occurred:

Traceback (most recent call last):
  File "D:\Codigos\LP2\end\redcashier\ve_redcashier\lib\site-packages\django\template\base.py", line 891, in _resolve_lookup
    if isinstance(current, BaseContext) and getattr(type(current), bit):
AttributeError: type object 'RequestContext' has no attribute 'is_popup'

During handling of the above exception, another exception occurred:

Traceback (most recent call last):
  File "D:\Codigos\LP2\end\redcashier\ve_redcashier\lib\site-packages\django\template\base.py", line 900, in _resolve_lookup
    current = current[int(bit)]
ValueError: invalid literal for int() with base 10: 'is_popup'

During handling of the above exception, another exception occurred:

Traceback (most recent call last):
  File "D:\Codigos\LP2\end\redcashier\ve_redcashier\lib\site-packages\django\template\base.py", line 907, in _resolve_lookup
    (bit, current))  # missing attribute
django.template.base.VariableDoesNotExist: Failed lookup for key [is_popup] in "[{'False': False, 'None': None, 'True': True}, {'messages': <django.contrib.messages.storage.fallback.FallbackStorage object at 0x04596C70>, 'user': <SimpleLazyObject: <User: ken>>, 'csrf_token': <SimpleLazyObject: <function csrf.<locals>._get_val at 0x04314D20>>, 'request': <WSGIRequest: GET '/admin/'>, 'perms': <django.contrib.auth.context_processors.PermWrapper object at 0x04656690>, 'DEFAULT_MESSAGE_LEVELS': {'WARNING': 30, 'DEBUG': 10, 'INFO': 20, 'SUCCESS': 25, 'ERROR': 40}}, {}, {'LANGUAGE_CODE': 'en-us', 'site_url': '/', 'site_title': <django.utils.functional.lazy.<locals>.__proxy__ object at 0x03574BF0>, 'has_permission': True, 'available_apps': [{'name': <django.utils.functional.lazy.<locals>.__proxy__ object at 0x035856F0>, 'app_url': '/admin/auth/', 'models': [{'name': <django.utils.functional.lazy.<locals>.__proxy__ object at 0x0459C650>, 'add_url': '/admin/auth/group/add/', 'object_name': 'Group', 'perms': {'delete': True, 'change': True, 'add': True}, 'admin_url': '/admin/auth/group/'}, {'name': <django.utils.functional.lazy.<locals>.__proxy__ object at 0x045D9170>, 'add_url': '/admin/auth/permission/add/', 'object_name': 'Permission', 'perms': {'delete': True, 'change': True, 'add': True}, 'admin_url': '/admin/auth/permission/'}], 'has_module_perms': True, 'app_label': 'auth'}, {'name': 'Auths', 'app_url': '/admin/auths/', 'models': [{'name': <django.utils.functional.lazy.<locals>.__proxy__ object at 0x045D9970>, 'add_url': '/admin/auths/hierarchytype/add/', 'object_name': 'HierarchyType', 'perms': {'delete': True, 'change': True, 'add': True}, 'admin_url': '/admin/auths/hierarchytype/'}, {'name': <django.utils.functional.lazy.<locals>.__proxy__ object at 0x045D9910>, 'add_url': '/admin/auths/hierarchy/add/', 'object_name': 'Hierarchy', 'perms': {'delete': True, 'change': True, 'add': True}, 'admin_url': '/admin/auths/hierarchy/'}, {'name': <django.utils.functional.lazy.<locals>.__proxy__ object at 0x045D93F0>, 'add_url': '/admin/auths/menu/add/', 'object_name': 'Menu', 'perms': {'delete': True, 'change': True, 'add': True}, 'admin_url': '/admin/auths/menu/'}, {'name': <django.utils.functional.lazy.<locals>.__proxy__ object at 0x045D93B0>, 'add_url': '/admin/auths/person/add/', 'object_name': 'Person', 'perms': {'delete': True, 'change': True, 'add': True}, 'admin_url': '/admin/auths/person/'}, {'name': <django.utils.functional.lazy.<locals>.__proxy__ object at 0x045D9AF0>, 'add_url': '/admin/auths/userhierarchygroup/add/', 'object_name': 'UserHierarchyGroup', 'perms': {'delete': True, 'change': True, 'add': True}, 'admin_url': '/admin/auths/userhierarchygroup/'}, {'name': <django.utils.functional.lazy.<locals>.__proxy__ object at 0x045D9610>, 'add_url': '/admin/auths/userhierarchypermission/add/', 'object_name': 'UserHierarchyPermission', 'perms': {'delete': True, 'change': True, 'add': True}, 'admin_url': '/admin/auths/userhierarchypermission/'}, {'name': <django.utils.functional.lazy.<locals>.__proxy__ object at 0x045D9EB0>, 'add_url': '/admin/auths/user/add/', 'object_name': 'User', 'perms': {'delete': True, 'change': True, 'add': True}, 'admin_url': '/admin/auths/user/'}], 'has_module_perms': True, 'app_label': 'auths'}, {'name': 'Caja', 'app_url': '/admin/caja/', 'models': [{'name': 'Boletas', 'add_url': '/admin/caja/boleta/add/', 'object_name': 'Boleta', 'perms': {'delete': True, 'change': True, 'add': True}, 'admin_url': '/admin/caja/boleta/'}, {'name': 'Cajaingresos', 'add_url': '/admin/caja/cajaingreso/add/', 'object_name': 'Cajaingreso', 'perms': {'delete': True, 'change': True, 'add': True}, 'admin_url': '/admin/caja/cajaingreso/'}, {'name': 'Clientes', 'add_url': '/admin/caja/cliente/add/', 'object_name': 'Cliente', 'perms': {'delete': True, 'change': True, 'add': True}, 'admin_url': '/admin/caja/cliente/'}, {'name': 'Modcontables', 'add_url': '/admin/caja/modcontable/add/', 'object_name': 'Modcontable', 'perms': {'delete': True, 'change': True, 'add': True}, 'admin_url': '/admin/caja/modcontable/'}, {'name': 'Niveles', 'add_url': '/admin/caja/nivel/add/', 'object_name': 'Nivel', 'perms': {'delete': True, 'change': True, 'add': True}, 'admin_url': '/admin/caja/nivel/'}, {'name': 'PeriodoContables', 'add_url': '/admin/caja/periodocontable/add/', 'object_name': 'PeriodoContable', 'perms': {'delete': True, 'change': True, 'add': True}, 'admin_url': '/admin/caja/periodocontable/'}, {'name': 'Usercashiers', 'add_url': '/admin/caja/usercashier/add/', 'object_name': 'Usercashier', 'perms': {'delete': True, 'change': True, 'add': True}, 'admin_url': '/admin/caja/usercashier/'}], 'has_module_perms': True, 'app_label': 'caja'}, {'name': 'Catalogo', 'app_url': '/admin/catalogo/', 'models': [{'name': 'Autores', 'add_url': '/admin/catalogo/autor/add/', 'object_name': 'Autor', 'perms': {'delete': True, 'change': True, 'add': True}, 'admin_url': '/admin/catalogo/autor/'}, {'name': 'Categorias', 'add_url': '/admin/catalogo/categoria/add/', 'object_name': 'Categoria', 'perms': {'delete': True, 'change': True, 'add': True}, 'admin_url': '/admin/catalogo/categoria/'}, {'name': 'Libros', 'add_url': '/admin/catalogo/libro/add/', 'object_name': 'Libro', 'perms': {'delete': True, 'change': True, 'add': True}, 'admin_url': '/admin/catalogo/libro/'}], 'has_module_perms': True, 'app_label': 'catalogo'}, {'name': <django.utils.functional.lazy.<locals>.__proxy__ object at 0x03585810>, 'app_url': '/admin/contenttypes/', 'models': [{'name': <django.utils.functional.lazy.<locals>.__proxy__ object at 0x0459C330>, 'add_url': '/admin/contenttypes/contenttype/add/', 'object_name': 'ContentType', 'perms': {'delete': True, 'change': True, 'add': True}, 'admin_url': '/admin/contenttypes/contenttype/'}], 'has_module_perms': True, 'app_label': 'contenttypes'}, {'name': 'Django OAuth Toolkit', 'app_url': '/admin/oauth2_provider/', 'models': [{'name': <django.utils.functional.lazy.<locals>.__proxy__ object at 0x045D9ED0>, 'add_url': '/admin/oauth2_provider/accesstoken/add/', 'object_name': 'AccessToken', 'perms': {'delete': True, 'change': True, 'add': True}, 'admin_url': '/admin/oauth2_provider/accesstoken/'}, {'name': <django.utils.functional.lazy.<locals>.__proxy__ object at 0x045D9EF0>, 'add_url': '/admin/oauth2_provider/application/add/', 'object_name': 'Application', 'perms': {'delete': True, 'change': True, 'add': True}, 'admin_url': '/admin/oauth2_provider/application/'}, {'name': <django.utils.functional.lazy.<locals>.__proxy__ object at 0x045D91F0>, 'add_url': '/admin/oauth2_provider/grant/add/', 'object_name': 'Grant', 'perms': {'delete': True, 'change': True, 'add': True}, 'admin_url': '/admin/oauth2_provider/grant/'}, {'name': <django.utils.functional.lazy.<locals>.__proxy__ object at 0x045D9370>, 'add_url': '/admin/oauth2_provider/refreshtoken/add/', 'object_name': 'RefreshToken', 'perms': {'delete': True, 'change': True, 'add': True}, 'admin_url': '/admin/oauth2_provider/refreshtoken/'}], 'has_module_perms': True, 'app_label': 'oauth2_provider'}], 'LANGUAGE_BIDI': False, 'site_header': <django.utils.functional.lazy.<locals>.__proxy__ object at 0x03574C50>, 'title': <django.utils.functional.lazy.<locals>.__proxy__ object at 0x03574CB0>, 'app_list': [{'name': <django.utils.functional.lazy.<locals>.__proxy__ object at 0x035856F0>, 'app_url': '/admin/auth/', 'models': [{'name': <django.utils.functional.lazy.<locals>.__proxy__ object at 0x04596050>, 'add_url': '/admin/auth/group/add/', 'object_name': 'Group', 'perms': {'delete': True, 'change': True, 'add': True}, 'admin_url': '/admin/auth/group/'}, {'name': <django.utils.functional.lazy.<locals>.__proxy__ object at 0x0459C9D0>, 'add_url': '/admin/auth/permission/add/', 'object_name': 'Permission', 'perms': {'delete': True, 'change': True, 'add': True}, 'admin_url': '/admin/auth/permission/'}], 'has_module_perms': True, 'app_label': 'auth'}, {'name': 'Auths', 'app_url': '/admin/auths/', 'models': [{'name': <django.utils.functional.lazy.<locals>.__proxy__ object at 0x0459CAB0>, 'add_url': '/admin/auths/hierarchytype/add/', 'object_name': 'HierarchyType', 'perms': {'delete': True, 'change': True, 'add': True}, 'admin_url': '/admin/auths/hierarchytype/'}, {'name': <django.utils.functional.lazy.<locals>.__proxy__ object at 0x045F66D0>, 'add_url': '/admin/auths/hierarchy/add/', 'object_name': 'Hierarchy', 'perms': {'delete': True, 'change': True, 'add': True}, 'admin_url': '/admin/auths/hierarchy/'}, {'name': <django.utils.functional.lazy.<locals>.__proxy__ object at 0x0459CC70>, 'add_url': '/admin/auths/menu/add/', 'object_name': 'Menu', 'perms': {'delete': True, 'change': True, 'add': True}, 'admin_url': '/admin/auths/menu/'}, {'name': <django.utils.functional.lazy.<locals>.__proxy__ object at 0x0459C7F0>, 'add_url': '/admin/auths/person/add/', 'object_name': 'Person', 'perms': {'delete': True, 'change': True, 'add': True}, 'admin_url': '/admin/auths/person/'}, {'name': <django.utils.functional.lazy.<locals>.__proxy__ object at 0x0459C5D0>, 'add_url': '/admin/auths/userhierarchygroup/add/', 'object_name': 'UserHierarchyGroup', 'perms': {'delete': True, 'change': True, 'add': True}, 'admin_url': '/admin/auths/userhierarchygroup/'}, {'name': <django.utils.functional.lazy.<locals>.__proxy__ object at 0x0459CA90>, 'add_url': '/admin/auths/userhierarchypermission/add/', 'object_name': 'UserHierarchyPermission', 'perms': {'delete': True, 'change': True, 'add': True}, 'admin_url': '/admin/auths/userhierarchypermission/'}, {'name': <django.utils.functional.lazy.<locals>.__proxy__ object at 0x045F64D0>, 'add_url': '/admin/auths/user/add/', 'object_name': 'User', 'perms': {'delete': True, 'change': True, 'add': True}, 'admin_url': '/admin/auths/user/'}], 'has_module_perms': True, 'app_label': 'auths'}, {'name': 'Caja', 'app_url': '/admin/caja/', 'models': [{'name': 'Boletas', 'add_url': '/admin/caja/boleta/add/', 'object_name': 'Boleta', 'perms': {'delete': True, 'change': True, 'add': True}, 'admin_url': '/admin/caja/boleta/'}, {'name': 'Cajaingresos', 'add_url': '/admin/caja/cajaingreso/add/', 'object_name': 'Cajaingreso', 'perms': {'delete': True, 'change': True, 'add': True}, 'admin_url': '/admin/caja/cajaingreso/'}, {'name': 'Clientes', 'add_url': '/admin/caja/cliente/add/', 'object_name': 'Cliente', 'perms': {'delete': True, 'change': True, 'add': True}, 'admin_url': '/admin/caja/cliente/'}, {'name': 'Modcontables', 'add_url': '/admin/caja/modcontable/add/', 'object_name': 'Modcontable', 'perms': {'delete': True, 'change': True, 'add': True}, 'admin_url': '/admin/caja/modcontable/'}, {'name': 'Niveles', 'add_url': '/admin/caja/nivel/add/', 'object_name': 'Nivel', 'perms': {'delete': True, 'change': True, 'add': True}, 'admin_url': '/admin/caja/nivel/'}, {'name': 'PeriodoContables', 'add_url': '/admin/caja/periodocontable/add/', 'object_name': 'PeriodoContable', 'perms': {'delete': True, 'change': True, 'add': True}, 'admin_url': '/admin/caja/periodocontable/'}, {'name': 'Usercashiers', 'add_url': '/admin/caja/usercashier/add/', 'object_name': 'Usercashier', 'perms': {'delete': True, 'change': True, 'add': True}, 'admin_url': '/admin/caja/usercashier/'}], 'has_module_perms': True, 'app_label': 'caja'}, {'name': 'Catalogo', 'app_url': '/admin/catalogo/', 'models': [{'name': 'Autores', 'add_url': '/admin/catalogo/autor/add/', 'object_name': 'Autor', 'perms': {'delete': True, 'change': True, 'add': True}, 'admin_url': '/admin/catalogo/autor/'}, {'name': 'Categorias', 'add_url': '/admin/catalogo/categoria/add/', 'object_name': 'Categoria', 'perms': {'delete': True, 'change': True, 'add': True}, 'admin_url': '/admin/catalogo/categoria/'}, {'name': 'Libros', 'add_url': '/admin/catalogo/libro/add/', 'object_name': 'Libro', 'perms': {'delete': True, 'change': True, 'add': True}, 'admin_url': '/admin/catalogo/libro/'}], 'has_module_perms': True, 'app_label': 'catalogo'}, {'name': <django.utils.functional.lazy.<locals>.__proxy__ object at 0x03585810>, 'app_url': '/admin/contenttypes/', 'models': [{'name': <django.utils.functional.lazy.<locals>.__proxy__ object at 0x04596710>, 'add_url': '/admin/contenttypes/contenttype/add/', 'object_name': 'ContentType', 'perms': {'delete': True, 'change': True, 'add': True}, 'admin_url': '/admin/contenttypes/contenttype/'}], 'has_module_perms': True, 'app_label': 'contenttypes'}, {'name': 'Django OAuth Toolkit', 'app_url': '/admin/oauth2_provider/', 'models': [{'name': <django.utils.functional.lazy.<locals>.__proxy__ object at 0x045F66B0>, 'add_url': '/admin/oauth2_provider/accesstoken/add/', 'object_name': 'AccessToken', 'perms': {'delete': True, 'change': True, 'add': True}, 'admin_url': '/admin/oauth2_provider/accesstoken/'}, {'name': <django.utils.functional.lazy.<locals>.__proxy__ object at 0x0459CA30>, 'add_url': '/admin/oauth2_provider/application/add/', 'object_name': 'Application', 'perms': {'delete': True, 'change': True, 'add': True}, 'admin_url': '/admin/oauth2_provider/application/'}, {'name': <django.utils.functional.lazy.<locals>.__proxy__ object at 0x045F6670>, 'add_url': '/admin/oauth2_provider/grant/add/', 'object_name': 'Grant', 'perms': {'delete': True, 'change': True, 'add': True}, 'admin_url': '/admin/oauth2_provider/grant/'}, {'name': <django.utils.functional.lazy.<locals>.__proxy__ object at 0x0459CBF0>, 'add_url': '/admin/oauth2_provider/refreshtoken/add/', 'object_name': 'RefreshToken', 'perms': {'delete': True, 'change': True, 'add': True}, 'admin_url': '/admin/oauth2_provider/refreshtoken/'}], 'has_module_perms': True, 'app_label': 'oauth2_provider'}]}]"
[2016-11-30 19:02:07] DEBUG [django.db.backends:90] (0.000) SELECT "django_admin_log"."id", "django_admin_log"."action_time", "django_admin_log"."user_id", "django_admin_log"."content_type_id", "django_admin_log"."object_id", "django_admin_log"."object_repr", "django_admin_log"."action_flag", "django_admin_log"."change_message", "auths_user"."password", "auths_user"."last_login", "auths_user"."is_superuser", "auths_user"."username", "auths_user"."first_name", "auths_user"."last_name", "auths_user"."email", "auths_user"."is_staff", "auths_user"."is_active", "auths_user"."date_joined", "auths_user"."id", "auths_user"."last_hierarchy_id", "auths_user"."last_module_id", "auths_user"."person_id", "auths_user"."updated_at", "auths_user"."registered_by", "django_content_type"."id", "django_content_type"."app_label", "django_content_type"."model" FROM "django_admin_log" INNER JOIN "auths_user" ON ("django_admin_log"."user_id" = "auths_user"."id") LEFT OUTER JOIN "django_content_type" ON ("django_admin_log"."content_type_id" = "django_content_type"."id") WHERE "django_admin_log"."user_id" = 'c0984be488184a5aafe26a71cd216420' ORDER BY "django_admin_log"."action_time" DESC LIMIT 10; args=('c0984be488184a5aafe26a71cd216420',)
[2016-11-30 19:02:07] INFO [django.server:131] "GET /admin/ HTTP/1.1" 200 16701
[2016-11-30 19:02:07] INFO [django.server:131] "GET /static/admin/css/dashboard.css HTTP/1.1" 304 0
[2016-11-30 19:02:07] INFO [django.server:131] "GET /static/admin/img/icon-changelink.svg HTTP/1.1" 304 0
[2016-11-30 19:02:07] INFO [django.server:131] "GET /static/admin/img/icon-addlink.svg HTTP/1.1" 304 0
[2016-11-30 19:02:22] INFO [django.server:131] "OPTIONS /api/caja/boletas/ HTTP/1.1" 200 0
[2016-11-30 19:02:22] DEBUG [django.db.backends:90] (0.003) SELECT "oauth2_provider_accesstoken"."id", "oauth2_provider_accesstoken"."user_id", "oauth2_provider_accesstoken"."token", "oauth2_provider_accesstoken"."application_id", "oauth2_provider_accesstoken"."expires", "oauth2_provider_accesstoken"."scope", "auths_user"."password", "auths_user"."last_login", "auths_user"."is_superuser", "auths_user"."username", "auths_user"."first_name", "auths_user"."last_name", "auths_user"."email", "auths_user"."is_staff", "auths_user"."is_active", "auths_user"."date_joined", "auths_user"."id", "auths_user"."last_hierarchy_id", "auths_user"."last_module_id", "auths_user"."person_id", "auths_user"."updated_at", "auths_user"."registered_by", "oauth2_provider_application"."id", "oauth2_provider_application"."client_id", "oauth2_provider_application"."user_id", "oauth2_provider_application"."redirect_uris", "oauth2_provider_application"."client_type", "oauth2_provider_application"."authorization_grant_type", "oauth2_provider_application"."client_secret", "oauth2_provider_application"."name", "oauth2_provider_application"."skip_authorization" FROM "oauth2_provider_accesstoken" LEFT OUTER JOIN "auths_user" ON ("oauth2_provider_accesstoken"."user_id" = "auths_user"."id") INNER JOIN "oauth2_provider_application" ON ("oauth2_provider_accesstoken"."application_id" = "oauth2_provider_application"."id") WHERE "oauth2_provider_accesstoken"."token" = '32Lj56wsSfJHc637Qhh2vAfFGUMkz0'; args=('32Lj56wsSfJHc637Qhh2vAfFGUMkz0',)
[2016-11-30 19:02:22] DEBUG [django.db.backends:90] (0.000) SELECT "oauth2_provider_accesstoken"."id", "oauth2_provider_accesstoken"."user_id", "oauth2_provider_accesstoken"."token", "oauth2_provider_accesstoken"."application_id", "oauth2_provider_accesstoken"."expires", "oauth2_provider_accesstoken"."scope", "auths_user"."password", "auths_user"."last_login", "auths_user"."is_superuser", "auths_user"."username", "auths_user"."first_name", "auths_user"."last_name", "auths_user"."email", "auths_user"."is_staff", "auths_user"."is_active", "auths_user"."date_joined", "auths_user"."id", "auths_user"."last_hierarchy_id", "auths_user"."last_module_id", "auths_user"."person_id", "auths_user"."updated_at", "auths_user"."registered_by", "oauth2_provider_application"."id", "oauth2_provider_application"."client_id", "oauth2_provider_application"."user_id", "oauth2_provider_application"."redirect_uris", "oauth2_provider_application"."client_type", "oauth2_provider_application"."authorization_grant_type", "oauth2_provider_application"."client_secret", "oauth2_provider_application"."name", "oauth2_provider_application"."skip_authorization" FROM "oauth2_provider_accesstoken" LEFT OUTER JOIN "auths_user" ON ("oauth2_provider_accesstoken"."user_id" = "auths_user"."id") INNER JOIN "oauth2_provider_application" ON ("oauth2_provider_accesstoken"."application_id" = "oauth2_provider_application"."id") WHERE "oauth2_provider_accesstoken"."token" = '32Lj56wsSfJHc637Qhh2vAfFGUMkz0'; args=('32Lj56wsSfJHc637Qhh2vAfFGUMkz0',)
[2016-11-30 19:02:22] DEBUG [django.db.backends:90] (0.000) SELECT COUNT(*) AS "__count" FROM "caja_boleta"; args=()
[2016-11-30 19:02:22] DEBUG [django.db.backends:90] (0.053) SELECT "caja_boleta"."id", "caja_boleta"."cantidad", "caja_boleta"."detalle", "caja_boleta"."precioUn", "caja_boleta"."importe", "caja_boleta"."igv", "caja_boleta"."precioTotal", "caja_boleta"."nivel_id", "caja_boleta"."cliente_id", "caja_boleta"."usercashiers_id", "caja_boleta"."fecha" FROM "caja_boleta" LIMIT 5; args=()
[2016-11-30 19:02:22] DEBUG [django.db.backends:90] (0.001) SELECT "caja_nivel"."id", "caja_nivel"."nombreSuc", "caja_nivel"."direccion", "caja_nivel"."telforno" FROM "caja_nivel" WHERE "caja_nivel"."id" = 'e9a9952c7f3f4ee2aab7ba82783c74c0'; args=('e9a9952c7f3f4ee2aab7ba82783c74c0',)
[2016-11-30 19:02:22] DEBUG [django.db.backends:90] (0.001) SELECT "caja_cliente"."id", "caja_cliente"."nombre", "caja_cliente"."apellido", "caja_cliente"."docIdentidad", "caja_cliente"."direccion" FROM "caja_cliente" WHERE "caja_cliente"."id" = '99d8334be69c4f9585fc4f8ece85e0cc'; args=('99d8334be69c4f9585fc4f8ece85e0cc',)
[2016-11-30 19:02:22] DEBUG [django.db.backends:90] (0.001) SELECT "caja_nivel"."id", "caja_nivel"."nombreSuc", "caja_nivel"."direccion", "caja_nivel"."telforno" FROM "caja_nivel" WHERE "caja_nivel"."id" = 'e9a9952c7f3f4ee2aab7ba82783c74c0'; args=('e9a9952c7f3f4ee2aab7ba82783c74c0',)
[2016-11-30 19:02:22] DEBUG [django.db.backends:90] (0.000) SELECT "caja_cliente"."id", "caja_cliente"."nombre", "caja_cliente"."apellido", "caja_cliente"."docIdentidad", "caja_cliente"."direccion" FROM "caja_cliente" WHERE "caja_cliente"."id" = '5bec177140754a2d9fc721ccfd35956e'; args=('5bec177140754a2d9fc721ccfd35956e',)
[2016-11-30 19:02:22] INFO [django.server:131] "GET /api/caja/boletas/ HTTP/1.1" 200 1592
[2016-11-30 19:02:33] INFO [django.server:131] "OPTIONS /api/caja/boletas/?fields=codename&page=2&page_size=5 HTTP/1.1" 200 0
[2016-11-30 19:02:33] DEBUG [django.db.backends:90] (0.002) SELECT "oauth2_provider_accesstoken"."id", "oauth2_provider_accesstoken"."user_id", "oauth2_provider_accesstoken"."token", "oauth2_provider_accesstoken"."application_id", "oauth2_provider_accesstoken"."expires", "oauth2_provider_accesstoken"."scope", "auths_user"."password", "auths_user"."last_login", "auths_user"."is_superuser", "auths_user"."username", "auths_user"."first_name", "auths_user"."last_name", "auths_user"."email", "auths_user"."is_staff", "auths_user"."is_active", "auths_user"."date_joined", "auths_user"."id", "auths_user"."last_hierarchy_id", "auths_user"."last_module_id", "auths_user"."person_id", "auths_user"."updated_at", "auths_user"."registered_by", "oauth2_provider_application"."id", "oauth2_provider_application"."client_id", "oauth2_provider_application"."user_id", "oauth2_provider_application"."redirect_uris", "oauth2_provider_application"."client_type", "oauth2_provider_application"."authorization_grant_type", "oauth2_provider_application"."client_secret", "oauth2_provider_application"."name", "oauth2_provider_application"."skip_authorization" FROM "oauth2_provider_accesstoken" LEFT OUTER JOIN "auths_user" ON ("oauth2_provider_accesstoken"."user_id" = "auths_user"."id") INNER JOIN "oauth2_provider_application" ON ("oauth2_provider_accesstoken"."application_id" = "oauth2_provider_application"."id") WHERE "oauth2_provider_accesstoken"."token" = '32Lj56wsSfJHc637Qhh2vAfFGUMkz0'; args=('32Lj56wsSfJHc637Qhh2vAfFGUMkz0',)
[2016-11-30 19:02:33] DEBUG [django.db.backends:90] (0.000) SELECT "oauth2_provider_accesstoken"."id", "oauth2_provider_accesstoken"."user_id", "oauth2_provider_accesstoken"."token", "oauth2_provider_accesstoken"."application_id", "oauth2_provider_accesstoken"."expires", "oauth2_provider_accesstoken"."scope", "auths_user"."password", "auths_user"."last_login", "auths_user"."is_superuser", "auths_user"."username", "auths_user"."first_name", "auths_user"."last_name", "auths_user"."email", "auths_user"."is_staff", "auths_user"."is_active", "auths_user"."date_joined", "auths_user"."id", "auths_user"."last_hierarchy_id", "auths_user"."last_module_id", "auths_user"."person_id", "auths_user"."updated_at", "auths_user"."registered_by", "oauth2_provider_application"."id", "oauth2_provider_application"."client_id", "oauth2_provider_application"."user_id", "oauth2_provider_application"."redirect_uris", "oauth2_provider_application"."client_type", "oauth2_provider_application"."authorization_grant_type", "oauth2_provider_application"."client_secret", "oauth2_provider_application"."name", "oauth2_provider_application"."skip_authorization" FROM "oauth2_provider_accesstoken" LEFT OUTER JOIN "auths_user" ON ("oauth2_provider_accesstoken"."user_id" = "auths_user"."id") INNER JOIN "oauth2_provider_application" ON ("oauth2_provider_accesstoken"."application_id" = "oauth2_provider_application"."id") WHERE "oauth2_provider_accesstoken"."token" = '32Lj56wsSfJHc637Qhh2vAfFGUMkz0'; args=('32Lj56wsSfJHc637Qhh2vAfFGUMkz0',)
[2016-11-30 19:02:33] DEBUG [django.db.backends:90] (0.000) SELECT COUNT(*) AS "__count" FROM "caja_boleta"; args=()
[2016-11-30 19:02:33] DEBUG [django.db.backends:90] (0.001) SELECT "caja_boleta"."id", "caja_boleta"."cantidad", "caja_boleta"."detalle", "caja_boleta"."precioUn", "caja_boleta"."importe", "caja_boleta"."igv", "caja_boleta"."precioTotal", "caja_boleta"."nivel_id", "caja_boleta"."cliente_id", "caja_boleta"."usercashiers_id", "caja_boleta"."fecha" FROM "caja_boleta" LIMIT 1 OFFSET 5; args=()
[2016-11-30 19:02:33] INFO [django.server:131] "GET /api/caja/boletas/?fields=codename&page=2&page_size=5 HTTP/1.1" 200 374
[2016-11-30 19:02:35] INFO [django.server:131] "OPTIONS /api/caja/boletas/?fields=codename&page=1&page_size=5 HTTP/1.1" 200 0
[2016-11-30 19:02:35] DEBUG [django.db.backends:90] (0.002) SELECT "oauth2_provider_accesstoken"."id", "oauth2_provider_accesstoken"."user_id", "oauth2_provider_accesstoken"."token", "oauth2_provider_accesstoken"."application_id", "oauth2_provider_accesstoken"."expires", "oauth2_provider_accesstoken"."scope", "auths_user"."password", "auths_user"."last_login", "auths_user"."is_superuser", "auths_user"."username", "auths_user"."first_name", "auths_user"."last_name", "auths_user"."email", "auths_user"."is_staff", "auths_user"."is_active", "auths_user"."date_joined", "auths_user"."id", "auths_user"."last_hierarchy_id", "auths_user"."last_module_id", "auths_user"."person_id", "auths_user"."updated_at", "auths_user"."registered_by", "oauth2_provider_application"."id", "oauth2_provider_application"."client_id", "oauth2_provider_application"."user_id", "oauth2_provider_application"."redirect_uris", "oauth2_provider_application"."client_type", "oauth2_provider_application"."authorization_grant_type", "oauth2_provider_application"."client_secret", "oauth2_provider_application"."name", "oauth2_provider_application"."skip_authorization" FROM "oauth2_provider_accesstoken" LEFT OUTER JOIN "auths_user" ON ("oauth2_provider_accesstoken"."user_id" = "auths_user"."id") INNER JOIN "oauth2_provider_application" ON ("oauth2_provider_accesstoken"."application_id" = "oauth2_provider_application"."id") WHERE "oauth2_provider_accesstoken"."token" = '32Lj56wsSfJHc637Qhh2vAfFGUMkz0'; args=('32Lj56wsSfJHc637Qhh2vAfFGUMkz0',)
[2016-11-30 19:02:35] DEBUG [django.db.backends:90] (0.001) SELECT "oauth2_provider_accesstoken"."id", "oauth2_provider_accesstoken"."user_id", "oauth2_provider_accesstoken"."token", "oauth2_provider_accesstoken"."application_id", "oauth2_provider_accesstoken"."expires", "oauth2_provider_accesstoken"."scope", "auths_user"."password", "auths_user"."last_login", "auths_user"."is_superuser", "auths_user"."username", "auths_user"."first_name", "auths_user"."last_name", "auths_user"."email", "auths_user"."is_staff", "auths_user"."is_active", "auths_user"."date_joined", "auths_user"."id", "auths_user"."last_hierarchy_id", "auths_user"."last_module_id", "auths_user"."person_id", "auths_user"."updated_at", "auths_user"."registered_by", "oauth2_provider_application"."id", "oauth2_provider_application"."client_id", "oauth2_provider_application"."user_id", "oauth2_provider_application"."redirect_uris", "oauth2_provider_application"."client_type", "oauth2_provider_application"."authorization_grant_type", "oauth2_provider_application"."client_secret", "oauth2_provider_application"."name", "oauth2_provider_application"."skip_authorization" FROM "oauth2_provider_accesstoken" LEFT OUTER JOIN "auths_user" ON ("oauth2_provider_accesstoken"."user_id" = "auths_user"."id") INNER JOIN "oauth2_provider_application" ON ("oauth2_provider_accesstoken"."application_id" = "oauth2_provider_application"."id") WHERE "oauth2_provider_accesstoken"."token" = '32Lj56wsSfJHc637Qhh2vAfFGUMkz0'; args=('32Lj56wsSfJHc637Qhh2vAfFGUMkz0',)
[2016-11-30 19:02:35] DEBUG [django.db.backends:90] (0.000) SELECT COUNT(*) AS "__count" FROM "caja_boleta"; args=()
[2016-11-30 19:02:35] DEBUG [django.db.backends:90] (0.001) SELECT "caja_boleta"."id", "caja_boleta"."cantidad", "caja_boleta"."detalle", "caja_boleta"."precioUn", "caja_boleta"."importe", "caja_boleta"."igv", "caja_boleta"."precioTotal", "caja_boleta"."nivel_id", "caja_boleta"."cliente_id", "caja_boleta"."usercashiers_id", "caja_boleta"."fecha" FROM "caja_boleta" LIMIT 5; args=()
[2016-11-30 19:02:35] DEBUG [django.db.backends:90] (0.000) SELECT "caja_nivel"."id", "caja_nivel"."nombreSuc", "caja_nivel"."direccion", "caja_nivel"."telforno" FROM "caja_nivel" WHERE "caja_nivel"."id" = 'e9a9952c7f3f4ee2aab7ba82783c74c0'; args=('e9a9952c7f3f4ee2aab7ba82783c74c0',)
[2016-11-30 19:02:35] DEBUG [django.db.backends:90] (0.000) SELECT "caja_cliente"."id", "caja_cliente"."nombre", "caja_cliente"."apellido", "caja_cliente"."docIdentidad", "caja_cliente"."direccion" FROM "caja_cliente" WHERE "caja_cliente"."id" = '99d8334be69c4f9585fc4f8ece85e0cc'; args=('99d8334be69c4f9585fc4f8ece85e0cc',)
[2016-11-30 19:02:35] DEBUG [django.db.backends:90] (0.000) SELECT "caja_nivel"."id", "caja_nivel"."nombreSuc", "caja_nivel"."direccion", "caja_nivel"."telforno" FROM "caja_nivel" WHERE "caja_nivel"."id" = 'e9a9952c7f3f4ee2aab7ba82783c74c0'; args=('e9a9952c7f3f4ee2aab7ba82783c74c0',)
[2016-11-30 19:02:35] DEBUG [django.db.backends:90] (0.000) SELECT "caja_cliente"."id", "caja_cliente"."nombre", "caja_cliente"."apellido", "caja_cliente"."docIdentidad", "caja_cliente"."direccion" FROM "caja_cliente" WHERE "caja_cliente"."id" = '5bec177140754a2d9fc721ccfd35956e'; args=('5bec177140754a2d9fc721ccfd35956e',)
[2016-11-30 19:02:35] INFO [django.server:131] "GET /api/caja/boletas/?fields=codename&page=1&page_size=5 HTTP/1.1" 200 1592
[2016-11-30 19:06:11] DEBUG [django.db.backends:90] (0.000) 
            SELECT name, type FROM sqlite_master
            WHERE type in ('table', 'view') AND NOT name='sqlite_sequence'
            ORDER BY name; args=None
[2016-11-30 19:06:11] DEBUG [django.db.backends:90] (0.000) SELECT "django_migrations"."app", "django_migrations"."name" FROM "django_migrations"; args=()
