[2016-11-16 04:53:27] DEBUG [django.db.backends:90] (0.036) 
            SELECT name, type FROM sqlite_master
            WHERE type in ('table', 'view') AND NOT name='sqlite_sequence'
            ORDER BY name; args=None
[2016-11-16 04:53:27] DEBUG [django.db.backends:90] (0.000) SELECT "django_migrations"."app", "django_migrations"."name" FROM "django_migrations"; args=()
[2016-11-16 04:54:03] DEBUG [django.db.backends:90] (0.002) 
            SELECT name, type FROM sqlite_master
            WHERE type in ('table', 'view') AND NOT name='sqlite_sequence'
            ORDER BY name; args=None
[2016-11-16 04:54:03] DEBUG [django.db.backends:90] (0.000) SELECT "django_migrations"."app", "django_migrations"."name" FROM "django_migrations"; args=()
[2016-11-16 04:54:31] DEBUG [django.template:929] Exception while resolving variable 'name' in template 'unknown'.
Traceback (most recent call last):
  File "D:\Project\redcashier\ve_redcashier\lib\site-packages\django\core\handlers\exception.py", line 39, in inner
    response = get_response(request)
  File "D:\Project\redcashier\ve_redcashier\lib\site-packages\django\core\handlers\base.py", line 249, in _legacy_get_response
    response = self._get_response(request)
  File "D:\Project\redcashier\ve_redcashier\lib\site-packages\django\core\handlers\base.py", line 172, in _get_response
    resolver_match = resolver.resolve(request.path_info)
  File "D:\Project\redcashier\ve_redcashier\lib\site-packages\django\urls\resolvers.py", line 300, in resolve
    raise Resolver404({'tried': tried, 'path': new_path})
django.urls.exceptions.Resolver404: {'path': '', 'tried': [[<RegexURLResolver <RegexURLPattern list> (admin:admin) ^admin/>], [<RegexURLResolver <module 'django.contrib.admindocs.urls' from 'D:\\Project\\redcashier\\ve_redcashier\\lib\\site-packages\\django\\contrib\\admindocs\\urls.py'> (None:None) ^admin/doc/>], [<RegexURLResolver <module 'rest_framework.urls' from 'D:\\Project\\redcashier\\ve_redcashier\\lib\\site-packages\\rest_framework\\urls.py'> (rest_framework:rest_framework) ^api-auth/>], [<RegexURLResolver <module 'oauth2_provider.urls' from 'D:\\Project\\redcashier\\ve_redcashier\\lib\\site-packages\\oauth2_provider\\urls.py'> (None:oauth2_provider) ^o/>], [<RegexURLResolver <module 'redcashier_service_apps.auths_api.urls' from 'D:\\Project\\redcashier\\redcashier_service\\redcashier_service_apps\\auths_api\\urls.py'> (None:None) ^api/auths/>], [<RegexURLResolver <module 'redcashier_service_apps.catalogo_api.urls' from 'D:\\Project\\redcashier\\redcashier_service\\redcashier_service_apps\\catalogo_api\\urls.py'> (None:None) ^api/catalogo/>], [<RegexURLResolver <module 'redcashier_service_apps.caja_api.urls' from 'D:\\Project\\redcashier\\redcashier_service\\redcashier_service_apps\\caja_api\\urls.py'> (None:None) ^api/caja/>]]}

During handling of the above exception, another exception occurred:

Traceback (most recent call last):
  File "D:\Project\redcashier\ve_redcashier\lib\site-packages\django\template\base.py", line 885, in _resolve_lookup
    current = current[bit]
TypeError: 'RegexURLResolver' object is not subscriptable

During handling of the above exception, another exception occurred:

Traceback (most recent call last):
  File "D:\Project\redcashier\ve_redcashier\lib\site-packages\django\template\base.py", line 893, in _resolve_lookup
    current = getattr(current, bit)
AttributeError: 'RegexURLResolver' object has no attribute 'name'

During handling of the above exception, another exception occurred:

Traceback (most recent call last):
  File "D:\Project\redcashier\ve_redcashier\lib\site-packages\django\template\base.py", line 900, in _resolve_lookup
    current = current[int(bit)]
ValueError: invalid literal for int() with base 10: 'name'

During handling of the above exception, another exception occurred:

Traceback (most recent call last):
  File "D:\Project\redcashier\ve_redcashier\lib\site-packages\django\template\base.py", line 907, in _resolve_lookup
    (bit, current))  # missing attribute
django.template.base.VariableDoesNotExist: Failed lookup for key [name] in '<RegexURLResolver <RegexURLPattern list> (admin:admin) ^admin/>'
[2016-11-16 04:54:31] DEBUG [django.template:929] Exception while resolving variable 'name' in template 'unknown'.
Traceback (most recent call last):
  File "D:\Project\redcashier\ve_redcashier\lib\site-packages\django\core\handlers\exception.py", line 39, in inner
    response = get_response(request)
  File "D:\Project\redcashier\ve_redcashier\lib\site-packages\django\core\handlers\base.py", line 249, in _legacy_get_response
    response = self._get_response(request)
  File "D:\Project\redcashier\ve_redcashier\lib\site-packages\django\core\handlers\base.py", line 172, in _get_response
    resolver_match = resolver.resolve(request.path_info)
  File "D:\Project\redcashier\ve_redcashier\lib\site-packages\django\urls\resolvers.py", line 300, in resolve
    raise Resolver404({'tried': tried, 'path': new_path})
django.urls.exceptions.Resolver404: {'path': '', 'tried': [[<RegexURLResolver <RegexURLPattern list> (admin:admin) ^admin/>], [<RegexURLResolver <module 'django.contrib.admindocs.urls' from 'D:\\Project\\redcashier\\ve_redcashier\\lib\\site-packages\\django\\contrib\\admindocs\\urls.py'> (None:None) ^admin/doc/>], [<RegexURLResolver <module 'rest_framework.urls' from 'D:\\Project\\redcashier\\ve_redcashier\\lib\\site-packages\\rest_framework\\urls.py'> (rest_framework:rest_framework) ^api-auth/>], [<RegexURLResolver <module 'oauth2_provider.urls' from 'D:\\Project\\redcashier\\ve_redcashier\\lib\\site-packages\\oauth2_provider\\urls.py'> (None:oauth2_provider) ^o/>], [<RegexURLResolver <module 'redcashier_service_apps.auths_api.urls' from 'D:\\Project\\redcashier\\redcashier_service\\redcashier_service_apps\\auths_api\\urls.py'> (None:None) ^api/auths/>], [<RegexURLResolver <module 'redcashier_service_apps.catalogo_api.urls' from 'D:\\Project\\redcashier\\redcashier_service\\redcashier_service_apps\\catalogo_api\\urls.py'> (None:None) ^api/catalogo/>], [<RegexURLResolver <module 'redcashier_service_apps.caja_api.urls' from 'D:\\Project\\redcashier\\redcashier_service\\redcashier_service_apps\\caja_api\\urls.py'> (None:None) ^api/caja/>]]}

During handling of the above exception, another exception occurred:

Traceback (most recent call last):
  File "D:\Project\redcashier\ve_redcashier\lib\site-packages\django\template\base.py", line 885, in _resolve_lookup
    current = current[bit]
TypeError: 'RegexURLResolver' object is not subscriptable

During handling of the above exception, another exception occurred:

Traceback (most recent call last):
  File "D:\Project\redcashier\ve_redcashier\lib\site-packages\django\template\base.py", line 893, in _resolve_lookup
    current = getattr(current, bit)
AttributeError: 'RegexURLResolver' object has no attribute 'name'

During handling of the above exception, another exception occurred:

Traceback (most recent call last):
  File "D:\Project\redcashier\ve_redcashier\lib\site-packages\django\template\base.py", line 900, in _resolve_lookup
    current = current[int(bit)]
ValueError: invalid literal for int() with base 10: 'name'

During handling of the above exception, another exception occurred:

Traceback (most recent call last):
  File "D:\Project\redcashier\ve_redcashier\lib\site-packages\django\template\base.py", line 907, in _resolve_lookup
    (bit, current))  # missing attribute
django.template.base.VariableDoesNotExist: Failed lookup for key [name] in "<RegexURLResolver <module 'django.contrib.admindocs.urls' from 'D:\\\\Project\\\\redcashier\\\\ve_redcashier\\\\lib\\\\site-packages\\\\django\\\\contrib\\\\admindocs\\\\urls.py'> (None:None) ^admin/doc/>"
[2016-11-16 04:54:31] DEBUG [django.template:929] Exception while resolving variable 'name' in template 'unknown'.
Traceback (most recent call last):
  File "D:\Project\redcashier\ve_redcashier\lib\site-packages\django\core\handlers\exception.py", line 39, in inner
    response = get_response(request)
  File "D:\Project\redcashier\ve_redcashier\lib\site-packages\django\core\handlers\base.py", line 249, in _legacy_get_response
    response = self._get_response(request)
  File "D:\Project\redcashier\ve_redcashier\lib\site-packages\django\core\handlers\base.py", line 172, in _get_response
    resolver_match = resolver.resolve(request.path_info)
  File "D:\Project\redcashier\ve_redcashier\lib\site-packages\django\urls\resolvers.py", line 300, in resolve
    raise Resolver404({'tried': tried, 'path': new_path})
django.urls.exceptions.Resolver404: {'path': '', 'tried': [[<RegexURLResolver <RegexURLPattern list> (admin:admin) ^admin/>], [<RegexURLResolver <module 'django.contrib.admindocs.urls' from 'D:\\Project\\redcashier\\ve_redcashier\\lib\\site-packages\\django\\contrib\\admindocs\\urls.py'> (None:None) ^admin/doc/>], [<RegexURLResolver <module 'rest_framework.urls' from 'D:\\Project\\redcashier\\ve_redcashier\\lib\\site-packages\\rest_framework\\urls.py'> (rest_framework:rest_framework) ^api-auth/>], [<RegexURLResolver <module 'oauth2_provider.urls' from 'D:\\Project\\redcashier\\ve_redcashier\\lib\\site-packages\\oauth2_provider\\urls.py'> (None:oauth2_provider) ^o/>], [<RegexURLResolver <module 'redcashier_service_apps.auths_api.urls' from 'D:\\Project\\redcashier\\redcashier_service\\redcashier_service_apps\\auths_api\\urls.py'> (None:None) ^api/auths/>], [<RegexURLResolver <module 'redcashier_service_apps.catalogo_api.urls' from 'D:\\Project\\redcashier\\redcashier_service\\redcashier_service_apps\\catalogo_api\\urls.py'> (None:None) ^api/catalogo/>], [<RegexURLResolver <module 'redcashier_service_apps.caja_api.urls' from 'D:\\Project\\redcashier\\redcashier_service\\redcashier_service_apps\\caja_api\\urls.py'> (None:None) ^api/caja/>]]}

During handling of the above exception, another exception occurred:

Traceback (most recent call last):
  File "D:\Project\redcashier\ve_redcashier\lib\site-packages\django\template\base.py", line 885, in _resolve_lookup
    current = current[bit]
TypeError: 'RegexURLResolver' object is not subscriptable

During handling of the above exception, another exception occurred:

Traceback (most recent call last):
  File "D:\Project\redcashier\ve_redcashier\lib\site-packages\django\template\base.py", line 893, in _resolve_lookup
    current = getattr(current, bit)
AttributeError: 'RegexURLResolver' object has no attribute 'name'

During handling of the above exception, another exception occurred:

Traceback (most recent call last):
  File "D:\Project\redcashier\ve_redcashier\lib\site-packages\django\template\base.py", line 900, in _resolve_lookup
    current = current[int(bit)]
ValueError: invalid literal for int() with base 10: 'name'

During handling of the above exception, another exception occurred:

Traceback (most recent call last):
  File "D:\Project\redcashier\ve_redcashier\lib\site-packages\django\template\base.py", line 907, in _resolve_lookup
    (bit, current))  # missing attribute
django.template.base.VariableDoesNotExist: Failed lookup for key [name] in "<RegexURLResolver <module 'rest_framework.urls' from 'D:\\\\Project\\\\redcashier\\\\ve_redcashier\\\\lib\\\\site-packages\\\\rest_framework\\\\urls.py'> (rest_framework:rest_framework) ^api-auth/>"
[2016-11-16 04:54:31] DEBUG [django.template:929] Exception while resolving variable 'name' in template 'unknown'.
Traceback (most recent call last):
  File "D:\Project\redcashier\ve_redcashier\lib\site-packages\django\core\handlers\exception.py", line 39, in inner
    response = get_response(request)
  File "D:\Project\redcashier\ve_redcashier\lib\site-packages\django\core\handlers\base.py", line 249, in _legacy_get_response
    response = self._get_response(request)
  File "D:\Project\redcashier\ve_redcashier\lib\site-packages\django\core\handlers\base.py", line 172, in _get_response
    resolver_match = resolver.resolve(request.path_info)
  File "D:\Project\redcashier\ve_redcashier\lib\site-packages\django\urls\resolvers.py", line 300, in resolve
    raise Resolver404({'tried': tried, 'path': new_path})
django.urls.exceptions.Resolver404: {'path': '', 'tried': [[<RegexURLResolver <RegexURLPattern list> (admin:admin) ^admin/>], [<RegexURLResolver <module 'django.contrib.admindocs.urls' from 'D:\\Project\\redcashier\\ve_redcashier\\lib\\site-packages\\django\\contrib\\admindocs\\urls.py'> (None:None) ^admin/doc/>], [<RegexURLResolver <module 'rest_framework.urls' from 'D:\\Project\\redcashier\\ve_redcashier\\lib\\site-packages\\rest_framework\\urls.py'> (rest_framework:rest_framework) ^api-auth/>], [<RegexURLResolver <module 'oauth2_provider.urls' from 'D:\\Project\\redcashier\\ve_redcashier\\lib\\site-packages\\oauth2_provider\\urls.py'> (None:oauth2_provider) ^o/>], [<RegexURLResolver <module 'redcashier_service_apps.auths_api.urls' from 'D:\\Project\\redcashier\\redcashier_service\\redcashier_service_apps\\auths_api\\urls.py'> (None:None) ^api/auths/>], [<RegexURLResolver <module 'redcashier_service_apps.catalogo_api.urls' from 'D:\\Project\\redcashier\\redcashier_service\\redcashier_service_apps\\catalogo_api\\urls.py'> (None:None) ^api/catalogo/>], [<RegexURLResolver <module 'redcashier_service_apps.caja_api.urls' from 'D:\\Project\\redcashier\\redcashier_service\\redcashier_service_apps\\caja_api\\urls.py'> (None:None) ^api/caja/>]]}

During handling of the above exception, another exception occurred:

Traceback (most recent call last):
  File "D:\Project\redcashier\ve_redcashier\lib\site-packages\django\template\base.py", line 885, in _resolve_lookup
    current = current[bit]
TypeError: 'RegexURLResolver' object is not subscriptable

During handling of the above exception, another exception occurred:

Traceback (most recent call last):
  File "D:\Project\redcashier\ve_redcashier\lib\site-packages\django\template\base.py", line 893, in _resolve_lookup
    current = getattr(current, bit)
AttributeError: 'RegexURLResolver' object has no attribute 'name'

During handling of the above exception, another exception occurred:

Traceback (most recent call last):
  File "D:\Project\redcashier\ve_redcashier\lib\site-packages\django\template\base.py", line 900, in _resolve_lookup
    current = current[int(bit)]
ValueError: invalid literal for int() with base 10: 'name'

During handling of the above exception, another exception occurred:

Traceback (most recent call last):
  File "D:\Project\redcashier\ve_redcashier\lib\site-packages\django\template\base.py", line 907, in _resolve_lookup
    (bit, current))  # missing attribute
django.template.base.VariableDoesNotExist: Failed lookup for key [name] in "<RegexURLResolver <module 'oauth2_provider.urls' from 'D:\\\\Project\\\\redcashier\\\\ve_redcashier\\\\lib\\\\site-packages\\\\oauth2_provider\\\\urls.py'> (None:oauth2_provider) ^o/>"
[2016-11-16 04:54:31] DEBUG [django.template:929] Exception while resolving variable 'name' in template 'unknown'.
Traceback (most recent call last):
  File "D:\Project\redcashier\ve_redcashier\lib\site-packages\django\core\handlers\exception.py", line 39, in inner
    response = get_response(request)
  File "D:\Project\redcashier\ve_redcashier\lib\site-packages\django\core\handlers\base.py", line 249, in _legacy_get_response
    response = self._get_response(request)
  File "D:\Project\redcashier\ve_redcashier\lib\site-packages\django\core\handlers\base.py", line 172, in _get_response
    resolver_match = resolver.resolve(request.path_info)
  File "D:\Project\redcashier\ve_redcashier\lib\site-packages\django\urls\resolvers.py", line 300, in resolve
    raise Resolver404({'tried': tried, 'path': new_path})
django.urls.exceptions.Resolver404: {'path': '', 'tried': [[<RegexURLResolver <RegexURLPattern list> (admin:admin) ^admin/>], [<RegexURLResolver <module 'django.contrib.admindocs.urls' from 'D:\\Project\\redcashier\\ve_redcashier\\lib\\site-packages\\django\\contrib\\admindocs\\urls.py'> (None:None) ^admin/doc/>], [<RegexURLResolver <module 'rest_framework.urls' from 'D:\\Project\\redcashier\\ve_redcashier\\lib\\site-packages\\rest_framework\\urls.py'> (rest_framework:rest_framework) ^api-auth/>], [<RegexURLResolver <module 'oauth2_provider.urls' from 'D:\\Project\\redcashier\\ve_redcashier\\lib\\site-packages\\oauth2_provider\\urls.py'> (None:oauth2_provider) ^o/>], [<RegexURLResolver <module 'redcashier_service_apps.auths_api.urls' from 'D:\\Project\\redcashier\\redcashier_service\\redcashier_service_apps\\auths_api\\urls.py'> (None:None) ^api/auths/>], [<RegexURLResolver <module 'redcashier_service_apps.catalogo_api.urls' from 'D:\\Project\\redcashier\\redcashier_service\\redcashier_service_apps\\catalogo_api\\urls.py'> (None:None) ^api/catalogo/>], [<RegexURLResolver <module 'redcashier_service_apps.caja_api.urls' from 'D:\\Project\\redcashier\\redcashier_service\\redcashier_service_apps\\caja_api\\urls.py'> (None:None) ^api/caja/>]]}

During handling of the above exception, another exception occurred:

Traceback (most recent call last):
  File "D:\Project\redcashier\ve_redcashier\lib\site-packages\django\template\base.py", line 885, in _resolve_lookup
    current = current[bit]
TypeError: 'RegexURLResolver' object is not subscriptable

During handling of the above exception, another exception occurred:

Traceback (most recent call last):
  File "D:\Project\redcashier\ve_redcashier\lib\site-packages\django\template\base.py", line 893, in _resolve_lookup
    current = getattr(current, bit)
AttributeError: 'RegexURLResolver' object has no attribute 'name'

During handling of the above exception, another exception occurred:

Traceback (most recent call last):
  File "D:\Project\redcashier\ve_redcashier\lib\site-packages\django\template\base.py", line 900, in _resolve_lookup
    current = current[int(bit)]
ValueError: invalid literal for int() with base 10: 'name'

During handling of the above exception, another exception occurred:

Traceback (most recent call last):
  File "D:\Project\redcashier\ve_redcashier\lib\site-packages\django\template\base.py", line 907, in _resolve_lookup
    (bit, current))  # missing attribute
django.template.base.VariableDoesNotExist: Failed lookup for key [name] in "<RegexURLResolver <module 'redcashier_service_apps.auths_api.urls' from 'D:\\\\Project\\\\redcashier\\\\redcashier_service\\\\redcashier_service_apps\\\\auths_api\\\\urls.py'> (None:None) ^api/auths/>"
[2016-11-16 04:54:31] DEBUG [django.template:929] Exception while resolving variable 'name' in template 'unknown'.
Traceback (most recent call last):
  File "D:\Project\redcashier\ve_redcashier\lib\site-packages\django\core\handlers\exception.py", line 39, in inner
    response = get_response(request)
  File "D:\Project\redcashier\ve_redcashier\lib\site-packages\django\core\handlers\base.py", line 249, in _legacy_get_response
    response = self._get_response(request)
  File "D:\Project\redcashier\ve_redcashier\lib\site-packages\django\core\handlers\base.py", line 172, in _get_response
    resolver_match = resolver.resolve(request.path_info)
  File "D:\Project\redcashier\ve_redcashier\lib\site-packages\django\urls\resolvers.py", line 300, in resolve
    raise Resolver404({'tried': tried, 'path': new_path})
django.urls.exceptions.Resolver404: {'path': '', 'tried': [[<RegexURLResolver <RegexURLPattern list> (admin:admin) ^admin/>], [<RegexURLResolver <module 'django.contrib.admindocs.urls' from 'D:\\Project\\redcashier\\ve_redcashier\\lib\\site-packages\\django\\contrib\\admindocs\\urls.py'> (None:None) ^admin/doc/>], [<RegexURLResolver <module 'rest_framework.urls' from 'D:\\Project\\redcashier\\ve_redcashier\\lib\\site-packages\\rest_framework\\urls.py'> (rest_framework:rest_framework) ^api-auth/>], [<RegexURLResolver <module 'oauth2_provider.urls' from 'D:\\Project\\redcashier\\ve_redcashier\\lib\\site-packages\\oauth2_provider\\urls.py'> (None:oauth2_provider) ^o/>], [<RegexURLResolver <module 'redcashier_service_apps.auths_api.urls' from 'D:\\Project\\redcashier\\redcashier_service\\redcashier_service_apps\\auths_api\\urls.py'> (None:None) ^api/auths/>], [<RegexURLResolver <module 'redcashier_service_apps.catalogo_api.urls' from 'D:\\Project\\redcashier\\redcashier_service\\redcashier_service_apps\\catalogo_api\\urls.py'> (None:None) ^api/catalogo/>], [<RegexURLResolver <module 'redcashier_service_apps.caja_api.urls' from 'D:\\Project\\redcashier\\redcashier_service\\redcashier_service_apps\\caja_api\\urls.py'> (None:None) ^api/caja/>]]}

During handling of the above exception, another exception occurred:

Traceback (most recent call last):
  File "D:\Project\redcashier\ve_redcashier\lib\site-packages\django\template\base.py", line 885, in _resolve_lookup
    current = current[bit]
TypeError: 'RegexURLResolver' object is not subscriptable

During handling of the above exception, another exception occurred:

Traceback (most recent call last):
  File "D:\Project\redcashier\ve_redcashier\lib\site-packages\django\template\base.py", line 893, in _resolve_lookup
    current = getattr(current, bit)
AttributeError: 'RegexURLResolver' object has no attribute 'name'

During handling of the above exception, another exception occurred:

Traceback (most recent call last):
  File "D:\Project\redcashier\ve_redcashier\lib\site-packages\django\template\base.py", line 900, in _resolve_lookup
    current = current[int(bit)]
ValueError: invalid literal for int() with base 10: 'name'

During handling of the above exception, another exception occurred:

Traceback (most recent call last):
  File "D:\Project\redcashier\ve_redcashier\lib\site-packages\django\template\base.py", line 907, in _resolve_lookup
    (bit, current))  # missing attribute
django.template.base.VariableDoesNotExist: Failed lookup for key [name] in "<RegexURLResolver <module 'redcashier_service_apps.catalogo_api.urls' from 'D:\\\\Project\\\\redcashier\\\\redcashier_service\\\\redcashier_service_apps\\\\catalogo_api\\\\urls.py'> (None:None) ^api/catalogo/>"
[2016-11-16 04:54:31] DEBUG [django.template:929] Exception while resolving variable 'name' in template 'unknown'.
Traceback (most recent call last):
  File "D:\Project\redcashier\ve_redcashier\lib\site-packages\django\core\handlers\exception.py", line 39, in inner
    response = get_response(request)
  File "D:\Project\redcashier\ve_redcashier\lib\site-packages\django\core\handlers\base.py", line 249, in _legacy_get_response
    response = self._get_response(request)
  File "D:\Project\redcashier\ve_redcashier\lib\site-packages\django\core\handlers\base.py", line 172, in _get_response
    resolver_match = resolver.resolve(request.path_info)
  File "D:\Project\redcashier\ve_redcashier\lib\site-packages\django\urls\resolvers.py", line 300, in resolve
    raise Resolver404({'tried': tried, 'path': new_path})
django.urls.exceptions.Resolver404: {'path': '', 'tried': [[<RegexURLResolver <RegexURLPattern list> (admin:admin) ^admin/>], [<RegexURLResolver <module 'django.contrib.admindocs.urls' from 'D:\\Project\\redcashier\\ve_redcashier\\lib\\site-packages\\django\\contrib\\admindocs\\urls.py'> (None:None) ^admin/doc/>], [<RegexURLResolver <module 'rest_framework.urls' from 'D:\\Project\\redcashier\\ve_redcashier\\lib\\site-packages\\rest_framework\\urls.py'> (rest_framework:rest_framework) ^api-auth/>], [<RegexURLResolver <module 'oauth2_provider.urls' from 'D:\\Project\\redcashier\\ve_redcashier\\lib\\site-packages\\oauth2_provider\\urls.py'> (None:oauth2_provider) ^o/>], [<RegexURLResolver <module 'redcashier_service_apps.auths_api.urls' from 'D:\\Project\\redcashier\\redcashier_service\\redcashier_service_apps\\auths_api\\urls.py'> (None:None) ^api/auths/>], [<RegexURLResolver <module 'redcashier_service_apps.catalogo_api.urls' from 'D:\\Project\\redcashier\\redcashier_service\\redcashier_service_apps\\catalogo_api\\urls.py'> (None:None) ^api/catalogo/>], [<RegexURLResolver <module 'redcashier_service_apps.caja_api.urls' from 'D:\\Project\\redcashier\\redcashier_service\\redcashier_service_apps\\caja_api\\urls.py'> (None:None) ^api/caja/>]]}

During handling of the above exception, another exception occurred:

Traceback (most recent call last):
  File "D:\Project\redcashier\ve_redcashier\lib\site-packages\django\template\base.py", line 885, in _resolve_lookup
    current = current[bit]
TypeError: 'RegexURLResolver' object is not subscriptable

During handling of the above exception, another exception occurred:

Traceback (most recent call last):
  File "D:\Project\redcashier\ve_redcashier\lib\site-packages\django\template\base.py", line 893, in _resolve_lookup
    current = getattr(current, bit)
AttributeError: 'RegexURLResolver' object has no attribute 'name'

During handling of the above exception, another exception occurred:

Traceback (most recent call last):
  File "D:\Project\redcashier\ve_redcashier\lib\site-packages\django\template\base.py", line 900, in _resolve_lookup
    current = current[int(bit)]
ValueError: invalid literal for int() with base 10: 'name'

During handling of the above exception, another exception occurred:

Traceback (most recent call last):
  File "D:\Project\redcashier\ve_redcashier\lib\site-packages\django\template\base.py", line 907, in _resolve_lookup
    (bit, current))  # missing attribute
django.template.base.VariableDoesNotExist: Failed lookup for key [name] in "<RegexURLResolver <module 'redcashier_service_apps.caja_api.urls' from 'D:\\\\Project\\\\redcashier\\\\redcashier_service\\\\redcashier_service_apps\\\\caja_api\\\\urls.py'> (None:None) ^api/caja/>"
[2016-11-16 04:54:31] WARNING [django.request:152] Not Found: /
[2016-11-16 04:54:31] WARNING [django.server:131] "GET / HTTP/1.1" 404 2571
[2016-11-16 04:54:31] DEBUG [django.template:929] Exception while resolving variable 'name' in template 'unknown'.
Traceback (most recent call last):
  File "D:\Project\redcashier\ve_redcashier\lib\site-packages\django\core\handlers\exception.py", line 39, in inner
    response = get_response(request)
  File "D:\Project\redcashier\ve_redcashier\lib\site-packages\django\core\handlers\base.py", line 249, in _legacy_get_response
    response = self._get_response(request)
  File "D:\Project\redcashier\ve_redcashier\lib\site-packages\django\core\handlers\base.py", line 172, in _get_response
    resolver_match = resolver.resolve(request.path_info)
  File "D:\Project\redcashier\ve_redcashier\lib\site-packages\django\urls\resolvers.py", line 300, in resolve
    raise Resolver404({'tried': tried, 'path': new_path})
django.urls.exceptions.Resolver404: {'path': 'favicon.ico', 'tried': [[<RegexURLResolver <RegexURLPattern list> (admin:admin) ^admin/>], [<RegexURLResolver <module 'django.contrib.admindocs.urls' from 'D:\\Project\\redcashier\\ve_redcashier\\lib\\site-packages\\django\\contrib\\admindocs\\urls.py'> (None:None) ^admin/doc/>], [<RegexURLResolver <module 'rest_framework.urls' from 'D:\\Project\\redcashier\\ve_redcashier\\lib\\site-packages\\rest_framework\\urls.py'> (rest_framework:rest_framework) ^api-auth/>], [<RegexURLResolver <module 'oauth2_provider.urls' from 'D:\\Project\\redcashier\\ve_redcashier\\lib\\site-packages\\oauth2_provider\\urls.py'> (None:oauth2_provider) ^o/>], [<RegexURLResolver <module 'redcashier_service_apps.auths_api.urls' from 'D:\\Project\\redcashier\\redcashier_service\\redcashier_service_apps\\auths_api\\urls.py'> (None:None) ^api/auths/>], [<RegexURLResolver <module 'redcashier_service_apps.catalogo_api.urls' from 'D:\\Project\\redcashier\\redcashier_service\\redcashier_service_apps\\catalogo_api\\urls.py'> (None:None) ^api/catalogo/>], [<RegexURLResolver <module 'redcashier_service_apps.caja_api.urls' from 'D:\\Project\\redcashier\\redcashier_service\\redcashier_service_apps\\caja_api\\urls.py'> (None:None) ^api/caja/>]]}

During handling of the above exception, another exception occurred:

Traceback (most recent call last):
  File "D:\Project\redcashier\ve_redcashier\lib\site-packages\django\template\base.py", line 885, in _resolve_lookup
    current = current[bit]
TypeError: 'RegexURLResolver' object is not subscriptable

During handling of the above exception, another exception occurred:

Traceback (most recent call last):
  File "D:\Project\redcashier\ve_redcashier\lib\site-packages\django\template\base.py", line 893, in _resolve_lookup
    current = getattr(current, bit)
AttributeError: 'RegexURLResolver' object has no attribute 'name'

During handling of the above exception, another exception occurred:

Traceback (most recent call last):
  File "D:\Project\redcashier\ve_redcashier\lib\site-packages\django\template\base.py", line 900, in _resolve_lookup
    current = current[int(bit)]
ValueError: invalid literal for int() with base 10: 'name'

During handling of the above exception, another exception occurred:

Traceback (most recent call last):
  File "D:\Project\redcashier\ve_redcashier\lib\site-packages\django\template\base.py", line 907, in _resolve_lookup
    (bit, current))  # missing attribute
django.template.base.VariableDoesNotExist: Failed lookup for key [name] in '<RegexURLResolver <RegexURLPattern list> (admin:admin) ^admin/>'
[2016-11-16 04:54:31] DEBUG [django.template:929] Exception while resolving variable 'name' in template 'unknown'.
Traceback (most recent call last):
  File "D:\Project\redcashier\ve_redcashier\lib\site-packages\django\core\handlers\exception.py", line 39, in inner
    response = get_response(request)
  File "D:\Project\redcashier\ve_redcashier\lib\site-packages\django\core\handlers\base.py", line 249, in _legacy_get_response
    response = self._get_response(request)
  File "D:\Project\redcashier\ve_redcashier\lib\site-packages\django\core\handlers\base.py", line 172, in _get_response
    resolver_match = resolver.resolve(request.path_info)
  File "D:\Project\redcashier\ve_redcashier\lib\site-packages\django\urls\resolvers.py", line 300, in resolve
    raise Resolver404({'tried': tried, 'path': new_path})
django.urls.exceptions.Resolver404: {'path': 'favicon.ico', 'tried': [[<RegexURLResolver <RegexURLPattern list> (admin:admin) ^admin/>], [<RegexURLResolver <module 'django.contrib.admindocs.urls' from 'D:\\Project\\redcashier\\ve_redcashier\\lib\\site-packages\\django\\contrib\\admindocs\\urls.py'> (None:None) ^admin/doc/>], [<RegexURLResolver <module 'rest_framework.urls' from 'D:\\Project\\redcashier\\ve_redcashier\\lib\\site-packages\\rest_framework\\urls.py'> (rest_framework:rest_framework) ^api-auth/>], [<RegexURLResolver <module 'oauth2_provider.urls' from 'D:\\Project\\redcashier\\ve_redcashier\\lib\\site-packages\\oauth2_provider\\urls.py'> (None:oauth2_provider) ^o/>], [<RegexURLResolver <module 'redcashier_service_apps.auths_api.urls' from 'D:\\Project\\redcashier\\redcashier_service\\redcashier_service_apps\\auths_api\\urls.py'> (None:None) ^api/auths/>], [<RegexURLResolver <module 'redcashier_service_apps.catalogo_api.urls' from 'D:\\Project\\redcashier\\redcashier_service\\redcashier_service_apps\\catalogo_api\\urls.py'> (None:None) ^api/catalogo/>], [<RegexURLResolver <module 'redcashier_service_apps.caja_api.urls' from 'D:\\Project\\redcashier\\redcashier_service\\redcashier_service_apps\\caja_api\\urls.py'> (None:None) ^api/caja/>]]}

During handling of the above exception, another exception occurred:

Traceback (most recent call last):
  File "D:\Project\redcashier\ve_redcashier\lib\site-packages\django\template\base.py", line 885, in _resolve_lookup
    current = current[bit]
TypeError: 'RegexURLResolver' object is not subscriptable

During handling of the above exception, another exception occurred:

Traceback (most recent call last):
  File "D:\Project\redcashier\ve_redcashier\lib\site-packages\django\template\base.py", line 893, in _resolve_lookup
    current = getattr(current, bit)
AttributeError: 'RegexURLResolver' object has no attribute 'name'

During handling of the above exception, another exception occurred:

Traceback (most recent call last):
  File "D:\Project\redcashier\ve_redcashier\lib\site-packages\django\template\base.py", line 900, in _resolve_lookup
    current = current[int(bit)]
ValueError: invalid literal for int() with base 10: 'name'

During handling of the above exception, another exception occurred:

Traceback (most recent call last):
  File "D:\Project\redcashier\ve_redcashier\lib\site-packages\django\template\base.py", line 907, in _resolve_lookup
    (bit, current))  # missing attribute
django.template.base.VariableDoesNotExist: Failed lookup for key [name] in "<RegexURLResolver <module 'django.contrib.admindocs.urls' from 'D:\\\\Project\\\\redcashier\\\\ve_redcashier\\\\lib\\\\site-packages\\\\django\\\\contrib\\\\admindocs\\\\urls.py'> (None:None) ^admin/doc/>"
[2016-11-16 04:54:31] DEBUG [django.template:929] Exception while resolving variable 'name' in template 'unknown'.
Traceback (most recent call last):
  File "D:\Project\redcashier\ve_redcashier\lib\site-packages\django\core\handlers\exception.py", line 39, in inner
    response = get_response(request)
  File "D:\Project\redcashier\ve_redcashier\lib\site-packages\django\core\handlers\base.py", line 249, in _legacy_get_response
    response = self._get_response(request)
  File "D:\Project\redcashier\ve_redcashier\lib\site-packages\django\core\handlers\base.py", line 172, in _get_response
    resolver_match = resolver.resolve(request.path_info)
  File "D:\Project\redcashier\ve_redcashier\lib\site-packages\django\urls\resolvers.py", line 300, in resolve
    raise Resolver404({'tried': tried, 'path': new_path})
django.urls.exceptions.Resolver404: {'path': 'favicon.ico', 'tried': [[<RegexURLResolver <RegexURLPattern list> (admin:admin) ^admin/>], [<RegexURLResolver <module 'django.contrib.admindocs.urls' from 'D:\\Project\\redcashier\\ve_redcashier\\lib\\site-packages\\django\\contrib\\admindocs\\urls.py'> (None:None) ^admin/doc/>], [<RegexURLResolver <module 'rest_framework.urls' from 'D:\\Project\\redcashier\\ve_redcashier\\lib\\site-packages\\rest_framework\\urls.py'> (rest_framework:rest_framework) ^api-auth/>], [<RegexURLResolver <module 'oauth2_provider.urls' from 'D:\\Project\\redcashier\\ve_redcashier\\lib\\site-packages\\oauth2_provider\\urls.py'> (None:oauth2_provider) ^o/>], [<RegexURLResolver <module 'redcashier_service_apps.auths_api.urls' from 'D:\\Project\\redcashier\\redcashier_service\\redcashier_service_apps\\auths_api\\urls.py'> (None:None) ^api/auths/>], [<RegexURLResolver <module 'redcashier_service_apps.catalogo_api.urls' from 'D:\\Project\\redcashier\\redcashier_service\\redcashier_service_apps\\catalogo_api\\urls.py'> (None:None) ^api/catalogo/>], [<RegexURLResolver <module 'redcashier_service_apps.caja_api.urls' from 'D:\\Project\\redcashier\\redcashier_service\\redcashier_service_apps\\caja_api\\urls.py'> (None:None) ^api/caja/>]]}

During handling of the above exception, another exception occurred:

Traceback (most recent call last):
  File "D:\Project\redcashier\ve_redcashier\lib\site-packages\django\template\base.py", line 885, in _resolve_lookup
    current = current[bit]
TypeError: 'RegexURLResolver' object is not subscriptable

During handling of the above exception, another exception occurred:

Traceback (most recent call last):
  File "D:\Project\redcashier\ve_redcashier\lib\site-packages\django\template\base.py", line 893, in _resolve_lookup
    current = getattr(current, bit)
AttributeError: 'RegexURLResolver' object has no attribute 'name'

During handling of the above exception, another exception occurred:

Traceback (most recent call last):
  File "D:\Project\redcashier\ve_redcashier\lib\site-packages\django\template\base.py", line 900, in _resolve_lookup
    current = current[int(bit)]
ValueError: invalid literal for int() with base 10: 'name'

During handling of the above exception, another exception occurred:

Traceback (most recent call last):
  File "D:\Project\redcashier\ve_redcashier\lib\site-packages\django\template\base.py", line 907, in _resolve_lookup
    (bit, current))  # missing attribute
django.template.base.VariableDoesNotExist: Failed lookup for key [name] in "<RegexURLResolver <module 'rest_framework.urls' from 'D:\\\\Project\\\\redcashier\\\\ve_redcashier\\\\lib\\\\site-packages\\\\rest_framework\\\\urls.py'> (rest_framework:rest_framework) ^api-auth/>"
[2016-11-16 04:54:31] DEBUG [django.template:929] Exception while resolving variable 'name' in template 'unknown'.
Traceback (most recent call last):
  File "D:\Project\redcashier\ve_redcashier\lib\site-packages\django\core\handlers\exception.py", line 39, in inner
    response = get_response(request)
  File "D:\Project\redcashier\ve_redcashier\lib\site-packages\django\core\handlers\base.py", line 249, in _legacy_get_response
    response = self._get_response(request)
  File "D:\Project\redcashier\ve_redcashier\lib\site-packages\django\core\handlers\base.py", line 172, in _get_response
    resolver_match = resolver.resolve(request.path_info)
  File "D:\Project\redcashier\ve_redcashier\lib\site-packages\django\urls\resolvers.py", line 300, in resolve
    raise Resolver404({'tried': tried, 'path': new_path})
django.urls.exceptions.Resolver404: {'path': 'favicon.ico', 'tried': [[<RegexURLResolver <RegexURLPattern list> (admin:admin) ^admin/>], [<RegexURLResolver <module 'django.contrib.admindocs.urls' from 'D:\\Project\\redcashier\\ve_redcashier\\lib\\site-packages\\django\\contrib\\admindocs\\urls.py'> (None:None) ^admin/doc/>], [<RegexURLResolver <module 'rest_framework.urls' from 'D:\\Project\\redcashier\\ve_redcashier\\lib\\site-packages\\rest_framework\\urls.py'> (rest_framework:rest_framework) ^api-auth/>], [<RegexURLResolver <module 'oauth2_provider.urls' from 'D:\\Project\\redcashier\\ve_redcashier\\lib\\site-packages\\oauth2_provider\\urls.py'> (None:oauth2_provider) ^o/>], [<RegexURLResolver <module 'redcashier_service_apps.auths_api.urls' from 'D:\\Project\\redcashier\\redcashier_service\\redcashier_service_apps\\auths_api\\urls.py'> (None:None) ^api/auths/>], [<RegexURLResolver <module 'redcashier_service_apps.catalogo_api.urls' from 'D:\\Project\\redcashier\\redcashier_service\\redcashier_service_apps\\catalogo_api\\urls.py'> (None:None) ^api/catalogo/>], [<RegexURLResolver <module 'redcashier_service_apps.caja_api.urls' from 'D:\\Project\\redcashier\\redcashier_service\\redcashier_service_apps\\caja_api\\urls.py'> (None:None) ^api/caja/>]]}

During handling of the above exception, another exception occurred:

Traceback (most recent call last):
  File "D:\Project\redcashier\ve_redcashier\lib\site-packages\django\template\base.py", line 885, in _resolve_lookup
    current = current[bit]
TypeError: 'RegexURLResolver' object is not subscriptable

During handling of the above exception, another exception occurred:

Traceback (most recent call last):
  File "D:\Project\redcashier\ve_redcashier\lib\site-packages\django\template\base.py", line 893, in _resolve_lookup
    current = getattr(current, bit)
AttributeError: 'RegexURLResolver' object has no attribute 'name'

During handling of the above exception, another exception occurred:

Traceback (most recent call last):
  File "D:\Project\redcashier\ve_redcashier\lib\site-packages\django\template\base.py", line 900, in _resolve_lookup
    current = current[int(bit)]
ValueError: invalid literal for int() with base 10: 'name'

During handling of the above exception, another exception occurred:

Traceback (most recent call last):
  File "D:\Project\redcashier\ve_redcashier\lib\site-packages\django\template\base.py", line 907, in _resolve_lookup
    (bit, current))  # missing attribute
django.template.base.VariableDoesNotExist: Failed lookup for key [name] in "<RegexURLResolver <module 'oauth2_provider.urls' from 'D:\\\\Project\\\\redcashier\\\\ve_redcashier\\\\lib\\\\site-packages\\\\oauth2_provider\\\\urls.py'> (None:oauth2_provider) ^o/>"
[2016-11-16 04:54:31] DEBUG [django.template:929] Exception while resolving variable 'name' in template 'unknown'.
Traceback (most recent call last):
  File "D:\Project\redcashier\ve_redcashier\lib\site-packages\django\core\handlers\exception.py", line 39, in inner
    response = get_response(request)
  File "D:\Project\redcashier\ve_redcashier\lib\site-packages\django\core\handlers\base.py", line 249, in _legacy_get_response
    response = self._get_response(request)
  File "D:\Project\redcashier\ve_redcashier\lib\site-packages\django\core\handlers\base.py", line 172, in _get_response
    resolver_match = resolver.resolve(request.path_info)
  File "D:\Project\redcashier\ve_redcashier\lib\site-packages\django\urls\resolvers.py", line 300, in resolve
    raise Resolver404({'tried': tried, 'path': new_path})
django.urls.exceptions.Resolver404: {'path': 'favicon.ico', 'tried': [[<RegexURLResolver <RegexURLPattern list> (admin:admin) ^admin/>], [<RegexURLResolver <module 'django.contrib.admindocs.urls' from 'D:\\Project\\redcashier\\ve_redcashier\\lib\\site-packages\\django\\contrib\\admindocs\\urls.py'> (None:None) ^admin/doc/>], [<RegexURLResolver <module 'rest_framework.urls' from 'D:\\Project\\redcashier\\ve_redcashier\\lib\\site-packages\\rest_framework\\urls.py'> (rest_framework:rest_framework) ^api-auth/>], [<RegexURLResolver <module 'oauth2_provider.urls' from 'D:\\Project\\redcashier\\ve_redcashier\\lib\\site-packages\\oauth2_provider\\urls.py'> (None:oauth2_provider) ^o/>], [<RegexURLResolver <module 'redcashier_service_apps.auths_api.urls' from 'D:\\Project\\redcashier\\redcashier_service\\redcashier_service_apps\\auths_api\\urls.py'> (None:None) ^api/auths/>], [<RegexURLResolver <module 'redcashier_service_apps.catalogo_api.urls' from 'D:\\Project\\redcashier\\redcashier_service\\redcashier_service_apps\\catalogo_api\\urls.py'> (None:None) ^api/catalogo/>], [<RegexURLResolver <module 'redcashier_service_apps.caja_api.urls' from 'D:\\Project\\redcashier\\redcashier_service\\redcashier_service_apps\\caja_api\\urls.py'> (None:None) ^api/caja/>]]}

During handling of the above exception, another exception occurred:

Traceback (most recent call last):
  File "D:\Project\redcashier\ve_redcashier\lib\site-packages\django\template\base.py", line 885, in _resolve_lookup
    current = current[bit]
TypeError: 'RegexURLResolver' object is not subscriptable

During handling of the above exception, another exception occurred:

Traceback (most recent call last):
  File "D:\Project\redcashier\ve_redcashier\lib\site-packages\django\template\base.py", line 893, in _resolve_lookup
    current = getattr(current, bit)
AttributeError: 'RegexURLResolver' object has no attribute 'name'

During handling of the above exception, another exception occurred:

Traceback (most recent call last):
  File "D:\Project\redcashier\ve_redcashier\lib\site-packages\django\template\base.py", line 900, in _resolve_lookup
    current = current[int(bit)]
ValueError: invalid literal for int() with base 10: 'name'

During handling of the above exception, another exception occurred:

Traceback (most recent call last):
  File "D:\Project\redcashier\ve_redcashier\lib\site-packages\django\template\base.py", line 907, in _resolve_lookup
    (bit, current))  # missing attribute
django.template.base.VariableDoesNotExist: Failed lookup for key [name] in "<RegexURLResolver <module 'redcashier_service_apps.auths_api.urls' from 'D:\\\\Project\\\\redcashier\\\\redcashier_service\\\\redcashier_service_apps\\\\auths_api\\\\urls.py'> (None:None) ^api/auths/>"
[2016-11-16 04:54:31] DEBUG [django.template:929] Exception while resolving variable 'name' in template 'unknown'.
Traceback (most recent call last):
  File "D:\Project\redcashier\ve_redcashier\lib\site-packages\django\core\handlers\exception.py", line 39, in inner
    response = get_response(request)
  File "D:\Project\redcashier\ve_redcashier\lib\site-packages\django\core\handlers\base.py", line 249, in _legacy_get_response
    response = self._get_response(request)
  File "D:\Project\redcashier\ve_redcashier\lib\site-packages\django\core\handlers\base.py", line 172, in _get_response
    resolver_match = resolver.resolve(request.path_info)
  File "D:\Project\redcashier\ve_redcashier\lib\site-packages\django\urls\resolvers.py", line 300, in resolve
    raise Resolver404({'tried': tried, 'path': new_path})
django.urls.exceptions.Resolver404: {'path': 'favicon.ico', 'tried': [[<RegexURLResolver <RegexURLPattern list> (admin:admin) ^admin/>], [<RegexURLResolver <module 'django.contrib.admindocs.urls' from 'D:\\Project\\redcashier\\ve_redcashier\\lib\\site-packages\\django\\contrib\\admindocs\\urls.py'> (None:None) ^admin/doc/>], [<RegexURLResolver <module 'rest_framework.urls' from 'D:\\Project\\redcashier\\ve_redcashier\\lib\\site-packages\\rest_framework\\urls.py'> (rest_framework:rest_framework) ^api-auth/>], [<RegexURLResolver <module 'oauth2_provider.urls' from 'D:\\Project\\redcashier\\ve_redcashier\\lib\\site-packages\\oauth2_provider\\urls.py'> (None:oauth2_provider) ^o/>], [<RegexURLResolver <module 'redcashier_service_apps.auths_api.urls' from 'D:\\Project\\redcashier\\redcashier_service\\redcashier_service_apps\\auths_api\\urls.py'> (None:None) ^api/auths/>], [<RegexURLResolver <module 'redcashier_service_apps.catalogo_api.urls' from 'D:\\Project\\redcashier\\redcashier_service\\redcashier_service_apps\\catalogo_api\\urls.py'> (None:None) ^api/catalogo/>], [<RegexURLResolver <module 'redcashier_service_apps.caja_api.urls' from 'D:\\Project\\redcashier\\redcashier_service\\redcashier_service_apps\\caja_api\\urls.py'> (None:None) ^api/caja/>]]}

During handling of the above exception, another exception occurred:

Traceback (most recent call last):
  File "D:\Project\redcashier\ve_redcashier\lib\site-packages\django\template\base.py", line 885, in _resolve_lookup
    current = current[bit]
TypeError: 'RegexURLResolver' object is not subscriptable

During handling of the above exception, another exception occurred:

Traceback (most recent call last):
  File "D:\Project\redcashier\ve_redcashier\lib\site-packages\django\template\base.py", line 893, in _resolve_lookup
    current = getattr(current, bit)
AttributeError: 'RegexURLResolver' object has no attribute 'name'

During handling of the above exception, another exception occurred:

Traceback (most recent call last):
  File "D:\Project\redcashier\ve_redcashier\lib\site-packages\django\template\base.py", line 900, in _resolve_lookup
    current = current[int(bit)]
ValueError: invalid literal for int() with base 10: 'name'

During handling of the above exception, another exception occurred:

Traceback (most recent call last):
  File "D:\Project\redcashier\ve_redcashier\lib\site-packages\django\template\base.py", line 907, in _resolve_lookup
    (bit, current))  # missing attribute
django.template.base.VariableDoesNotExist: Failed lookup for key [name] in "<RegexURLResolver <module 'redcashier_service_apps.catalogo_api.urls' from 'D:\\\\Project\\\\redcashier\\\\redcashier_service\\\\redcashier_service_apps\\\\catalogo_api\\\\urls.py'> (None:None) ^api/catalogo/>"
[2016-11-16 04:54:31] DEBUG [django.template:929] Exception while resolving variable 'name' in template 'unknown'.
Traceback (most recent call last):
  File "D:\Project\redcashier\ve_redcashier\lib\site-packages\django\core\handlers\exception.py", line 39, in inner
    response = get_response(request)
  File "D:\Project\redcashier\ve_redcashier\lib\site-packages\django\core\handlers\base.py", line 249, in _legacy_get_response
    response = self._get_response(request)
  File "D:\Project\redcashier\ve_redcashier\lib\site-packages\django\core\handlers\base.py", line 172, in _get_response
    resolver_match = resolver.resolve(request.path_info)
  File "D:\Project\redcashier\ve_redcashier\lib\site-packages\django\urls\resolvers.py", line 300, in resolve
    raise Resolver404({'tried': tried, 'path': new_path})
django.urls.exceptions.Resolver404: {'path': 'favicon.ico', 'tried': [[<RegexURLResolver <RegexURLPattern list> (admin:admin) ^admin/>], [<RegexURLResolver <module 'django.contrib.admindocs.urls' from 'D:\\Project\\redcashier\\ve_redcashier\\lib\\site-packages\\django\\contrib\\admindocs\\urls.py'> (None:None) ^admin/doc/>], [<RegexURLResolver <module 'rest_framework.urls' from 'D:\\Project\\redcashier\\ve_redcashier\\lib\\site-packages\\rest_framework\\urls.py'> (rest_framework:rest_framework) ^api-auth/>], [<RegexURLResolver <module 'oauth2_provider.urls' from 'D:\\Project\\redcashier\\ve_redcashier\\lib\\site-packages\\oauth2_provider\\urls.py'> (None:oauth2_provider) ^o/>], [<RegexURLResolver <module 'redcashier_service_apps.auths_api.urls' from 'D:\\Project\\redcashier\\redcashier_service\\redcashier_service_apps\\auths_api\\urls.py'> (None:None) ^api/auths/>], [<RegexURLResolver <module 'redcashier_service_apps.catalogo_api.urls' from 'D:\\Project\\redcashier\\redcashier_service\\redcashier_service_apps\\catalogo_api\\urls.py'> (None:None) ^api/catalogo/>], [<RegexURLResolver <module 'redcashier_service_apps.caja_api.urls' from 'D:\\Project\\redcashier\\redcashier_service\\redcashier_service_apps\\caja_api\\urls.py'> (None:None) ^api/caja/>]]}

During handling of the above exception, another exception occurred:

Traceback (most recent call last):
  File "D:\Project\redcashier\ve_redcashier\lib\site-packages\django\template\base.py", line 885, in _resolve_lookup
    current = current[bit]
TypeError: 'RegexURLResolver' object is not subscriptable

During handling of the above exception, another exception occurred:

Traceback (most recent call last):
  File "D:\Project\redcashier\ve_redcashier\lib\site-packages\django\template\base.py", line 893, in _resolve_lookup
    current = getattr(current, bit)
AttributeError: 'RegexURLResolver' object has no attribute 'name'

During handling of the above exception, another exception occurred:

Traceback (most recent call last):
  File "D:\Project\redcashier\ve_redcashier\lib\site-packages\django\template\base.py", line 900, in _resolve_lookup
    current = current[int(bit)]
ValueError: invalid literal for int() with base 10: 'name'

During handling of the above exception, another exception occurred:

Traceback (most recent call last):
  File "D:\Project\redcashier\ve_redcashier\lib\site-packages\django\template\base.py", line 907, in _resolve_lookup
    (bit, current))  # missing attribute
django.template.base.VariableDoesNotExist: Failed lookup for key [name] in "<RegexURLResolver <module 'redcashier_service_apps.caja_api.urls' from 'D:\\\\Project\\\\redcashier\\\\redcashier_service\\\\redcashier_service_apps\\\\caja_api\\\\urls.py'> (None:None) ^api/caja/>"
[2016-11-16 04:54:31] WARNING [django.request:152] Not Found: /favicon.ico
[2016-11-16 04:54:31] WARNING [django.server:131] "GET /favicon.ico HTTP/1.1" 404 2604
[2016-11-16 04:54:40] INFO [django.server:131] "GET /admin/ HTTP/1.1" 302 0
[2016-11-16 04:54:40] DEBUG [django.template:929] Exception while resolving variable 'is_popup' in template 'admin/login.html'.
Traceback (most recent call last):
  File "D:\Project\redcashier\ve_redcashier\lib\site-packages\django\template\base.py", line 885, in _resolve_lookup
    current = current[bit]
  File "D:\Project\redcashier\ve_redcashier\lib\site-packages\django\template\context.py", line 75, in __getitem__
    raise KeyError(key)
KeyError: 'is_popup'

During handling of the above exception, another exception occurred:

Traceback (most recent call last):
  File "D:\Project\redcashier\ve_redcashier\lib\site-packages\django\template\base.py", line 891, in _resolve_lookup
    if isinstance(current, BaseContext) and getattr(type(current), bit):
AttributeError: type object 'RequestContext' has no attribute 'is_popup'

During handling of the above exception, another exception occurred:

Traceback (most recent call last):
  File "D:\Project\redcashier\ve_redcashier\lib\site-packages\django\template\base.py", line 900, in _resolve_lookup
    current = current[int(bit)]
ValueError: invalid literal for int() with base 10: 'is_popup'

During handling of the above exception, another exception occurred:

Traceback (most recent call last):
  File "D:\Project\redcashier\ve_redcashier\lib\site-packages\django\template\base.py", line 907, in _resolve_lookup
    (bit, current))  # missing attribute
django.template.base.VariableDoesNotExist: Failed lookup for key [is_popup] in "[{'None': None, 'True': True, 'False': False}, {'messages': <django.contrib.messages.storage.fallback.FallbackStorage object at 0x0545DD70>, 'DEFAULT_MESSAGE_LEVELS': {'ERROR': 40, 'DEBUG': 10, 'SUCCESS': 25, 'INFO': 20, 'WARNING': 30}, 'user': <SimpleLazyObject: <django.contrib.auth.models.AnonymousUser object at 0x04F97470>>, 'request': <WSGIRequest: GET '/admin/login/?next=/admin/'>, 'perms': <django.contrib.auth.context_processors.PermWrapper object at 0x054C7F30>, 'csrf_token': <SimpleLazyObject: <function csrf.<locals>._get_val at 0x04D48660>>}, {}, {'LANGUAGE_BIDI': False, 'next': '/admin/', 'site': <django.contrib.sites.requests.RequestSite object at 0x0545D550>, 'LANGUAGE_CODE': 'en-us', 'available_apps': [], 'username': '', 'app_path': '/admin/login/?next=/admin/', 'site_title': <django.utils.functional.lazy.<locals>.__proxy__ object at 0x03FDDB10>, 'title': 'Log in', 'site_name': 'localhost:9000', 'form': <AdminAuthenticationForm bound=False, valid=Unknown, fields=(username;password)>, 'site_url': '/', 'has_permission': False, 'site_header': <django.utils.functional.lazy.<locals>.__proxy__ object at 0x03FDDB70>}]"
[2016-11-16 04:54:40] DEBUG [django.template:929] Exception while resolving variable 'is_popup' in template 'admin/login.html'.
Traceback (most recent call last):
  File "D:\Project\redcashier\ve_redcashier\lib\site-packages\django\template\base.py", line 885, in _resolve_lookup
    current = current[bit]
  File "D:\Project\redcashier\ve_redcashier\lib\site-packages\django\template\context.py", line 75, in __getitem__
    raise KeyError(key)
KeyError: 'is_popup'

During handling of the above exception, another exception occurred:

Traceback (most recent call last):
  File "D:\Project\redcashier\ve_redcashier\lib\site-packages\django\template\base.py", line 891, in _resolve_lookup
    if isinstance(current, BaseContext) and getattr(type(current), bit):
AttributeError: type object 'RequestContext' has no attribute 'is_popup'

During handling of the above exception, another exception occurred:

Traceback (most recent call last):
  File "D:\Project\redcashier\ve_redcashier\lib\site-packages\django\template\base.py", line 900, in _resolve_lookup
    current = current[int(bit)]
ValueError: invalid literal for int() with base 10: 'is_popup'

During handling of the above exception, another exception occurred:

Traceback (most recent call last):
  File "D:\Project\redcashier\ve_redcashier\lib\site-packages\django\template\base.py", line 907, in _resolve_lookup
    (bit, current))  # missing attribute
django.template.base.VariableDoesNotExist: Failed lookup for key [is_popup] in "[{'None': None, 'True': True, 'False': False}, {'messages': <django.contrib.messages.storage.fallback.FallbackStorage object at 0x0545DD70>, 'DEFAULT_MESSAGE_LEVELS': {'ERROR': 40, 'DEBUG': 10, 'SUCCESS': 25, 'INFO': 20, 'WARNING': 30}, 'user': <SimpleLazyObject: <django.contrib.auth.models.AnonymousUser object at 0x04F97470>>, 'request': <WSGIRequest: GET '/admin/login/?next=/admin/'>, 'perms': <django.contrib.auth.context_processors.PermWrapper object at 0x054C7F30>, 'csrf_token': <SimpleLazyObject: <function csrf.<locals>._get_val at 0x04D48660>>}, {}, {'LANGUAGE_BIDI': False, 'next': '/admin/', 'site': <django.contrib.sites.requests.RequestSite object at 0x0545D550>, 'LANGUAGE_CODE': 'en-us', 'available_apps': [], 'username': '', 'app_path': '/admin/login/?next=/admin/', 'site_title': <django.utils.functional.lazy.<locals>.__proxy__ object at 0x03FDDB10>, 'title': 'Log in', 'site_name': 'localhost:9000', 'form': <AdminAuthenticationForm bound=False, valid=Unknown, fields=(username;password)>, 'site_url': '/', 'has_permission': False, 'site_header': <django.utils.functional.lazy.<locals>.__proxy__ object at 0x03FDDB70>}]"
[2016-11-16 04:54:40] INFO [django.server:131] "GET /admin/login/?next=/admin/ HTTP/1.1" 200 1658
[2016-11-16 04:54:41] INFO [django.server:131] "GET /static/admin/css/login.css HTTP/1.1" 200 1203
[2016-11-16 04:54:41] INFO [django.server:131] "GET /static/admin/css/base.css HTTP/1.1" 200 15937
[2016-11-16 04:54:41] INFO [django.server:131] "GET /static/admin/css/fonts.css HTTP/1.1" 200 423
[2016-11-16 04:54:41] INFO [django.server:131] "GET /static/admin/fonts/Roboto-Regular-webfont.woff HTTP/1.1" 200 80304
[2016-11-16 04:54:41] INFO [django.server:131] "GET /static/admin/fonts/Roboto-Light-webfont.woff HTTP/1.1" 200 81348
[2016-11-16 04:54:50] DEBUG [django.db.backends:90] (0.006) SELECT "auths_menu"."router_json" FROM "auths_menu" ORDER BY "auths_menu"."pos" ASC; args=()
[2016-11-16 04:54:50] INFO [django.server:131] "GET /api/auths/routers/ HTTP/1.1" 200 2
[2016-11-16 04:55:08] DEBUG [django.db.backends:90] (0.002) 
            SELECT name, type FROM sqlite_master
            WHERE type in ('table', 'view') AND NOT name='sqlite_sequence'
            ORDER BY name; args=None
[2016-11-16 04:55:08] DEBUG [django.db.backends:90] (0.000) SELECT "django_migrations"."app", "django_migrations"."name" FROM "django_migrations"; args=()
[2016-11-16 04:55:12] DEBUG [django.db.backends:90] (0.001) SELECT "auths_user"."password", "auths_user"."last_login", "auths_user"."is_superuser", "auths_user"."username", "auths_user"."first_name", "auths_user"."last_name", "auths_user"."email", "auths_user"."is_staff", "auths_user"."is_active", "auths_user"."date_joined", "auths_user"."id", "auths_user"."last_hierarchy_id", "auths_user"."last_module_id", "auths_user"."person_id", "auths_user"."updated_at", "auths_user"."registered_by" FROM "auths_user" WHERE "auths_user"."username" = 'sal'; args=('sal',)
[2016-11-16 04:55:27] DEBUG [django.db.backends:90] (0.001) SELECT "auths_user"."password", "auths_user"."last_login", "auths_user"."is_superuser", "auths_user"."username", "auths_user"."first_name", "auths_user"."last_name", "auths_user"."email", "auths_user"."is_staff", "auths_user"."is_active", "auths_user"."date_joined", "auths_user"."id", "auths_user"."last_hierarchy_id", "auths_user"."last_module_id", "auths_user"."person_id", "auths_user"."updated_at", "auths_user"."registered_by" FROM "auths_user" WHERE "auths_user"."username" = 'salva'; args=('salva',)
[2016-11-16 04:55:44] DEBUG [django.db.backends:90] (0.001) BEGIN; args=None
[2016-11-16 04:55:44] DEBUG [django.db.backends:90] (0.000) UPDATE "auths_user" SET "password" = 'pbkdf2_sha256$30000$sr6SvZti5eeO$ZZ934yRDmNhaS7vsTDO3/4YrkVVqPkLjqLQCQ68vccc=', "last_login" = NULL, "is_superuser" = 1, "username" = 'salva', "first_name" = '', "last_name" = '', "email" = '', "is_staff" = 1, "is_active" = 1, "date_joined" = '2016-11-16 10:55:44.132143', "last_hierarchy_id" = NULL, "last_module_id" = NULL, "person_id" = NULL, "updated_at" = '2016-11-16 10:55:44.204197', "registered_by" = NULL WHERE "auths_user"."id" = '0cd3cfbbe0484ece9727ec97c3b65b0f'; args=('pbkdf2_sha256$30000$sr6SvZti5eeO$ZZ934yRDmNhaS7vsTDO3/4YrkVVqPkLjqLQCQ68vccc=', True, 'salva', '', '', '', True, True, '2016-11-16 10:55:44.132143', '2016-11-16 10:55:44.204197', '0cd3cfbbe0484ece9727ec97c3b65b0f')
[2016-11-16 04:55:44] DEBUG [django.db.backends:90] (0.001) INSERT INTO "auths_user" ("password", "last_login", "is_superuser", "username", "first_name", "last_name", "email", "is_staff", "is_active", "date_joined", "id", "last_hierarchy_id", "last_module_id", "person_id", "updated_at", "registered_by") SELECT 'pbkdf2_sha256$30000$sr6SvZti5eeO$ZZ934yRDmNhaS7vsTDO3/4YrkVVqPkLjqLQCQ68vccc=', NULL, 1, 'salva', '', '', '', 1, 1, '2016-11-16 10:55:44.132143', '0cd3cfbbe0484ece9727ec97c3b65b0f', NULL, NULL, NULL, '2016-11-16 10:55:44.206199', NULL; args=('pbkdf2_sha256$30000$sr6SvZti5eeO$ZZ934yRDmNhaS7vsTDO3/4YrkVVqPkLjqLQCQ68vccc=', None, True, 'salva', '', '', '', True, True, '2016-11-16 10:55:44.132143', '0cd3cfbbe0484ece9727ec97c3b65b0f', None, None, None, '2016-11-16 10:55:44.206199', None)
[2016-11-16 04:55:56] DEBUG [django.db.backends:90] (0.002) 
            SELECT name, type FROM sqlite_master
            WHERE type in ('table', 'view') AND NOT name='sqlite_sequence'
            ORDER BY name; args=None
[2016-11-16 04:55:56] DEBUG [django.db.backends:90] (0.000) SELECT "django_migrations"."app", "django_migrations"."name" FROM "django_migrations"; args=()
[2016-11-16 04:56:01] DEBUG [django.template:929] Exception while resolving variable 'is_popup' in template 'admin/login.html'.
Traceback (most recent call last):
  File "D:\Project\redcashier\ve_redcashier\lib\site-packages\django\template\base.py", line 885, in _resolve_lookup
    current = current[bit]
  File "D:\Project\redcashier\ve_redcashier\lib\site-packages\django\template\context.py", line 75, in __getitem__
    raise KeyError(key)
KeyError: 'is_popup'

During handling of the above exception, another exception occurred:

Traceback (most recent call last):
  File "D:\Project\redcashier\ve_redcashier\lib\site-packages\django\template\base.py", line 891, in _resolve_lookup
    if isinstance(current, BaseContext) and getattr(type(current), bit):
AttributeError: type object 'RequestContext' has no attribute 'is_popup'

During handling of the above exception, another exception occurred:

Traceback (most recent call last):
  File "D:\Project\redcashier\ve_redcashier\lib\site-packages\django\template\base.py", line 900, in _resolve_lookup
    current = current[int(bit)]
ValueError: invalid literal for int() with base 10: 'is_popup'

During handling of the above exception, another exception occurred:

Traceback (most recent call last):
  File "D:\Project\redcashier\ve_redcashier\lib\site-packages\django\template\base.py", line 907, in _resolve_lookup
    (bit, current))  # missing attribute
django.template.base.VariableDoesNotExist: Failed lookup for key [is_popup] in "[{'True': True, 'None': None, 'False': False}, {'perms': <django.contrib.auth.context_processors.PermWrapper object at 0x04A86E70>, 'csrf_token': <SimpleLazyObject: <function csrf.<locals>._get_val at 0x047EF540>>, 'request': <WSGIRequest: GET '/admin/login/?next=/admin/'>, 'user': <SimpleLazyObject: <django.contrib.auth.models.AnonymousUser object at 0x04470250>>, 'DEFAULT_MESSAGE_LEVELS': {'ERROR': 40, 'INFO': 20, 'DEBUG': 10, 'WARNING': 30, 'SUCCESS': 25}, 'messages': <django.contrib.messages.storage.fallback.FallbackStorage object at 0x04457890>}, {}, {'app_path': '/admin/login/?next=/admin/', 'title': 'Log in', 'next': '/admin/', 'site_header': <django.utils.functional.lazy.<locals>.__proxy__ object at 0x03AADB70>, 'LANGUAGE_BIDI': False, 'site': <django.contrib.sites.requests.RequestSite object at 0x04A6E290>, 'LANGUAGE_CODE': 'en-us', 'available_apps': [], 'username': '', 'site_url': '/', 'has_permission': False, 'site_title': <django.utils.functional.lazy.<locals>.__proxy__ object at 0x03AADB10>, 'site_name': 'localhost:9000', 'form': <AdminAuthenticationForm bound=False, valid=Unknown, fields=(username;password)>}]"
[2016-11-16 04:56:02] DEBUG [django.template:929] Exception while resolving variable 'is_popup' in template 'admin/login.html'.
Traceback (most recent call last):
  File "D:\Project\redcashier\ve_redcashier\lib\site-packages\django\template\base.py", line 885, in _resolve_lookup
    current = current[bit]
  File "D:\Project\redcashier\ve_redcashier\lib\site-packages\django\template\context.py", line 75, in __getitem__
    raise KeyError(key)
KeyError: 'is_popup'

During handling of the above exception, another exception occurred:

Traceback (most recent call last):
  File "D:\Project\redcashier\ve_redcashier\lib\site-packages\django\template\base.py", line 891, in _resolve_lookup
    if isinstance(current, BaseContext) and getattr(type(current), bit):
AttributeError: type object 'RequestContext' has no attribute 'is_popup'

During handling of the above exception, another exception occurred:

Traceback (most recent call last):
  File "D:\Project\redcashier\ve_redcashier\lib\site-packages\django\template\base.py", line 900, in _resolve_lookup
    current = current[int(bit)]
ValueError: invalid literal for int() with base 10: 'is_popup'

During handling of the above exception, another exception occurred:

Traceback (most recent call last):
  File "D:\Project\redcashier\ve_redcashier\lib\site-packages\django\template\base.py", line 907, in _resolve_lookup
    (bit, current))  # missing attribute
django.template.base.VariableDoesNotExist: Failed lookup for key [is_popup] in "[{'True': True, 'None': None, 'False': False}, {'perms': <django.contrib.auth.context_processors.PermWrapper object at 0x04A86E70>, 'csrf_token': <SimpleLazyObject: <function csrf.<locals>._get_val at 0x047EF540>>, 'request': <WSGIRequest: GET '/admin/login/?next=/admin/'>, 'user': <SimpleLazyObject: <django.contrib.auth.models.AnonymousUser object at 0x04470250>>, 'DEFAULT_MESSAGE_LEVELS': {'ERROR': 40, 'INFO': 20, 'DEBUG': 10, 'WARNING': 30, 'SUCCESS': 25}, 'messages': <django.contrib.messages.storage.fallback.FallbackStorage object at 0x04457890>}, {}, {'app_path': '/admin/login/?next=/admin/', 'title': 'Log in', 'next': '/admin/', 'site_header': <django.utils.functional.lazy.<locals>.__proxy__ object at 0x03AADB70>, 'LANGUAGE_BIDI': False, 'site': <django.contrib.sites.requests.RequestSite object at 0x04A6E290>, 'LANGUAGE_CODE': 'en-us', 'available_apps': [], 'username': '', 'site_url': '/', 'has_permission': False, 'site_title': <django.utils.functional.lazy.<locals>.__proxy__ object at 0x03AADB10>, 'site_name': 'localhost:9000', 'form': <AdminAuthenticationForm bound=False, valid=Unknown, fields=(username;password)>}]"
[2016-11-16 04:56:02] INFO [django.server:131] "GET /admin/login/?next=/admin/ HTTP/1.1" 200 1658
[2016-11-16 04:56:02] INFO [django.server:131] "GET /static/admin/css/base.css HTTP/1.1" 304 0
[2016-11-16 04:56:02] INFO [django.server:131] "GET /static/admin/css/login.css HTTP/1.1" 304 0
[2016-11-16 04:56:02] INFO [django.server:131] "GET /static/admin/css/fonts.css HTTP/1.1" 304 0
[2016-11-16 04:56:12] DEBUG [django.db.backends:90] (0.003) SELECT "auths_user"."password", "auths_user"."last_login", "auths_user"."is_superuser", "auths_user"."username", "auths_user"."first_name", "auths_user"."last_name", "auths_user"."email", "auths_user"."is_staff", "auths_user"."is_active", "auths_user"."date_joined", "auths_user"."id", "auths_user"."last_hierarchy_id", "auths_user"."last_module_id", "auths_user"."person_id", "auths_user"."updated_at", "auths_user"."registered_by" FROM "auths_user" WHERE "auths_user"."username" = 'sal'; args=('sal',)
[2016-11-16 04:56:13] DEBUG [django.db.backends:90] (0.017) SELECT (1) AS "a" FROM "django_session" WHERE "django_session"."session_key" = 'd1vf81ec5z4lcqysvk1whyweu3tqlv6m' LIMIT 1; args=('d1vf81ec5z4lcqysvk1whyweu3tqlv6m',)
[2016-11-16 04:56:13] DEBUG [django.db.backends:90] (0.000) BEGIN; args=None
[2016-11-16 04:56:13] DEBUG [django.db.backends:90] (0.002) INSERT INTO "django_session" ("session_key", "session_data", "expire_date") SELECT 'd1vf81ec5z4lcqysvk1whyweu3tqlv6m', 'YjQyNjUzMGM0ZTg1NjNmMDFhZTFiNGZkZmExODhjNWE3MTg2YmQ5Zjp7fQ==', '2016-11-30 10:56:13.033828'; args=('d1vf81ec5z4lcqysvk1whyweu3tqlv6m', 'YjQyNjUzMGM0ZTg1NjNmMDFhZTFiNGZkZmExODhjNWE3MTg2YmQ5Zjp7fQ==', '2016-11-30 10:56:13.033828')
[2016-11-16 04:56:13] DEBUG [django.db.backends:90] (0.000) BEGIN; args=None
[2016-11-16 04:56:13] DEBUG [django.db.backends:90] (0.007) UPDATE "auths_user" SET "last_login" = '2016-11-16 10:56:13.168728' WHERE "auths_user"."id" = 'b5095ea74ce147329f9b2a855bf8c53b'; args=('2016-11-16 10:56:13.168728', 'b5095ea74ce147329f9b2a855bf8c53b')
[2016-11-16 04:56:13] DEBUG [django.db.backends:90] (0.000) BEGIN; args=None
[2016-11-16 04:56:13] DEBUG [django.db.backends:90] (0.019) UPDATE "django_session" SET "session_data" = 'NTA1OTYwMDQ1NDNlOTg1MWY1NTk4OTM1YzE2NWNiYTBmMjBhZGU3Njp7Il9hdXRoX3VzZXJfaWQiOiJiNTA5NWVhNy00Y2UxLTQ3MzItOWY5Yi0yYTg1NWJmOGM1M2IiLCJfYXV0aF91c2VyX2JhY2tlbmQiOiJkamFuZ28uY29udHJpYi5hdXRoLmJhY2tlbmRzLk1vZGVsQmFja2VuZCIsIl9hdXRoX3VzZXJfaGFzaCI6ImFkNzk3ZGU2NzE1ZTU1MThhZTVjZmExODFmZGM0NjA1N2ViZWU3YjUifQ==', "expire_date" = '2016-11-30 10:56:13.326332' WHERE "django_session"."session_key" = 'd1vf81ec5z4lcqysvk1whyweu3tqlv6m'; args=('NTA1OTYwMDQ1NDNlOTg1MWY1NTk4OTM1YzE2NWNiYTBmMjBhZGU3Njp7Il9hdXRoX3VzZXJfaWQiOiJiNTA5NWVhNy00Y2UxLTQ3MzItOWY5Yi0yYTg1NWJmOGM1M2IiLCJfYXV0aF91c2VyX2JhY2tlbmQiOiJkamFuZ28uY29udHJpYi5hdXRoLmJhY2tlbmRzLk1vZGVsQmFja2VuZCIsIl9hdXRoX3VzZXJfaGFzaCI6ImFkNzk3ZGU2NzE1ZTU1MThhZTVjZmExODFmZGM0NjA1N2ViZWU3YjUifQ==', '2016-11-30 10:56:13.326332', 'd1vf81ec5z4lcqysvk1whyweu3tqlv6m')
[2016-11-16 04:56:13] INFO [django.server:131] "POST /admin/login/?next=/admin/ HTTP/1.1" 302 0
[2016-11-16 04:56:13] DEBUG [django.db.backends:90] (0.006) SELECT "django_session"."session_key", "django_session"."session_data", "django_session"."expire_date" FROM "django_session" WHERE ("django_session"."expire_date" > '2016-11-16 10:56:13.520570' AND "django_session"."session_key" = 'd1vf81ec5z4lcqysvk1whyweu3tqlv6m'); args=('2016-11-16 10:56:13.520570', 'd1vf81ec5z4lcqysvk1whyweu3tqlv6m')
[2016-11-16 04:56:13] DEBUG [django.db.backends:90] (0.000) SELECT "auths_user"."password", "auths_user"."last_login", "auths_user"."is_superuser", "auths_user"."username", "auths_user"."first_name", "auths_user"."last_name", "auths_user"."email", "auths_user"."is_staff", "auths_user"."is_active", "auths_user"."date_joined", "auths_user"."id", "auths_user"."last_hierarchy_id", "auths_user"."last_module_id", "auths_user"."person_id", "auths_user"."updated_at", "auths_user"."registered_by" FROM "auths_user" WHERE "auths_user"."id" = 'b5095ea74ce147329f9b2a855bf8c53b'; args=('b5095ea74ce147329f9b2a855bf8c53b',)
[2016-11-16 04:56:13] DEBUG [django.template:929] Exception while resolving variable 'is_popup' in template 'admin/index.html'.
Traceback (most recent call last):
  File "D:\Project\redcashier\ve_redcashier\lib\site-packages\django\template\base.py", line 885, in _resolve_lookup
    current = current[bit]
  File "D:\Project\redcashier\ve_redcashier\lib\site-packages\django\template\context.py", line 75, in __getitem__
    raise KeyError(key)
KeyError: 'is_popup'

During handling of the above exception, another exception occurred:

Traceback (most recent call last):
  File "D:\Project\redcashier\ve_redcashier\lib\site-packages\django\template\base.py", line 891, in _resolve_lookup
    if isinstance(current, BaseContext) and getattr(type(current), bit):
AttributeError: type object 'RequestContext' has no attribute 'is_popup'

During handling of the above exception, another exception occurred:

Traceback (most recent call last):
  File "D:\Project\redcashier\ve_redcashier\lib\site-packages\django\template\base.py", line 900, in _resolve_lookup
    current = current[int(bit)]
ValueError: invalid literal for int() with base 10: 'is_popup'

During handling of the above exception, another exception occurred:

Traceback (most recent call last):
  File "D:\Project\redcashier\ve_redcashier\lib\site-packages\django\template\base.py", line 907, in _resolve_lookup
    (bit, current))  # missing attribute
django.template.base.VariableDoesNotExist: Failed lookup for key [is_popup] in "[{'True': True, 'None': None, 'False': False}, {'perms': <django.contrib.auth.context_processors.PermWrapper object at 0x04A80670>, 'csrf_token': <SimpleLazyObject: <function csrf.<locals>._get_val at 0x04B50A50>>, 'request': <WSGIRequest: GET '/admin/'>, 'user': <SimpleLazyObject: <User: sal>>, 'DEFAULT_MESSAGE_LEVELS': {'ERROR': 40, 'INFO': 20, 'DEBUG': 10, 'WARNING': 30, 'SUCCESS': 25}, 'messages': <django.contrib.messages.storage.fallback.FallbackStorage object at 0x04A9FB70>}, {}, {'site_url': '/', 'has_permission': True, 'site_title': <django.utils.functional.lazy.<locals>.__proxy__ object at 0x03AADB10>, 'title': <django.utils.functional.lazy.<locals>.__proxy__ object at 0x03AADBD0>, 'site_header': <django.utils.functional.lazy.<locals>.__proxy__ object at 0x03AADB70>, 'LANGUAGE_BIDI': False, 'app_list': [{'app_url': '/admin/auth/', 'models': [{'perms': {'add': True, 'delete': True, 'change': True}, 'name': <django.utils.functional.lazy.<locals>.__proxy__ object at 0x04A9FA50>, 'admin_url': '/admin/auth/group/', 'add_url': '/admin/auth/group/add/', 'object_name': 'Group'}, {'perms': {'add': True, 'delete': True, 'change': True}, 'name': <django.utils.functional.lazy.<locals>.__proxy__ object at 0x04A9F590>, 'admin_url': '/admin/auth/permission/', 'add_url': '/admin/auth/permission/add/', 'object_name': 'Permission'}], 'name': <django.utils.functional.lazy.<locals>.__proxy__ object at 0x03AC2610>, 'app_label': 'auth', 'has_module_perms': True}, {'app_url': '/admin/auths/', 'models': [{'perms': {'add': True, 'delete': True, 'change': True}, 'name': <django.utils.functional.lazy.<locals>.__proxy__ object at 0x04A6EB10>, 'admin_url': '/admin/auths/hierarchytype/', 'add_url': '/admin/auths/hierarchytype/add/', 'object_name': 'HierarchyType'}, {'perms': {'add': True, 'delete': True, 'change': True}, 'name': <django.utils.functional.lazy.<locals>.__proxy__ object at 0x04A6EAF0>, 'admin_url': '/admin/auths/hierarchy/', 'add_url': '/admin/auths/hierarchy/add/', 'object_name': 'Hierarchy'}, {'perms': {'add': True, 'delete': True, 'change': True}, 'name': <django.utils.functional.lazy.<locals>.__proxy__ object at 0x04A6E590>, 'admin_url': '/admin/auths/menu/', 'add_url': '/admin/auths/menu/add/', 'object_name': 'Menu'}, {'perms': {'add': True, 'delete': True, 'change': True}, 'name': <django.utils.functional.lazy.<locals>.__proxy__ object at 0x04A9FAB0>, 'admin_url': '/admin/auths/person/', 'add_url': '/admin/auths/person/add/', 'object_name': 'Person'}, {'perms': {'add': True, 'delete': True, 'change': True}, 'name': <django.utils.functional.lazy.<locals>.__proxy__ object at 0x04A9F7B0>, 'admin_url': '/admin/auths/userhierarchygroup/', 'add_url': '/admin/auths/userhierarchygroup/add/', 'object_name': 'UserHierarchyGroup'}, {'perms': {'add': True, 'delete': True, 'change': True}, 'name': <django.utils.functional.lazy.<locals>.__proxy__ object at 0x04A9FA30>, 'admin_url': '/admin/auths/userhierarchypermission/', 'add_url': '/admin/auths/userhierarchypermission/add/', 'object_name': 'UserHierarchyPermission'}, {'perms': {'add': True, 'delete': True, 'change': True}, 'name': <django.utils.functional.lazy.<locals>.__proxy__ object at 0x04A9FCB0>, 'admin_url': '/admin/auths/user/', 'add_url': '/admin/auths/user/add/', 'object_name': 'User'}], 'name': 'Auths', 'app_label': 'auths', 'has_module_perms': True}, {'app_url': '/admin/caja/', 'models': [{'perms': {'add': True, 'delete': True, 'change': True}, 'name': 'Cajaingresos', 'admin_url': '/admin/caja/cajaingreso/', 'add_url': '/admin/caja/cajaingreso/add/', 'object_name': 'Cajaingreso'}, {'perms': {'add': True, 'delete': True, 'change': True}, 'name': 'Modcontables', 'admin_url': '/admin/caja/modcontable/', 'add_url': '/admin/caja/modcontable/add/', 'object_name': 'Modcontable'}, {'perms': {'add': True, 'delete': True, 'change': True}, 'name': 'Niveles', 'admin_url': '/admin/caja/nivel/', 'add_url': '/admin/caja/nivel/add/', 'object_name': 'Nivel'}, {'perms': {'add': True, 'delete': True, 'change': True}, 'name': 'PeriodoContables', 'admin_url': '/admin/caja/periodocontable/', 'add_url': '/admin/caja/periodocontable/add/', 'object_name': 'PeriodoContable'}, {'perms': {'add': True, 'delete': True, 'change': True}, 'name': 'Usercashiers', 'admin_url': '/admin/caja/usercashier/', 'add_url': '/admin/caja/usercashier/add/', 'object_name': 'Usercashier'}], 'name': 'Caja', 'app_label': 'caja', 'has_module_perms': True}, {'app_url': '/admin/catalogo/', 'models': [{'perms': {'add': True, 'delete': True, 'change': True}, 'name': 'Autores', 'admin_url': '/admin/catalogo/autor/', 'add_url': '/admin/catalogo/autor/add/', 'object_name': 'Autor'}, {'perms': {'add': True, 'delete': True, 'change': True}, 'name': 'Categorias', 'admin_url': '/admin/catalogo/categoria/', 'add_url': '/admin/catalogo/categoria/add/', 'object_name': 'Categoria'}, {'perms': {'add': True, 'delete': True, 'change': True}, 'name': 'Libros', 'admin_url': '/admin/catalogo/libro/', 'add_url': '/admin/catalogo/libro/add/', 'object_name': 'Libro'}], 'name': 'Catalogo', 'app_label': 'catalogo', 'has_module_perms': True}, {'app_url': '/admin/contenttypes/', 'models': [{'perms': {'add': True, 'delete': True, 'change': True}, 'name': <django.utils.functional.lazy.<locals>.__proxy__ object at 0x04A9F650>, 'admin_url': '/admin/contenttypes/contenttype/', 'add_url': '/admin/contenttypes/contenttype/add/', 'object_name': 'ContentType'}], 'name': <django.utils.functional.lazy.<locals>.__proxy__ object at 0x03AC2730>, 'app_label': 'contenttypes', 'has_module_perms': True}, {'app_url': '/admin/oauth2_provider/', 'models': [{'perms': {'add': True, 'delete': True, 'change': True}, 'name': <django.utils.functional.lazy.<locals>.__proxy__ object at 0x04A9F6D0>, 'admin_url': '/admin/oauth2_provider/accesstoken/', 'add_url': '/admin/oauth2_provider/accesstoken/add/', 'object_name': 'AccessToken'}, {'perms': {'add': True, 'delete': True, 'change': True}, 'name': <django.utils.functional.lazy.<locals>.__proxy__ object at 0x04A9F610>, 'admin_url': '/admin/oauth2_provider/application/', 'add_url': '/admin/oauth2_provider/application/add/', 'object_name': 'Application'}, {'perms': {'add': True, 'delete': True, 'change': True}, 'name': <django.utils.functional.lazy.<locals>.__proxy__ object at 0x04A9F630>, 'admin_url': '/admin/oauth2_provider/grant/', 'add_url': '/admin/oauth2_provider/grant/add/', 'object_name': 'Grant'}, {'perms': {'add': True, 'delete': True, 'change': True}, 'name': <django.utils.functional.lazy.<locals>.__proxy__ object at 0x04A9F990>, 'admin_url': '/admin/oauth2_provider/refreshtoken/', 'add_url': '/admin/oauth2_provider/refreshtoken/add/', 'object_name': 'RefreshToken'}], 'name': 'Django OAuth Toolkit', 'app_label': 'oauth2_provider', 'has_module_perms': True}], 'available_apps': [{'app_url': '/admin/auth/', 'models': [{'perms': {'add': True, 'delete': True, 'change': True}, 'name': <django.utils.functional.lazy.<locals>.__proxy__ object at 0x04A6EFB0>, 'admin_url': '/admin/auth/group/', 'add_url': '/admin/auth/group/add/', 'object_name': 'Group'}, {'perms': {'add': True, 'delete': True, 'change': True}, 'name': <django.utils.functional.lazy.<locals>.__proxy__ object at 0x04A6EE30>, 'admin_url': '/admin/auth/permission/', 'add_url': '/admin/auth/permission/add/', 'object_name': 'Permission'}], 'name': <django.utils.functional.lazy.<locals>.__proxy__ object at 0x03AC2610>, 'app_label': 'auth', 'has_module_perms': True}, {'app_url': '/admin/auths/', 'models': [{'perms': {'add': True, 'delete': True, 'change': True}, 'name': <django.utils.functional.lazy.<locals>.__proxy__ object at 0x04A86110>, 'admin_url': '/admin/auths/hierarchytype/', 'add_url': '/admin/auths/hierarchytype/add/', 'object_name': 'HierarchyType'}, {'perms': {'add': True, 'delete': True, 'change': True}, 'name': <django.utils.functional.lazy.<locals>.__proxy__ object at 0x04A86050>, 'admin_url': '/admin/auths/hierarchy/', 'add_url': '/admin/auths/hierarchy/add/', 'object_name': 'Hierarchy'}, {'perms': {'add': True, 'delete': True, 'change': True}, 'name': <django.utils.functional.lazy.<locals>.__proxy__ object at 0x04A86630>, 'admin_url': '/admin/auths/menu/', 'add_url': '/admin/auths/menu/add/', 'object_name': 'Menu'}, {'perms': {'add': True, 'delete': True, 'change': True}, 'name': <django.utils.functional.lazy.<locals>.__proxy__ object at 0x04A6EFF0>, 'admin_url': '/admin/auths/person/', 'add_url': '/admin/auths/person/add/', 'object_name': 'Person'}, {'perms': {'add': True, 'delete': True, 'change': True}, 'name': <django.utils.functional.lazy.<locals>.__proxy__ object at 0x04A86030>, 'admin_url': '/admin/auths/userhierarchygroup/', 'add_url': '/admin/auths/userhierarchygroup/add/', 'object_name': 'UserHierarchyGroup'}, {'perms': {'add': True, 'delete': True, 'change': True}, 'name': <django.utils.functional.lazy.<locals>.__proxy__ object at 0x04A6EDF0>, 'admin_url': '/admin/auths/userhierarchypermission/', 'add_url': '/admin/auths/userhierarchypermission/add/', 'object_name': 'UserHierarchyPermission'}, {'perms': {'add': True, 'delete': True, 'change': True}, 'name': <django.utils.functional.lazy.<locals>.__proxy__ object at 0x04A6EDD0>, 'admin_url': '/admin/auths/user/', 'add_url': '/admin/auths/user/add/', 'object_name': 'User'}], 'name': 'Auths', 'app_label': 'auths', 'has_module_perms': True}, {'app_url': '/admin/caja/', 'models': [{'perms': {'add': True, 'delete': True, 'change': True}, 'name': 'Cajaingresos', 'admin_url': '/admin/caja/cajaingreso/', 'add_url': '/admin/caja/cajaingreso/add/', 'object_name': 'Cajaingreso'}, {'perms': {'add': True, 'delete': True, 'change': True}, 'name': 'Modcontables', 'admin_url': '/admin/caja/modcontable/', 'add_url': '/admin/caja/modcontable/add/', 'object_name': 'Modcontable'}, {'perms': {'add': True, 'delete': True, 'change': True}, 'name': 'Niveles', 'admin_url': '/admin/caja/nivel/', 'add_url': '/admin/caja/nivel/add/', 'object_name': 'Nivel'}, {'perms': {'add': True, 'delete': True, 'change': True}, 'name': 'PeriodoContables', 'admin_url': '/admin/caja/periodocontable/', 'add_url': '/admin/caja/periodocontable/add/', 'object_name': 'PeriodoContable'}, {'perms': {'add': True, 'delete': True, 'change': True}, 'name': 'Usercashiers', 'admin_url': '/admin/caja/usercashier/', 'add_url': '/admin/caja/usercashier/add/', 'object_name': 'Usercashier'}], 'name': 'Caja', 'app_label': 'caja', 'has_module_perms': True}, {'app_url': '/admin/catalogo/', 'models': [{'perms': {'add': True, 'delete': True, 'change': True}, 'name': 'Autores', 'admin_url': '/admin/catalogo/autor/', 'add_url': '/admin/catalogo/autor/add/', 'object_name': 'Autor'}, {'perms': {'add': True, 'delete': True, 'change': True}, 'name': 'Categorias', 'admin_url': '/admin/catalogo/categoria/', 'add_url': '/admin/catalogo/categoria/add/', 'object_name': 'Categoria'}, {'perms': {'add': True, 'delete': True, 'change': True}, 'name': 'Libros', 'admin_url': '/admin/catalogo/libro/', 'add_url': '/admin/catalogo/libro/add/', 'object_name': 'Libro'}], 'name': 'Catalogo', 'app_label': 'catalogo', 'has_module_perms': True}, {'app_url': '/admin/contenttypes/', 'models': [{'perms': {'add': True, 'delete': True, 'change': True}, 'name': <django.utils.functional.lazy.<locals>.__proxy__ object at 0x04A6E610>, 'admin_url': '/admin/contenttypes/contenttype/', 'add_url': '/admin/contenttypes/contenttype/add/', 'object_name': 'ContentType'}], 'name': <django.utils.functional.lazy.<locals>.__proxy__ object at 0x03AC2730>, 'app_label': 'contenttypes', 'has_module_perms': True}, {'app_url': '/admin/oauth2_provider/', 'models': [{'perms': {'add': True, 'delete': True, 'change': True}, 'name': <django.utils.functional.lazy.<locals>.__proxy__ object at 0x04A6E890>, 'admin_url': '/admin/oauth2_provider/accesstoken/', 'add_url': '/admin/oauth2_provider/accesstoken/add/', 'object_name': 'AccessToken'}, {'perms': {'add': True, 'delete': True, 'change': True}, 'name': <django.utils.functional.lazy.<locals>.__proxy__ object at 0x04A6E2D0>, 'admin_url': '/admin/oauth2_provider/application/', 'add_url': '/admin/oauth2_provider/application/add/', 'object_name': 'Application'}, {'perms': {'add': True, 'delete': True, 'change': True}, 'name': <django.utils.functional.lazy.<locals>.__proxy__ object at 0x04A6EFD0>, 'admin_url': '/admin/oauth2_provider/grant/', 'add_url': '/admin/oauth2_provider/grant/add/', 'object_name': 'Grant'}, {'perms': {'add': True, 'delete': True, 'change': True}, 'name': <django.utils.functional.lazy.<locals>.__proxy__ object at 0x04A6EF50>, 'admin_url': '/admin/oauth2_provider/refreshtoken/', 'add_url': '/admin/oauth2_provider/refreshtoken/add/', 'object_name': 'RefreshToken'}], 'name': 'Django OAuth Toolkit', 'app_label': 'oauth2_provider', 'has_module_perms': True}], 'LANGUAGE_CODE': 'en-us'}]"
[2016-11-16 04:56:13] DEBUG [django.template:929] Exception while resolving variable 'is_popup' in template 'admin/index.html'.
Traceback (most recent call last):
  File "D:\Project\redcashier\ve_redcashier\lib\site-packages\django\template\base.py", line 885, in _resolve_lookup
    current = current[bit]
  File "D:\Project\redcashier\ve_redcashier\lib\site-packages\django\template\context.py", line 75, in __getitem__
    raise KeyError(key)
KeyError: 'is_popup'

During handling of the above exception, another exception occurred:

Traceback (most recent call last):
  File "D:\Project\redcashier\ve_redcashier\lib\site-packages\django\template\base.py", line 891, in _resolve_lookup
    if isinstance(current, BaseContext) and getattr(type(current), bit):
AttributeError: type object 'RequestContext' has no attribute 'is_popup'

During handling of the above exception, another exception occurred:

Traceback (most recent call last):
  File "D:\Project\redcashier\ve_redcashier\lib\site-packages\django\template\base.py", line 900, in _resolve_lookup
    current = current[int(bit)]
ValueError: invalid literal for int() with base 10: 'is_popup'

During handling of the above exception, another exception occurred:

Traceback (most recent call last):
  File "D:\Project\redcashier\ve_redcashier\lib\site-packages\django\template\base.py", line 907, in _resolve_lookup
    (bit, current))  # missing attribute
django.template.base.VariableDoesNotExist: Failed lookup for key [is_popup] in "[{'True': True, 'None': None, 'False': False}, {'perms': <django.contrib.auth.context_processors.PermWrapper object at 0x04A80670>, 'csrf_token': <SimpleLazyObject: <function csrf.<locals>._get_val at 0x04B50A50>>, 'request': <WSGIRequest: GET '/admin/'>, 'user': <SimpleLazyObject: <User: sal>>, 'DEFAULT_MESSAGE_LEVELS': {'ERROR': 40, 'INFO': 20, 'DEBUG': 10, 'WARNING': 30, 'SUCCESS': 25}, 'messages': <django.contrib.messages.storage.fallback.FallbackStorage object at 0x04A9FB70>}, {}, {'site_url': '/', 'has_permission': True, 'site_title': <django.utils.functional.lazy.<locals>.__proxy__ object at 0x03AADB10>, 'title': <django.utils.functional.lazy.<locals>.__proxy__ object at 0x03AADBD0>, 'site_header': <django.utils.functional.lazy.<locals>.__proxy__ object at 0x03AADB70>, 'LANGUAGE_BIDI': False, 'app_list': [{'app_url': '/admin/auth/', 'models': [{'perms': {'add': True, 'delete': True, 'change': True}, 'name': <django.utils.functional.lazy.<locals>.__proxy__ object at 0x04A9FA50>, 'admin_url': '/admin/auth/group/', 'add_url': '/admin/auth/group/add/', 'object_name': 'Group'}, {'perms': {'add': True, 'delete': True, 'change': True}, 'name': <django.utils.functional.lazy.<locals>.__proxy__ object at 0x04A9F590>, 'admin_url': '/admin/auth/permission/', 'add_url': '/admin/auth/permission/add/', 'object_name': 'Permission'}], 'name': <django.utils.functional.lazy.<locals>.__proxy__ object at 0x03AC2610>, 'app_label': 'auth', 'has_module_perms': True}, {'app_url': '/admin/auths/', 'models': [{'perms': {'add': True, 'delete': True, 'change': True}, 'name': <django.utils.functional.lazy.<locals>.__proxy__ object at 0x04A6EB10>, 'admin_url': '/admin/auths/hierarchytype/', 'add_url': '/admin/auths/hierarchytype/add/', 'object_name': 'HierarchyType'}, {'perms': {'add': True, 'delete': True, 'change': True}, 'name': <django.utils.functional.lazy.<locals>.__proxy__ object at 0x04A6EAF0>, 'admin_url': '/admin/auths/hierarchy/', 'add_url': '/admin/auths/hierarchy/add/', 'object_name': 'Hierarchy'}, {'perms': {'add': True, 'delete': True, 'change': True}, 'name': <django.utils.functional.lazy.<locals>.__proxy__ object at 0x04A6E590>, 'admin_url': '/admin/auths/menu/', 'add_url': '/admin/auths/menu/add/', 'object_name': 'Menu'}, {'perms': {'add': True, 'delete': True, 'change': True}, 'name': <django.utils.functional.lazy.<locals>.__proxy__ object at 0x04A9FAB0>, 'admin_url': '/admin/auths/person/', 'add_url': '/admin/auths/person/add/', 'object_name': 'Person'}, {'perms': {'add': True, 'delete': True, 'change': True}, 'name': <django.utils.functional.lazy.<locals>.__proxy__ object at 0x04A9F7B0>, 'admin_url': '/admin/auths/userhierarchygroup/', 'add_url': '/admin/auths/userhierarchygroup/add/', 'object_name': 'UserHierarchyGroup'}, {'perms': {'add': True, 'delete': True, 'change': True}, 'name': <django.utils.functional.lazy.<locals>.__proxy__ object at 0x04A9FA30>, 'admin_url': '/admin/auths/userhierarchypermission/', 'add_url': '/admin/auths/userhierarchypermission/add/', 'object_name': 'UserHierarchyPermission'}, {'perms': {'add': True, 'delete': True, 'change': True}, 'name': <django.utils.functional.lazy.<locals>.__proxy__ object at 0x04A9FCB0>, 'admin_url': '/admin/auths/user/', 'add_url': '/admin/auths/user/add/', 'object_name': 'User'}], 'name': 'Auths', 'app_label': 'auths', 'has_module_perms': True}, {'app_url': '/admin/caja/', 'models': [{'perms': {'add': True, 'delete': True, 'change': True}, 'name': 'Cajaingresos', 'admin_url': '/admin/caja/cajaingreso/', 'add_url': '/admin/caja/cajaingreso/add/', 'object_name': 'Cajaingreso'}, {'perms': {'add': True, 'delete': True, 'change': True}, 'name': 'Modcontables', 'admin_url': '/admin/caja/modcontable/', 'add_url': '/admin/caja/modcontable/add/', 'object_name': 'Modcontable'}, {'perms': {'add': True, 'delete': True, 'change': True}, 'name': 'Niveles', 'admin_url': '/admin/caja/nivel/', 'add_url': '/admin/caja/nivel/add/', 'object_name': 'Nivel'}, {'perms': {'add': True, 'delete': True, 'change': True}, 'name': 'PeriodoContables', 'admin_url': '/admin/caja/periodocontable/', 'add_url': '/admin/caja/periodocontable/add/', 'object_name': 'PeriodoContable'}, {'perms': {'add': True, 'delete': True, 'change': True}, 'name': 'Usercashiers', 'admin_url': '/admin/caja/usercashier/', 'add_url': '/admin/caja/usercashier/add/', 'object_name': 'Usercashier'}], 'name': 'Caja', 'app_label': 'caja', 'has_module_perms': True}, {'app_url': '/admin/catalogo/', 'models': [{'perms': {'add': True, 'delete': True, 'change': True}, 'name': 'Autores', 'admin_url': '/admin/catalogo/autor/', 'add_url': '/admin/catalogo/autor/add/', 'object_name': 'Autor'}, {'perms': {'add': True, 'delete': True, 'change': True}, 'name': 'Categorias', 'admin_url': '/admin/catalogo/categoria/', 'add_url': '/admin/catalogo/categoria/add/', 'object_name': 'Categoria'}, {'perms': {'add': True, 'delete': True, 'change': True}, 'name': 'Libros', 'admin_url': '/admin/catalogo/libro/', 'add_url': '/admin/catalogo/libro/add/', 'object_name': 'Libro'}], 'name': 'Catalogo', 'app_label': 'catalogo', 'has_module_perms': True}, {'app_url': '/admin/contenttypes/', 'models': [{'perms': {'add': True, 'delete': True, 'change': True}, 'name': <django.utils.functional.lazy.<locals>.__proxy__ object at 0x04A9F650>, 'admin_url': '/admin/contenttypes/contenttype/', 'add_url': '/admin/contenttypes/contenttype/add/', 'object_name': 'ContentType'}], 'name': <django.utils.functional.lazy.<locals>.__proxy__ object at 0x03AC2730>, 'app_label': 'contenttypes', 'has_module_perms': True}, {'app_url': '/admin/oauth2_provider/', 'models': [{'perms': {'add': True, 'delete': True, 'change': True}, 'name': <django.utils.functional.lazy.<locals>.__proxy__ object at 0x04A9F6D0>, 'admin_url': '/admin/oauth2_provider/accesstoken/', 'add_url': '/admin/oauth2_provider/accesstoken/add/', 'object_name': 'AccessToken'}, {'perms': {'add': True, 'delete': True, 'change': True}, 'name': <django.utils.functional.lazy.<locals>.__proxy__ object at 0x04A9F610>, 'admin_url': '/admin/oauth2_provider/application/', 'add_url': '/admin/oauth2_provider/application/add/', 'object_name': 'Application'}, {'perms': {'add': True, 'delete': True, 'change': True}, 'name': <django.utils.functional.lazy.<locals>.__proxy__ object at 0x04A9F630>, 'admin_url': '/admin/oauth2_provider/grant/', 'add_url': '/admin/oauth2_provider/grant/add/', 'object_name': 'Grant'}, {'perms': {'add': True, 'delete': True, 'change': True}, 'name': <django.utils.functional.lazy.<locals>.__proxy__ object at 0x04A9F990>, 'admin_url': '/admin/oauth2_provider/refreshtoken/', 'add_url': '/admin/oauth2_provider/refreshtoken/add/', 'object_name': 'RefreshToken'}], 'name': 'Django OAuth Toolkit', 'app_label': 'oauth2_provider', 'has_module_perms': True}], 'available_apps': [{'app_url': '/admin/auth/', 'models': [{'perms': {'add': True, 'delete': True, 'change': True}, 'name': <django.utils.functional.lazy.<locals>.__proxy__ object at 0x04A6EFB0>, 'admin_url': '/admin/auth/group/', 'add_url': '/admin/auth/group/add/', 'object_name': 'Group'}, {'perms': {'add': True, 'delete': True, 'change': True}, 'name': <django.utils.functional.lazy.<locals>.__proxy__ object at 0x04A6EE30>, 'admin_url': '/admin/auth/permission/', 'add_url': '/admin/auth/permission/add/', 'object_name': 'Permission'}], 'name': <django.utils.functional.lazy.<locals>.__proxy__ object at 0x03AC2610>, 'app_label': 'auth', 'has_module_perms': True}, {'app_url': '/admin/auths/', 'models': [{'perms': {'add': True, 'delete': True, 'change': True}, 'name': <django.utils.functional.lazy.<locals>.__proxy__ object at 0x04A86110>, 'admin_url': '/admin/auths/hierarchytype/', 'add_url': '/admin/auths/hierarchytype/add/', 'object_name': 'HierarchyType'}, {'perms': {'add': True, 'delete': True, 'change': True}, 'name': <django.utils.functional.lazy.<locals>.__proxy__ object at 0x04A86050>, 'admin_url': '/admin/auths/hierarchy/', 'add_url': '/admin/auths/hierarchy/add/', 'object_name': 'Hierarchy'}, {'perms': {'add': True, 'delete': True, 'change': True}, 'name': <django.utils.functional.lazy.<locals>.__proxy__ object at 0x04A86630>, 'admin_url': '/admin/auths/menu/', 'add_url': '/admin/auths/menu/add/', 'object_name': 'Menu'}, {'perms': {'add': True, 'delete': True, 'change': True}, 'name': <django.utils.functional.lazy.<locals>.__proxy__ object at 0x04A6EFF0>, 'admin_url': '/admin/auths/person/', 'add_url': '/admin/auths/person/add/', 'object_name': 'Person'}, {'perms': {'add': True, 'delete': True, 'change': True}, 'name': <django.utils.functional.lazy.<locals>.__proxy__ object at 0x04A86030>, 'admin_url': '/admin/auths/userhierarchygroup/', 'add_url': '/admin/auths/userhierarchygroup/add/', 'object_name': 'UserHierarchyGroup'}, {'perms': {'add': True, 'delete': True, 'change': True}, 'name': <django.utils.functional.lazy.<locals>.__proxy__ object at 0x04A6EDF0>, 'admin_url': '/admin/auths/userhierarchypermission/', 'add_url': '/admin/auths/userhierarchypermission/add/', 'object_name': 'UserHierarchyPermission'}, {'perms': {'add': True, 'delete': True, 'change': True}, 'name': <django.utils.functional.lazy.<locals>.__proxy__ object at 0x04A6EDD0>, 'admin_url': '/admin/auths/user/', 'add_url': '/admin/auths/user/add/', 'object_name': 'User'}], 'name': 'Auths', 'app_label': 'auths', 'has_module_perms': True}, {'app_url': '/admin/caja/', 'models': [{'perms': {'add': True, 'delete': True, 'change': True}, 'name': 'Cajaingresos', 'admin_url': '/admin/caja/cajaingreso/', 'add_url': '/admin/caja/cajaingreso/add/', 'object_name': 'Cajaingreso'}, {'perms': {'add': True, 'delete': True, 'change': True}, 'name': 'Modcontables', 'admin_url': '/admin/caja/modcontable/', 'add_url': '/admin/caja/modcontable/add/', 'object_name': 'Modcontable'}, {'perms': {'add': True, 'delete': True, 'change': True}, 'name': 'Niveles', 'admin_url': '/admin/caja/nivel/', 'add_url': '/admin/caja/nivel/add/', 'object_name': 'Nivel'}, {'perms': {'add': True, 'delete': True, 'change': True}, 'name': 'PeriodoContables', 'admin_url': '/admin/caja/periodocontable/', 'add_url': '/admin/caja/periodocontable/add/', 'object_name': 'PeriodoContable'}, {'perms': {'add': True, 'delete': True, 'change': True}, 'name': 'Usercashiers', 'admin_url': '/admin/caja/usercashier/', 'add_url': '/admin/caja/usercashier/add/', 'object_name': 'Usercashier'}], 'name': 'Caja', 'app_label': 'caja', 'has_module_perms': True}, {'app_url': '/admin/catalogo/', 'models': [{'perms': {'add': True, 'delete': True, 'change': True}, 'name': 'Autores', 'admin_url': '/admin/catalogo/autor/', 'add_url': '/admin/catalogo/autor/add/', 'object_name': 'Autor'}, {'perms': {'add': True, 'delete': True, 'change': True}, 'name': 'Categorias', 'admin_url': '/admin/catalogo/categoria/', 'add_url': '/admin/catalogo/categoria/add/', 'object_name': 'Categoria'}, {'perms': {'add': True, 'delete': True, 'change': True}, 'name': 'Libros', 'admin_url': '/admin/catalogo/libro/', 'add_url': '/admin/catalogo/libro/add/', 'object_name': 'Libro'}], 'name': 'Catalogo', 'app_label': 'catalogo', 'has_module_perms': True}, {'app_url': '/admin/contenttypes/', 'models': [{'perms': {'add': True, 'delete': True, 'change': True}, 'name': <django.utils.functional.lazy.<locals>.__proxy__ object at 0x04A6E610>, 'admin_url': '/admin/contenttypes/contenttype/', 'add_url': '/admin/contenttypes/contenttype/add/', 'object_name': 'ContentType'}], 'name': <django.utils.functional.lazy.<locals>.__proxy__ object at 0x03AC2730>, 'app_label': 'contenttypes', 'has_module_perms': True}, {'app_url': '/admin/oauth2_provider/', 'models': [{'perms': {'add': True, 'delete': True, 'change': True}, 'name': <django.utils.functional.lazy.<locals>.__proxy__ object at 0x04A6E890>, 'admin_url': '/admin/oauth2_provider/accesstoken/', 'add_url': '/admin/oauth2_provider/accesstoken/add/', 'object_name': 'AccessToken'}, {'perms': {'add': True, 'delete': True, 'change': True}, 'name': <django.utils.functional.lazy.<locals>.__proxy__ object at 0x04A6E2D0>, 'admin_url': '/admin/oauth2_provider/application/', 'add_url': '/admin/oauth2_provider/application/add/', 'object_name': 'Application'}, {'perms': {'add': True, 'delete': True, 'change': True}, 'name': <django.utils.functional.lazy.<locals>.__proxy__ object at 0x04A6EFD0>, 'admin_url': '/admin/oauth2_provider/grant/', 'add_url': '/admin/oauth2_provider/grant/add/', 'object_name': 'Grant'}, {'perms': {'add': True, 'delete': True, 'change': True}, 'name': <django.utils.functional.lazy.<locals>.__proxy__ object at 0x04A6EF50>, 'admin_url': '/admin/oauth2_provider/refreshtoken/', 'add_url': '/admin/oauth2_provider/refreshtoken/add/', 'object_name': 'RefreshToken'}], 'name': 'Django OAuth Toolkit', 'app_label': 'oauth2_provider', 'has_module_perms': True}], 'LANGUAGE_CODE': 'en-us'}]"
[2016-11-16 04:56:13] DEBUG [django.db.backends:90] (0.001) SELECT "django_admin_log"."id", "django_admin_log"."action_time", "django_admin_log"."user_id", "django_admin_log"."content_type_id", "django_admin_log"."object_id", "django_admin_log"."object_repr", "django_admin_log"."action_flag", "django_admin_log"."change_message", "auths_user"."password", "auths_user"."last_login", "auths_user"."is_superuser", "auths_user"."username", "auths_user"."first_name", "auths_user"."last_name", "auths_user"."email", "auths_user"."is_staff", "auths_user"."is_active", "auths_user"."date_joined", "auths_user"."id", "auths_user"."last_hierarchy_id", "auths_user"."last_module_id", "auths_user"."person_id", "auths_user"."updated_at", "auths_user"."registered_by", "django_content_type"."id", "django_content_type"."app_label", "django_content_type"."model" FROM "django_admin_log" INNER JOIN "auths_user" ON ("django_admin_log"."user_id" = "auths_user"."id") LEFT OUTER JOIN "django_content_type" ON ("django_admin_log"."content_type_id" = "django_content_type"."id") WHERE "django_admin_log"."user_id" = 'b5095ea74ce147329f9b2a855bf8c53b' ORDER BY "django_admin_log"."action_time" DESC LIMIT 10; args=('b5095ea74ce147329f9b2a855bf8c53b',)
[2016-11-16 04:56:13] INFO [django.server:131] "GET /admin/ HTTP/1.1" 200 12643
[2016-11-16 04:56:13] INFO [django.server:131] "GET /static/admin/css/dashboard.css HTTP/1.1" 200 434
[2016-11-16 04:56:13] INFO [django.server:131] "GET /static/admin/img/icon-addlink.svg HTTP/1.1" 200 331
[2016-11-16 04:56:14] INFO [django.server:131] "GET /static/admin/img/icon-changelink.svg HTTP/1.1" 200 380
[2016-11-16 04:56:14] INFO [django.server:131] "GET /static/admin/fonts/Roboto-Bold-webfont.woff HTTP/1.1" 200 82564
[2016-11-16 04:56:27] DEBUG [django.db.backends:90] (0.002) SELECT "oauth2_provider_application"."id", "oauth2_provider_application"."client_id", "oauth2_provider_application"."user_id", "oauth2_provider_application"."redirect_uris", "oauth2_provider_application"."client_type", "oauth2_provider_application"."authorization_grant_type", "oauth2_provider_application"."client_secret", "oauth2_provider_application"."name", "oauth2_provider_application"."skip_authorization" FROM "oauth2_provider_application" WHERE "oauth2_provider_application"."client_id" = 'fyf52nHOVrQ9U7wbbftc10qDqeJWrsirZzpgyKFD'; args=('fyf52nHOVrQ9U7wbbftc10qDqeJWrsirZzpgyKFD',)
[2016-11-16 04:56:27] DEBUG [django.db.backends:90] (0.001) SELECT "auths_user"."password", "auths_user"."last_login", "auths_user"."is_superuser", "auths_user"."username", "auths_user"."first_name", "auths_user"."last_name", "auths_user"."email", "auths_user"."is_staff", "auths_user"."is_active", "auths_user"."date_joined", "auths_user"."id", "auths_user"."last_hierarchy_id", "auths_user"."last_module_id", "auths_user"."person_id", "auths_user"."updated_at", "auths_user"."registered_by" FROM "auths_user" WHERE "auths_user"."username" = 'sal'; args=('sal',)
[2016-11-16 04:56:27] DEBUG [django.db.backends:90] (0.001) BEGIN; args=None
[2016-11-16 04:56:27] DEBUG [django.db.backends:90] (0.026) INSERT INTO "oauth2_provider_accesstoken" ("user_id", "token", "application_id", "expires", "scope") VALUES ('b5095ea74ce147329f9b2a855bf8c53b', 'HM1wiakuWcaDQyvR7O5pSY7kh2gMpM', 1, '2016-11-16 20:56:27.829527', 'read write'); args=['b5095ea74ce147329f9b2a855bf8c53b', 'HM1wiakuWcaDQyvR7O5pSY7kh2gMpM', 1, '2016-11-16 20:56:27.829527', 'read write']
[2016-11-16 04:56:28] DEBUG [django.db.backends:90] (0.000) BEGIN; args=None
[2016-11-16 04:56:28] DEBUG [django.db.backends:90] (0.004) INSERT INTO "oauth2_provider_refreshtoken" ("user_id", "token", "application_id", "access_token_id") VALUES ('b5095ea74ce147329f9b2a855bf8c53b', 'ZQOW4KC5mPR27mhGmsaYlXR9HFVqSl', 1, 12); args=['b5095ea74ce147329f9b2a855bf8c53b', 'ZQOW4KC5mPR27mhGmsaYlXR9HFVqSl', 1, 12]
[2016-11-16 04:56:28] INFO [django.server:131] "POST /o/token/ HTTP/1.1" 200 169
[2016-11-16 04:56:30] INFO [django.server:131] "OPTIONS /api/auths/localuserinfo/ HTTP/1.1" 200 0
[2016-11-16 04:56:30] INFO [django.server:131] "OPTIONS /api/auths/usermenu/ HTTP/1.1" 200 0
[2016-11-16 04:56:30] DEBUG [django.db.backends:90] (0.011) SELECT "oauth2_provider_accesstoken"."id", "oauth2_provider_accesstoken"."user_id", "oauth2_provider_accesstoken"."token", "oauth2_provider_accesstoken"."application_id", "oauth2_provider_accesstoken"."expires", "oauth2_provider_accesstoken"."scope", "auths_user"."password", "auths_user"."last_login", "auths_user"."is_superuser", "auths_user"."username", "auths_user"."first_name", "auths_user"."last_name", "auths_user"."email", "auths_user"."is_staff", "auths_user"."is_active", "auths_user"."date_joined", "auths_user"."id", "auths_user"."last_hierarchy_id", "auths_user"."last_module_id", "auths_user"."person_id", "auths_user"."updated_at", "auths_user"."registered_by", "oauth2_provider_application"."id", "oauth2_provider_application"."client_id", "oauth2_provider_application"."user_id", "oauth2_provider_application"."redirect_uris", "oauth2_provider_application"."client_type", "oauth2_provider_application"."authorization_grant_type", "oauth2_provider_application"."client_secret", "oauth2_provider_application"."name", "oauth2_provider_application"."skip_authorization" FROM "oauth2_provider_accesstoken" LEFT OUTER JOIN "auths_user" ON ("oauth2_provider_accesstoken"."user_id" = "auths_user"."id") INNER JOIN "oauth2_provider_application" ON ("oauth2_provider_accesstoken"."application_id" = "oauth2_provider_application"."id") WHERE "oauth2_provider_accesstoken"."token" = 'HM1wiakuWcaDQyvR7O5pSY7kh2gMpM'; args=('HM1wiakuWcaDQyvR7O5pSY7kh2gMpM',)
[2016-11-16 04:56:30] DEBUG [django.db.backends:90] (0.001) SELECT "oauth2_provider_accesstoken"."id", "oauth2_provider_accesstoken"."user_id", "oauth2_provider_accesstoken"."token", "oauth2_provider_accesstoken"."application_id", "oauth2_provider_accesstoken"."expires", "oauth2_provider_accesstoken"."scope", "auths_user"."password", "auths_user"."last_login", "auths_user"."is_superuser", "auths_user"."username", "auths_user"."first_name", "auths_user"."last_name", "auths_user"."email", "auths_user"."is_staff", "auths_user"."is_active", "auths_user"."date_joined", "auths_user"."id", "auths_user"."last_hierarchy_id", "auths_user"."last_module_id", "auths_user"."person_id", "auths_user"."updated_at", "auths_user"."registered_by", "oauth2_provider_application"."id", "oauth2_provider_application"."client_id", "oauth2_provider_application"."user_id", "oauth2_provider_application"."redirect_uris", "oauth2_provider_application"."client_type", "oauth2_provider_application"."authorization_grant_type", "oauth2_provider_application"."client_secret", "oauth2_provider_application"."name", "oauth2_provider_application"."skip_authorization" FROM "oauth2_provider_accesstoken" LEFT OUTER JOIN "auths_user" ON ("oauth2_provider_accesstoken"."user_id" = "auths_user"."id") INNER JOIN "oauth2_provider_application" ON ("oauth2_provider_accesstoken"."application_id" = "oauth2_provider_application"."id") WHERE "oauth2_provider_accesstoken"."token" = 'HM1wiakuWcaDQyvR7O5pSY7kh2gMpM'; args=('HM1wiakuWcaDQyvR7O5pSY7kh2gMpM',)
[2016-11-16 04:56:30] DEBUG [django.db.backends:90] (0.001) SELECT "auth_group"."id", "auth_group"."name" FROM "auth_group" INNER JOIN "auths_user_groups" ON ("auth_group"."id" = "auths_user_groups"."group_id") WHERE "auths_user_groups"."user_id" = 'b5095ea74ce147329f9b2a855bf8c53b'; args=('b5095ea74ce147329f9b2a855bf8c53b',)
[2016-11-16 04:56:30] DEBUG [django.db.backends:90] (0.001) SELECT "auth_permission"."id", "auth_permission"."name", "auth_permission"."content_type_id", "auth_permission"."codename" FROM "auth_permission" INNER JOIN "auths_user_user_permissions" ON ("auth_permission"."id" = "auths_user_user_permissions"."permission_id") INNER JOIN "django_content_type" ON ("auth_permission"."content_type_id" = "django_content_type"."id") WHERE "auths_user_user_permissions"."user_id" = 'b5095ea74ce147329f9b2a855bf8c53b' ORDER BY "django_content_type"."app_label" ASC, "django_content_type"."model" ASC, "auth_permission"."codename" ASC; args=('b5095ea74ce147329f9b2a855bf8c53b',)
[2016-11-16 04:56:30] INFO [django.server:131] "GET /api/auths/localuserinfo/ HTTP/1.1" 200 403
[2016-11-16 04:56:30] DEBUG [django.db.backends:90] (0.006) SELECT "oauth2_provider_accesstoken"."id", "oauth2_provider_accesstoken"."user_id", "oauth2_provider_accesstoken"."token", "oauth2_provider_accesstoken"."application_id", "oauth2_provider_accesstoken"."expires", "oauth2_provider_accesstoken"."scope", "auths_user"."password", "auths_user"."last_login", "auths_user"."is_superuser", "auths_user"."username", "auths_user"."first_name", "auths_user"."last_name", "auths_user"."email", "auths_user"."is_staff", "auths_user"."is_active", "auths_user"."date_joined", "auths_user"."id", "auths_user"."last_hierarchy_id", "auths_user"."last_module_id", "auths_user"."person_id", "auths_user"."updated_at", "auths_user"."registered_by", "oauth2_provider_application"."id", "oauth2_provider_application"."client_id", "oauth2_provider_application"."user_id", "oauth2_provider_application"."redirect_uris", "oauth2_provider_application"."client_type", "oauth2_provider_application"."authorization_grant_type", "oauth2_provider_application"."client_secret", "oauth2_provider_application"."name", "oauth2_provider_application"."skip_authorization" FROM "oauth2_provider_accesstoken" LEFT OUTER JOIN "auths_user" ON ("oauth2_provider_accesstoken"."user_id" = "auths_user"."id") INNER JOIN "oauth2_provider_application" ON ("oauth2_provider_accesstoken"."application_id" = "oauth2_provider_application"."id") WHERE "oauth2_provider_accesstoken"."token" = 'HM1wiakuWcaDQyvR7O5pSY7kh2gMpM'; args=('HM1wiakuWcaDQyvR7O5pSY7kh2gMpM',)
[2016-11-16 04:56:30] DEBUG [django.db.backends:90] (0.001) SELECT "oauth2_provider_accesstoken"."id", "oauth2_provider_accesstoken"."user_id", "oauth2_provider_accesstoken"."token", "oauth2_provider_accesstoken"."application_id", "oauth2_provider_accesstoken"."expires", "oauth2_provider_accesstoken"."scope", "auths_user"."password", "auths_user"."last_login", "auths_user"."is_superuser", "auths_user"."username", "auths_user"."first_name", "auths_user"."last_name", "auths_user"."email", "auths_user"."is_staff", "auths_user"."is_active", "auths_user"."date_joined", "auths_user"."id", "auths_user"."last_hierarchy_id", "auths_user"."last_module_id", "auths_user"."person_id", "auths_user"."updated_at", "auths_user"."registered_by", "oauth2_provider_application"."id", "oauth2_provider_application"."client_id", "oauth2_provider_application"."user_id", "oauth2_provider_application"."redirect_uris", "oauth2_provider_application"."client_type", "oauth2_provider_application"."authorization_grant_type", "oauth2_provider_application"."client_secret", "oauth2_provider_application"."name", "oauth2_provider_application"."skip_authorization" FROM "oauth2_provider_accesstoken" LEFT OUTER JOIN "auths_user" ON ("oauth2_provider_accesstoken"."user_id" = "auths_user"."id") INNER JOIN "oauth2_provider_application" ON ("oauth2_provider_accesstoken"."application_id" = "oauth2_provider_application"."id") WHERE "oauth2_provider_accesstoken"."token" = 'HM1wiakuWcaDQyvR7O5pSY7kh2gMpM'; args=('HM1wiakuWcaDQyvR7O5pSY7kh2gMpM',)
[2016-11-16 04:56:30] DEBUG [django.db.backends:90] (0.000) SELECT "auths_menu"."id" FROM "auths_menu" WHERE ("auths_menu"."id" IS NOT NULL AND "auths_menu"."is_active" = 1 AND "auths_menu"."module" = 'BACKEND') ORDER BY "auths_menu"."pos" ASC; args=(True, 'BACKEND')
[2016-11-16 04:56:30] DEBUG [django.db.backends:90] (0.001) SELECT (1) AS "a" FROM "django_session" WHERE "django_session"."session_key" = 'fhkwlw7gmy6e31y3muffwufxxw0o6lv9' LIMIT 1; args=('fhkwlw7gmy6e31y3muffwufxxw0o6lv9',)
[2016-11-16 04:56:30] DEBUG [django.db.backends:90] (0.000) BEGIN; args=None
[2016-11-16 04:56:30] DEBUG [django.db.backends:90] (0.015) INSERT INTO "django_session" ("session_key", "session_data", "expire_date") SELECT 'fhkwlw7gmy6e31y3muffwufxxw0o6lv9', 'ODY1NjFiZTY0MzBmM2M0MGUwMDNhZGY4YmJlNjRmMzUzYmRiN2M3Nzp7Il9zZXNzaW9uX2V4cGlyeSI6MzB9', '2016-11-16 10:57:00.950047'; args=('fhkwlw7gmy6e31y3muffwufxxw0o6lv9', 'ODY1NjFiZTY0MzBmM2M0MGUwMDNhZGY4YmJlNjRmMzUzYmRiN2M3Nzp7Il9zZXNzaW9uX2V4cGlyeSI6MzB9', '2016-11-16 10:57:00.950047')
[2016-11-16 04:56:31] INFO [django.server:131] "GET /api/auths/usermenu/ HTTP/1.1" 200 11
[2016-11-16 04:56:45] INFO [django.server:131] "OPTIONS /api/caja/modcontables/ HTTP/1.1" 200 0
[2016-11-16 04:56:45] DEBUG [django.db.backends:90] (0.004) SELECT "oauth2_provider_accesstoken"."id", "oauth2_provider_accesstoken"."user_id", "oauth2_provider_accesstoken"."token", "oauth2_provider_accesstoken"."application_id", "oauth2_provider_accesstoken"."expires", "oauth2_provider_accesstoken"."scope", "auths_user"."password", "auths_user"."last_login", "auths_user"."is_superuser", "auths_user"."username", "auths_user"."first_name", "auths_user"."last_name", "auths_user"."email", "auths_user"."is_staff", "auths_user"."is_active", "auths_user"."date_joined", "auths_user"."id", "auths_user"."last_hierarchy_id", "auths_user"."last_module_id", "auths_user"."person_id", "auths_user"."updated_at", "auths_user"."registered_by", "oauth2_provider_application"."id", "oauth2_provider_application"."client_id", "oauth2_provider_application"."user_id", "oauth2_provider_application"."redirect_uris", "oauth2_provider_application"."client_type", "oauth2_provider_application"."authorization_grant_type", "oauth2_provider_application"."client_secret", "oauth2_provider_application"."name", "oauth2_provider_application"."skip_authorization" FROM "oauth2_provider_accesstoken" LEFT OUTER JOIN "auths_user" ON ("oauth2_provider_accesstoken"."user_id" = "auths_user"."id") INNER JOIN "oauth2_provider_application" ON ("oauth2_provider_accesstoken"."application_id" = "oauth2_provider_application"."id") WHERE "oauth2_provider_accesstoken"."token" = 'HM1wiakuWcaDQyvR7O5pSY7kh2gMpM'; args=('HM1wiakuWcaDQyvR7O5pSY7kh2gMpM',)
[2016-11-16 04:56:45] DEBUG [django.db.backends:90] (0.000) SELECT "oauth2_provider_accesstoken"."id", "oauth2_provider_accesstoken"."user_id", "oauth2_provider_accesstoken"."token", "oauth2_provider_accesstoken"."application_id", "oauth2_provider_accesstoken"."expires", "oauth2_provider_accesstoken"."scope", "auths_user"."password", "auths_user"."last_login", "auths_user"."is_superuser", "auths_user"."username", "auths_user"."first_name", "auths_user"."last_name", "auths_user"."email", "auths_user"."is_staff", "auths_user"."is_active", "auths_user"."date_joined", "auths_user"."id", "auths_user"."last_hierarchy_id", "auths_user"."last_module_id", "auths_user"."person_id", "auths_user"."updated_at", "auths_user"."registered_by", "oauth2_provider_application"."id", "oauth2_provider_application"."client_id", "oauth2_provider_application"."user_id", "oauth2_provider_application"."redirect_uris", "oauth2_provider_application"."client_type", "oauth2_provider_application"."authorization_grant_type", "oauth2_provider_application"."client_secret", "oauth2_provider_application"."name", "oauth2_provider_application"."skip_authorization" FROM "oauth2_provider_accesstoken" LEFT OUTER JOIN "auths_user" ON ("oauth2_provider_accesstoken"."user_id" = "auths_user"."id") INNER JOIN "oauth2_provider_application" ON ("oauth2_provider_accesstoken"."application_id" = "oauth2_provider_application"."id") WHERE "oauth2_provider_accesstoken"."token" = 'HM1wiakuWcaDQyvR7O5pSY7kh2gMpM'; args=('HM1wiakuWcaDQyvR7O5pSY7kh2gMpM',)
[2016-11-16 04:56:45] DEBUG [django.db.backends:90] (0.000) SELECT "caja_modcontable"."id", "caja_modcontable"."contanual", "caja_modcontable"."regisanual" FROM "caja_modcontable"; args=()
[2016-11-16 04:56:45] INFO [django.server:131] "GET /api/caja/modcontables/ HTTP/1.1" 200 265
